Workbook

Sheet Užduotis
A1: Savarankiško darbo užduotis:
A3: Darbalapis "Darbuotojai"
B4: Stulpelio pavadinimas | C4: Užduotis | D4: Pastabos
A5: 1 | B5: Eil. Nr. | C5: Sukurkite seką
A6: 2 | B6: Pavardė, vardas | C6: Sukurkite seką "Darbuotojas1" ir t.t.
A7: 3 | B7: Pareigos | C7: Sudarykite sąrašą ir parinkite vieną iš pateiktų pareigybių kiekvienam darbuotojui. Pareigybių skaičius duotas "Pareigybės" lape | D7: sąrašas
A8: 4 | B8: Pareiginis atlyginimas, € | C8: Parinkite kiekvienam darbuotojui pareiginį atlyginimą pagal pareigas | D8: vlookup()
A9: 5 | B9: Valandinis tarifinis atlygis, € | C9: Apskaičiuokite iš pareiginio atlyginimo imdami vidutinį mėnesio darbo dienų skaičių 22
A10: 6 | B10: Avansas, € | C10: Avansą parinkite atsitiktiniu būdu 150 arba 200 eurų | D10: choose()
A11: 7 | B11: Asmens kodas | C11: nepildyti
A12: 8 | B12: Tel. Nr. | C12: sujunkite "+370 6" ir 7 atsitiktiniai skaičiai | D12: concatenate()
A13: 9 | B13: Adresas | C13: sugalvokite patys
A16: Darbalapis "Darbo užmokestis"
B17: Stulpelio pavadinimas | C17: Užduotis
A18: 1 | B18: A5 | C18: Įrašykite kovo mėnesį
A19: 2 | B19: Registras | C19: Darbo užmokestis
A20: 3 | B20: Op. Nr. | C20: tarkime, kad darote registrą kovo mėnesiui, tada rašykite visur 03
A21: 4 | B21: Skaičiavimo data | C21: Pasirinkite šių metų kovo datą formatas: 2022/kov/31 | D21: eomonth()
A22: 5 | B22: Pavardė, vardas | C22: nukopijuokite darbuotojus iš darbuotojų lapo
A23: 6 | B23: Pareiginis atlyginimas, € | C23: Parinkite kiekvienam darbuotojui pareiginį atlyginimą iš darbuotojų lapo | D23: vlookup()
A24: 7 | B24: Valandinis tarifinis atlygis, € | C24: Parinkite kiekvienam darbuotojui pareiginį valandinį atlyginimą iš darbuotojų lapo | D24: vlookup()
A25: 8 | B25: Nustatytas darbo dienų skaičius | C25: apskaičiuokite darbo dienų skaičių su funkcija Networkdays(). Nepamirškite švenčių dienų.
A26: 9 | B26: Faktiškai dirbta, d. | C26: parinkite atsitiktiniu būdu nuo 15 iki mėnesio darbo dienų skaičiaus | D26: randbetween()
A27: 10 | B27: Faktiškai dirbta, val. | C27: dienos * 8 val.
A28: 11 | B28: Atlyginimas, € | C28: atlyginimas priskaičiuotas už dirbtas dienas | D28: atlyginimas*fakt.dirbtų d./d.d.skaičius
A29: 12 | B29: Mėnesinė priemoka, € | C29: Skirkite mėnesinę priemoką 50 eurų, jei dirbo visas darbo dienas | D29: IF
A30: 13 | B30: Eilinės atostogos, € | C30: Jei darbuotojas nedirbo daugiau nei 4 dienas, tada jis tas dienas buvo atostogose. Paskaičiuokite už tas dienas atostoginius | D30: IF
A31: 14 | B31: Kompensacija už nepanaudotas atostogas, € | C31: 0
A32: 15 | B32: Nedarbingumo pašalpa darbdavio lėšomis, € | C32: Jei darbuotojas nedirbo 4 ar mažiau dienų, tada jis sirgo. Paskaičiuokite už tas 1-2 dienas darbdavio mokamą atlyginimą | D32: IF
A33: 16 | B33: Priskaičiuota iš viso, € | C33: Visos priskaičiuotos sumos
A34: 17 | B34: pritaikytas NPD, € | C34: paskaičiuokite pagal dešinėje duotas formules | H34: Neapmokestinamo minimumo skaičiavimas:
A35: 18 | B35: GPM, € | C35: GMP=(Priskaičiuota - NPD)*20% | D35: koeficientams suteikite vardus | G35: 1) | H35: NPD max - 460 Eur. Taikomas pajamoms iki 730 Eur.
A36: 19 | B36: VSD ir PSD įmokos, € | C36: 14,29% nuo priskaičiuoto atlygio atėmus nedarbingumo pašalpos sumą, PSD - 6,98% | G36: 2) | H36: NPD = 460 – 0,26* (gyventojo mėnesio su darbo santykiais arba jų esmę atitinkančiais santykiais susijusios pajamos – 730) | R36: jei Du<1678
A37: 20 | B37: Papildomas pensijinis kaupimas | C37: 3% nuo priskaičiuoto atlygio | G37: 3) | H37: NPD = 400 – 0,18* (gyventojo mėnesio su darbo santykiais arba jų esmę atitinkančiais santykiais susijusios pajamos – 642) | R37: jei Du>1678
A38: 21 | B38: Išskaičiuota iš viso, € | C38: visa išskaičiuota suma mokesčiams | G38: 4) | H38: Jei neigiamas tai rašome 0
A39: 22 | B39: Išmokėtina suma, € | C39: Išmokama = priskaičiuota - išskaičiuota
A40: 23 | B40: Darbdavio VSD įmokos, € | C40: VSD (1,77%) * priskaičiuota
A41: 24 | B41: Avansas, € | C41: Parinkite iš darbuotojų lapo | D41: vlookup()
A42: 25 | B42: Išmokėtina suma po avanso, € | C42: Išmokama suma atėmus avansą
A43: 26 | B43: Garantinis fondas | C43: 0,2% nuo visiems darbuotojams priskaičiuotų atlyginimų
...

Sheet Pareigybės
A3: Eil. Nr. | B3: Pareigybė | C3: Pareiginis atlyginimas, € | D3: Darbuotojų skaičius
A4: 1 | B4: Vadovas | C4: 2800 | D4: 1
A5: 2 | B5: Buhalterė | C5: 1600 | D5: 2
A6: 3 | B6: Administratorė | C6: 1505 | D6: 1
A7: 4 | B7: Vadybininkas | C7: 1199 | D7: 2
A8: 5 | B8: Sandėlininkas | C8: 1090 | D8: 2
A9: 6 | B9: Gamybos darbuotojas | C9: 980 | D9: 7

Sheet Darbuotojai
A1: Darbuotojai
A5: Eil. Nr. | B5: Pavardė, vardas | C5: Pareigos | D5: Pareiginis atlyginimas, € | E5: Valandinis tarifinis atlygis, € | F5: Avansas, € | G5: Asmens kodas | H5: Tel. Nr. | I5: Adresas
A6: 1. | B6: Darbuotojas1 | C6: =Pareigybės!B4 -> Vadovas | D6: =VLOOKUP(C6,Pareigybės!$B$4:$C$9,2,FALSE) -> 2800 | F6: =CHOOSE(RANDBETWEEN(1,2),150,200) -> 200 | G6: x | I6: Jaunystės 1
A7: 2. | B7: Darbuotojas2 | C7: =Pareigybės!B5 -> Buhalterė | D7: =VLOOKUP(C7,Pareigybės!$B$4:$C$9,2,FALSE) -> 1600 | F7: =CHOOSE(RANDBETWEEN(1,2),150,200) -> 150 | G7: x | I7: Jaunystės 2
A8: 3. | B8: Darbuotojas3 | C8: =Pareigybės!B5 -> Buhalterė | D8: =VLOOKUP(C8,Pareigybės!$B$4:$C$9,2,FALSE) -> 1600 | F8: =CHOOSE(RANDBETWEEN(1,2),150,200) -> 150 | G8: x | I8: Jaunystės 3
A9: 4. | B9: Darbuotojas4 | C9: =Pareigybės!B6 -> Administratorė | D9: =VLOOKUP(C9,Pareigybės!$B$4:$C$9,2,FALSE) -> 1505 | F9: =CHOOSE(RANDBETWEEN(1,2),150,200) -> 200 | G9: x | I9: Jaunystės 4
A10: 5. | B10: Darbuotojas5 | C10: =Pareigybės!B7 -> Vadybininkas | D10: =VLOOKUP(C10,Pareigybės!$B$4:$C$9,2,FALSE) -> 1199 | F10: =CHOOSE(RANDBETWEEN(1,2),150,200) -> 200 | G10: x | I10: Jaunystės 5
A11: 6. | B11: Darbuotojas6 | C11: =Pareigybės!B7 -> Vadybininkas | D11: =VLOOKUP(C11,Pareigybės!$B$4:$C$9,2,FALSE) -> 1199 | F11: =CHOOSE(RANDBETWEEN(1,2),150,200) -> 150 | G11: x | I11: Jaunystės 6
A12: 7. | B12: Darbuotojas7 | C12: =Pareigybės!B8 -> Sandėlininkas | D12: =VLOOKUP(C12,Pareigybės!$B$4:$C$9,2,FALSE) -> 1090 | F12: =CHOOSE(RANDBETWEEN(1,2),150,200) -> 200 | G12: x | I12: Jaunystės 7
A13: 8. | B13: Darbuotojas8 | C13: =Pareigybės!B8 -> Sandėlininkas | D13: =VLOOKUP(C13,Pareigybės!$B$4:$C$9,2,FALSE) -> 1090 | F13: =CHOOSE(RANDBETWEEN(1,2),150,200) -> 200 | G13: x | I13: Jaunystės 8
A14: 9. | B14: Darbuotojas9 | C14: =Pareigybės!B9 -> Gamybos darbuotojas | D14: =VLOOKUP(C14,Pareigybės!$B$4:$C$9,2,FALSE) -> 980 | F14: =CHOOSE(RANDBETWEEN(1,2),150,200) -> 200 | G14: x | I14: Jaunystės 9
A15: 10. | B15: Darbuotojas10 | C15: =Pareigybės!B9 -> Gamybos darbuotojas | D15: =VLOOKUP(C15,Pareigybės!$B$4:$C$9,2,FALSE) -> 980 | F15: =CHOOSE(RANDBETWEEN(1,2),150,200) -> 150 | G15: x | I15: Jaunystės 10
A16: 11. | B16: Darbuotojas11 | C16: =Pareigybės!B9 -> Gamybos darbuotojas | D16: =VLOOKUP(C16,Pareigybės!$B$4:$C$9,2,FALSE) -> 980 | F16: =CHOOSE(RANDBETWEEN(1,2),150,200) -> 150 | G16: x | I16: Jaunystės 11
A17: 12. | B17: Darbuotojas12 | C17: =Pareigybės!B9 -> Gamybos darbuotojas | D17: =VLOOKUP(C17,Pareigybės!$B$4:$C$9,2,FALSE) -> 980 | F17: =CHOOSE(RANDBETWEEN(1,2),150,200) -> 200 | G17: x | I17: Jaunystės 12
A18: 13. | B18: Darbuotojas13 | C18: =Pareigybės!B9 -> Gamybos darbuotojas | D18: =VLOOKUP(C18,Pareigybės!$B$4:$C$9,2,FALSE) -> 980 | F18: =CHOOSE(RANDBETWEEN(1,2),150,200) -> 200 | G18: x | I18: Jaunystės 13
A19: 14. | B19: Darbuotojas14 | C19: =Pareigybės!B9 -> Gamybos darbuotojas | D19: =VLOOKUP(C19,Pareigybės!$B$4:$C$9,2,FALSE) -> 980 | F19: =CHOOSE(RANDBETWEEN(1,2),150,200) -> 200 | G19: x | I19: Jaunystės 14
A20: 15. | B20: Darbuotojas15 | C20: =Pareigybės!B9 -> Gamybos darbuotojas | D20: =VLOOKUP(C20,Pareigybės!$B$4:$C$9,2,FALSE) -> 980 | F20: =CHOOSE(RANDBETWEEN(1,2),150,200) -> 150 | G20: x | I20: Jaunystės 15

Sheet Darbo užmokestis
A1: UAB "Jaunystė" | F1: GPM1 | G1: 0.2 | J1: Garantinis fondas | L1: 0.002 | N1: Ilgalaikio darbo išmokų fondo įmoka | R1: 0.0016
A2: Įmonės kodas 1222555888 | F2: GPM2 | G2: 0.27 | J2: Įmoka | N2: Soc. draudimo įmokos nelaimingų atsitikimų draudimui | R2: 0.0014
A3: Darbo užmokesčio registras | F3: VSD darbuotojo | G3: 0.1429
F4: PSD | G4: 0.0698
F5: VSD darbdavio | G5: 0.0177
F6: Papildomas pensijinis kaupimas | G6: 0.03
A7: mėnuo | F7: Nedarbingumo pašalpa | G7: 0.65 | I7: Iš viso: | J7: =SUM(J10:J24) -> 0 | K7: =SUM(K10:K24) -> 0 | L7: =SUM(L10:L24) -> 0 | M7: =SUM(M10:M24) -> 0 | N7: =SUM(N10:N24) -> 0 | O7: =SUM(O10:O24) -> 0 | P7: =SUM(P10:P24) -> 0 | Q7: =SUM(Q10:Q24) -> 0 | ... Y7: =SUM(Y10:Y24) -> 0
A9: Registras | B9: Op. Nr. | C9: Skaičiavimo data | D9: Pavardė, vardas | E9: Pareiginis atlyginimas, € | F9: Valandinis tarifinis atlygis, € | G9: Nustatytas darbo dienų skaičius | H9: Faktiškai dirbta, d. | I9: Faktiškai dirbta, val. | J9: Atlyginimas, € | K9: Mėnesinė priemoka, € | L9: Eilinės atostogos, € | M9: Kompensacija už nepanaudotas atostogas, € | N9: Nedarbingumo pašalpa darbdavio lėšomis, € | O9: Priskaičiuota iš viso, € | P9: pritaikytas NPD, € | Q9: GPM, € | R9: VSD įmoka, € | S9: PSD įmoka, € | T9: Papildomas pensijinis kaupimas | U9: Išskaičiuota iš viso, € | V9: Išmokėtina suma, € | W9: Darbdavio VSD įmokos, € | X9: Avansas, € | Y9: Išmokėtina suma po avanso, €
A10: darbo užmokestis
A11: darbo užmokestis
A12: darbo užmokestis
A13: darbo užmokestis
A14: darbo užmokestis
A15: darbo užmokestis
A16: darbo užmokestis
A17: darbo užmokestis
A18: darbo užmokestis
A19: darbo užmokestis
A20: darbo užmokestis
A21: darbo užmokestis
... A24: darbo užmokestis

Sheet suvestinė
A3: 1 | B3: Keli darbuotojai dirbo 18 ir daugiau dienų
A4: 2 | B4: Darbuotojų, kurie dirbo mažiau nei 18 dienų, išmokamų atlyginimų suma
A5: 3 | B5: Vidutinė avanso suma
A6: 4 | B6: Darbuotojų, kurių valandinis įkainis mažiau nei 8 eurai, sumokamų VSD vidurkis
A7: 5 | B7: Pritaikyto NPD mediana
A8: 6 | B8: 2 didžiausia GPM reikšmė
