Workbook

Sheet Užduotis
A1: Savarankiško darbo užduotis:
A3: Darbalapis "Darbuotojai"
B4: Stulpelio pavadinimas | C4: Užduotis | D4: Pastabos
A5: 1 | B5: Eil. Nr. | C5: Sukurkite seką
A6: 2 | B6: Pavardė, vardas | C6: Sukurkite seką "Darbuotojas1" ir t.t.
A7: 3 | B7: Pareigos | C7: Sudarykite sąrašą ir parinkite vieną iš pateiktų pareigybių kiekvienam darbuotojui. Pareigybių skaičius duotas "Pareigybės" lape | D7: sąrašas
A8: 4 | B8: Pareiginis atlyginimas, € | C8: Parinkite kiekvienam darbuotojui pareiginį atlyginimą pagal pareigas | D8: vlookup()
A9: 5 | B9: Valandinis tarifinis atlygis, € | C9: Apskaičiuokite iš pareiginio atlyginimo imdami vidutinį mėnesio darbo dienų skaičių 22
A10: 6 | B10: Avansas, € | C10: Avansą parinkite atsitiktiniu būdu 150 arba 200 eurų | D10: choose()
A11: 7 | B11: Asmens kodas | C11: nepildyti
A12: 8 | B12: Tel. Nr. | C12: sujunkite "+370 6" ir 7 atsitiktiniai skaičiai | D12: concatenate()
A13: 9 | B13: Adresas | C13: sugalvokite patys
A16: Darbalapis "Darbo užmokestis"
B17: Stulpelio pavadinimas | C17: Užduotis
A18: 1 | B18: A5 | C18: Įrašykite kovo mėnesį
A19: 2 | B19: Registras | C19: Darbo užmokestis
A20: 3 | B20: Op. Nr. | C20: tarkime, kad darote registrą kovo mėnesiui, tada rašykite visur 03
A21: 4 | B21: Skaičiavimo data | C21: Pasirinkite šių metų kovo datą formatas: 2022/kov/31 | D21: eomonth()
A22: 5 | B22: Pavardė, vardas | C22: nukopijuokite darbuotojus iš darbuotojų lapo
A23: 6 | B23: Pareiginis atlyginimas, € | C23: Parinkite kiekvienam darbuotojui pareiginį atlyginimą iš darbuotojų lapo | D23: vlookup()
A24: 7 | B24: Valandinis tarifinis atlygis, € | C24: Parinkite kiekvienam darbuotojui pareiginį valandinį atlyginimą iš darbuotojų lapo | D24: vlookup()
A25: 8 | B25: Nustatytas darbo dienų skaičius | C25: apskaičiuokite darbo dienų skaičių su funkcija Networkdays(). Nepamirškite švenčių dienų.
A26: 9 | B26: Faktiškai dirbta, d. | C26: parinkite atsitiktiniu būdu nuo 15 iki mėnesio darbo dienų skaičiaus | D26: randbetween()
A27: 10 | B27: Faktiškai dirbta, val. | C27: dienos * 8 val.
A28: 11 | B28: Atlyginimas, € | C28: atlyginimas priskaičiuotas už dirbtas dienas | D28: atlyginimas*fakt.dirbtų d./d.d.skaičius
A29: 12 | B29: Mėnesinė priemoka, € | C29: Skirkite mėnesinę priemoką 50 eurų, jei dirbo visas darbo dienas | D29: IF
A30: 13 | B30: Eilinės atostogos, € | C30: Jei darbuotojas nedirbo daugiau nei 4 dienas, tada jis tas dienas buvo atostogose. Paskaičiuokite už tas dienas atostoginius | D30: IF
A31: 14 | B31: Kompensacija už nepanaudotas atostogas, € | C31: 0
A32: 15 | B32: Nedarbingumo pašalpa darbdavio lėšomis, € | C32: Jei darbuotojas nedirbo 4 ar mažiau dienų, tada jis sirgo. Paskaičiuokite už tas 1-2 dienas darbdavio mokamą atlyginimą | D32: IF
A33: 16 | B33: Priskaičiuota iš viso, € | C33: Visos priskaičiuotos sumos
A34: 17 | B34: pritaikytas NPD, € | C34: paskaičiuokite pagal dešinėje duotas formules | H34: Neapmokestinamo minimumo skaičiavimas:
A35: 18 | B35: GPM, € | C35: GMP=(Priskaičiuota - NPD)*20% | D35: koeficientams suteikite vardus | G35: 1) | H35: NPD max - 460 Eur. Taikomas pajamoms iki 730 Eur.
A36: 19 | B36: VSD ir PSD įmokos, € | C36: 14,29% nuo priskaičiuoto atlygio atėmus nedarbingumo pašalpos sumą, PSD - 6,98% | G36: 2) | H36: NPD = 460 – 0,26* (gyventojo mėnesio su darbo santykiais arba jų esmę atitinkančiais santykiais susijusios pajamos – 730) | R36: jei Du<1678
A37: 20 | B37: Papildomas pensijinis kaupimas | C37: 3% nuo priskaičiuoto atlygio | G37: 3) | H37: NPD = 400 – 0,18* (gyventojo mėnesio su darbo santykiais arba jų esmę atitinkančiais santykiais susijusios pajamos – 642) | R37: jei Du>1678
A38: 21 | B38: Išskaičiuota iš viso, € | C38: visa išskaičiuota suma mokesčiams | G38: 4) | H38: Jei neigiamas tai rašome 0
A39: 22 | B39: Išmokėtina suma, € | C39: Išmokama = priskaičiuota - išskaičiuota
A40: 23 | B40: Darbdavio VSD įmokos, € | C40: VSD (1,77%) * priskaičiuota
A41: 24 | B41: Avansas, € | C41: Parinkite iš darbuotojų lapo | D41: vlookup()
A42: 25 | B42: Išmokėtina suma po avanso, € | C42: Išmokama suma atėmus avansą
A43: 26 | B43: Garantinis fondas | C43: 0,2% nuo visiems darbuotojams priskaičiuotų atlyginimų
...

Sheet Pareigybės
A3: Eil. Nr. | B3: Pareigybė | C3: Pareiginis atlyginimas, € | D3: Darbuotojų skaičius
A4: 1 | B4: Vadovas | C4: 2800 | D4: 1
A5: 2 | B5: Buhalterė | C5: 1600 | D5: 2
A6: 3 | B6: Administratorė | C6: 1505 | D6: 1
A7: 4 | B7: Vadybininkas | C7: 1199 | D7: 2
A8: 5 | B8: Sandėlininkas | C8: 1090 | D8: 2
A9: 6 | B9: Gamybos darbuotojas | C9: 980 | D9: 7

Sheet Darbuotojai
A1: Darbuotojai
A5: Eil. Nr. | B5: Pavardė, vardas | C5: Pareigos | D5: Pareiginis atlyginimas, € | E5: Valandinis tarifinis atlygis, € | F5: Avansas, € | G5: Asmens kodas | H5: Tel. Nr. | I5: Adresas
A6: 1 | B6: Darbuotojas1 | C6: Buhalterė | D6: =VLOOKUP(C6, Pareigybės!$B$4:$C$9,2,0) -> 1600 | E6: =D6/(22*8) -> 9.0909091 | F6: =CHOOSE(RANDBETWEEN(1,2),150,200) -> 200 | G6: x | H6: =CONCATENATE("+",370,RANDBETWEEN(1000000,9999999)) -> +3709310122 | I6: Jaunystės 1
A7: 2 | B7: Darbuotojas2 | C7: Sandėlininkas | D7: =VLOOKUP(C7, Pareigybės!$B$4:$C$9,2,0) -> 1090 | E7: =D7/(22*8) -> 6.1931818 | F7: =CHOOSE(RANDBETWEEN(1,2),150,200) -> 200 | G7: x | H7: =CONCATENATE("+",370,RANDBETWEEN(1000000,9999999)) -> +3704792821 | I7: Jaunystės 2
A8: 3 | B8: Darbuotojas3 | C8: Gamybos darbuotojas | D8: =VLOOKUP(C8, Pareigybės!$B$4:$C$9,2,0) -> 980 | E8: =D8/(22*8) -> 5.5681818 | F8: =CHOOSE(RANDBETWEEN(1,2),150,200) -> 150 | G8: x | H8: =CONCATENATE("+",370,RANDBETWEEN(1000000,9999999)) -> +3703713712 | I8: Jaunystės 3
A9: 4 | B9: Darbuotojas4 | C9: Gamybos darbuotojas | D9: =VLOOKUP(C9, Pareigybės!$B$4:$C$9,2,0) -> 980 | E9: =D9/(22*8) -> 5.5681818 | F9: =CHOOSE(RANDBETWEEN(1,2),150,200) -> 150 | G9: x | H9: =CONCATENATE("+",370,RANDBETWEEN(1000000,9999999)) -> +3707643561 | I9: Jaunystės 4
A10: 5 | B10: Darbuotojas5 | C10: Vadybininkas | D10: =VLOOKUP(C10, Pareigybės!$B$4:$C$9,2,0) -> 1199 | E10: =D10/(22*8) -> 6.8125 | F10: =CHOOSE(RANDBETWEEN(1,2),150,200) -> 150 | G10: x | H10: =CONCATENATE("+",370,RANDBETWEEN(1000000,9999999)) -> +3702060735 | I10: Jaunystės 5
A11: 6 | B11: Darbuotojas6 | C11: Vadovas | D11: =VLOOKUP(C11, Pareigybės!$B$4:$C$9,2,0) -> 2800 | E11: =D11/(22*8) -> 15.909091 | F11: =CHOOSE(RANDBETWEEN(1,2),150,200) -> 150 | G11: x | H11: =CONCATENATE("+",370,RANDBETWEEN(1000000,9999999)) -> +3702837916 | I11: Jaunystės 6
A12: 7 | B12: Darbuotojas7 | C12: Vadybininkas | D12: =VLOOKUP(C12, Pareigybės!$B$4:$C$9,2,0) -> 1199 | E12: =D12/(22*8) -> 6.8125 | F12: =CHOOSE(RANDBETWEEN(1,2),150,200) -> 150 | G12: x | H12: =CONCATENATE("+",370,RANDBETWEEN(1000000,9999999)) -> +3705893988 | I12: Jaunystės 7
A13: 8 | B13: Darbuotojas8 | C13: Gamybos darbuotojas | D13: =VLOOKUP(C13, Pareigybės!$B$4:$C$9,2,0) -> 980 | E13: =D13/(22*8) -> 5.5681818 | F13: =CHOOSE(RANDBETWEEN(1,2),150,200) -> 150 | G13: x | H13: =CONCATENATE("+",370,RANDBETWEEN(1000000,9999999)) -> +3704736877 | I13: Jaunystės 8
A14: 9 | B14: Darbuotojas9 | C14: Buhalterė | D14: =VLOOKUP(C14, Pareigybės!$B$4:$C$9,2,0) -> 1600 | E14: =D14/(22*8) -> 9.0909091 | F14: =CHOOSE(RANDBETWEEN(1,2),150,200) -> 150 | G14: x | H14: =CONCATENATE("+",370,RANDBETWEEN(1000000,9999999)) -> +3702862979 | I14: Jaunystės 9
A15: 10 | B15: Darbuotojas10 | C15: Gamybos darbuotojas | D15: =VLOOKUP(C15, Pareigybės!$B$4:$C$9,2,0) -> 980 | E15: =D15/(22*8) -> 5.5681818 | F15: =CHOOSE(RANDBETWEEN(1,2),150,200) -> 200 | G15: x | H15: =CONCATENATE("+",370,RANDBETWEEN(1000000,9999999)) -> +3704692464 | I15: Jaunystės 10
A16: 11 | B16: Darbuotojas11 | C16: Gamybos darbuotojas | D16: =VLOOKUP(C16, Pareigybės!$B$4:$C$9,2,0) -> 980 | E16: =D16/(22*8) -> 5.5681818 | F16: =CHOOSE(RANDBETWEEN(1,2),150,200) -> 200 | G16: x | H16: =CONCATENATE("+",370,RANDBETWEEN(1000000,9999999)) -> +3709229730 | I16: Jaunystės 11
A17: 12 | B17: Darbuotojas12 | C17: Gamybos darbuotojas | D17: =VLOOKUP(C17, Pareigybės!$B$4:$C$9,2,0) -> 980 | E17: =D17/(22*8) -> 5.5681818 | F17: =CHOOSE(RANDBETWEEN(1,2),150,200) -> 200 | G17: x | H17: =CONCATENATE("+",370,RANDBETWEEN(1000000,9999999)) -> +3701311003 | I17: Jaunystės 12
... A20: 15 | B20: Darbuotojas15 | C20: Sandėlininkas | D20: =VLOOKUP(C20, Pareigybės!$B$4:$C$9,2,0) -> 1090 | E20: =D20/(22*8) -> 6.1931818 | F20: =CHOOSE(RANDBETWEEN(1,2),150,200) -> 200 | G20: x | H20: =CONCATENATE("+",370,RANDBETWEEN(1000000,9999999)) -> +3703732206 | I20: Jaunystės 15

Sheet Darbo užmokestis
A1: UAB "Jaunystė" | F1: GPM1 | G1: 0.2 | J1: Garantinis fondas | L1: 0.002 | N1: Ilgalaikio darbo išmokų fondo įmoka | R1: 0.0016
A2: Įmonės kodas 1222555888 | F2: GPM2 | G2: 0.27 | J2: Įmoka | N2: Soc. draudimo įmokos nelaimingų atsitikimų draudimui | R2: 0.0014
A3: Darbo užmokesčio registras | F3: VSD darbuotojo | G3: 0.1429
F4: PSD | G4: 0.0698
A5: Kov | F5: VSD darbdavio | G5: 0.0177
F6: Papildomas pensijinis kaupimas | G6: 0.03
A7: mėnuo | F7: Nedarbingumo pašalpa | G7: 0.65 | I7: Iš viso: | J7: =SUM(J10:J24) -> 15594.048 | K7: =SUM(K10:K24) -> 100 | L7: =SUM(L10:L24) -> 2366.3636 | M7: =SUM(M10:M24) -> 0 | N7: =SUM(N10:N24) -> 830.36364 | O7: =SUM(O10:O24) -> 18890.775 | P7: =SUM(P10:P24) -> 4922.7343 | Q7: =SUM(Q10:Q24) -> 2793.6081 | ... Y7: =SUM(Y10:Y24) -> 12855.51
A9: Registras | B9: Op. Nr. | C9: Skaičiavimo data | D9: Pavardė, vardas | E9: Pareiginis atlyginimas, € | F9: Valandinis tarifinis atlygis, € | G9: Nustatytas darbo dienų skaičius | H9: Faktiškai dirbta, d. | I9: Faktiškai dirbta, val. | J9: Atlyginimas, € | K9: Mėnesinė priemoka, € | L9: Eilinės atostogos, € | M9: Kompensacija už nepanaudotas atostogas, € | N9: Nedarbingumo pašalpa darbdavio lėšomis, € | O9: Priskaičiuota iš viso, € | P9: pritaikytas NPD, € | Q9: GPM, € | R9: VSD įmoka, € | S9: PSD įmoka, € | T9: Papildomas pensijinis kaupimas | U9: Išskaičiuota iš viso, € | V9: Išmokėtina suma, € | W9: Darbdavio VSD įmokos, € | X9: Avansas, € | Y9: Išmokėtina suma po avanso, €
A10: darbo užmokestis | B10: 1 | C10: =EOMONTH(DATE(2026,3,31),0) -> 46112 | D10: Darbuotojas1 | E10: =VLOOKUP(D10,Darbuotojai!B6:D20,3,FALSE) -> 1600 | F10: =VLOOKUP(D10,Darbuotojai!B6:E20,4,FALSE) -> 9.0909091 | G10: =NETWORKDAYS(DATE(2026,3,1),DATE(2026,3,31),DATE(2026,3,11)) -> 21 | H10: =RANDBETWEEN(15,G10) -> 16 | I10: =H10*8 -> 128 | J10: =E10*H10/G10 -> 1219.0476 | K10: =IF(H10=G10,50,0) -> 0 | L10: =IF(G10-H10>4,8*F10*(G10-H10),0) -> 363.63636 | M10: 0 | N10: =IF(G10-H10<4,8*F10*(G10-H10),0) -> 0 | O10: =SUM(J10:N10) -> 1582.684 | P10: =IF(O10<=730,460,IF(O10<1670,460-0.26*(O10-730),MAX(0,400-0.18*(O10-642)))) -> 238.30216 | Q10: =(O10-P10)*$G$1 -> 268.87636 | R10: =(O10*$G$4) -> 110.47134 | S10: =O10*$G$4 -> 110.47134 | T10: =O10*$G$6 -> 47.480519 | U10: =SUM(Q10:T10) -> 537.29957 | V10: =O10-U10 -> 1045.3844 | W10: =O10*$G$5 -> 28.013506 | X10: =O10*$L$1 -> 3.165368 | Y10: =V10-X10 -> 1042.219
A11: darbo užmokestis | B11: 2 | C11: =EOMONTH(DATE(2026,3,31),0) -> 46112 | D11: Darbuotojas2 | E11: =VLOOKUP(D11,Darbuotojai!B7:D21,3,FALSE) -> 1090 | F11: =VLOOKUP(D11,Darbuotojai!B7:E21,4,FALSE) -> 6.1931818 | G11: =NETWORKDAYS(DATE(2026,3,1),DATE(2026,3,31),DATE(2026,3,11)) -> 21 | H11: =RANDBETWEEN(15,G11) -> 19 | I11: =H11*8 -> 152 | J11: =E11*H11/G11 -> 986.19048 | K11: =IF(H11=G11,50,0) -> 0 | L11: =IF(G11-H11>4,8*F11*(G11-H11),0) -> 0 | M11: 0 | N11: =IF(G11-H11<4,8*F11*(G11-H11),0) -> 99.090909 | O11: =SUM(J11:N11) -> 1085.2814 | P11: =IF(O11<=730,460,IF(O11<1670,460-0.26*(O11-730),MAX(0,400-0.18*(O11-642)))) -> 367.62684 | Q11: =(O11-P11)*$G$1 -> 143.53091 | R11: =(O11*$G$4) -> 75.752641 | S11: =O11*$G$4 -> 75.752641 | T11: =O11*$G$6 -> 32.558442 | U11: =SUM(Q11:T11) -> 327.59463 | V11: =O11-U11 -> 757.68675 | W11: =O11*$G$5 -> 19.209481 | X11: =O11*$L$1 -> 2.1705628 | Y11: =V11-X11 -> 755.51619
A12: darbo užmokestis | B12: 3 | C12: =EOMONTH(DATE(2026,3,31),0) -> 46112 | D12: Darbuotojas3 | E12: =VLOOKUP(D12,Darbuotojai!B8:D22,3,FALSE) -> 980 | F12: =VLOOKUP(D12,Darbuotojai!B8:E22,4,FALSE) -> 5.5681818 | G12: =NETWORKDAYS(DATE(2026,3,1),DATE(2026,3,31),DATE(2026,3,11)) -> 21 | H12: =RANDBETWEEN(15,G12) -> 15 | I12: =H12*8 -> 120 | J12: =E12*H12/G12 -> 700 | K12: =IF(H12=G12,50,0) -> 0 | L12: =IF(G12-H12>4,8*F12*(G12-H12),0) -> 267.27273 | M12: 0 | N12: =IF(G12-H12<4,8*F12*(G12-H12),0) -> 0 | O12: =SUM(J12:N12) -> 967.27273 | P12: =IF(O12<=730,460,IF(O12<1670,460-0.26*(O12-730),MAX(0,400-0.18*(O12-642)))) -> 398.30909 | Q12: =(O12-P12)*$G$1 -> 113.79273 | R12: =(O12*$G$4) -> 67.515636 | S12: =O12*$G$4 -> 67.515636 | T12: =O12*$G$6 -> 29.018182 | U12: =SUM(Q12:T12) -> 277.84218 | V12: =O12-U12 -> 689.43055 | W12: =O12*$G$5 -> 17.120727 | X12: =O12*$L$1 -> 1.9345455 | Y12: =V12-X12 -> 687.496
A13: darbo užmokestis | B13: 4 | C13: =EOMONTH(DATE(2026,3,31),0) -> 46112 | D13: Darbuotojas4 | E13: =VLOOKUP(D13,Darbuotojai!B9:D23,3,FALSE) -> 980 | F13: =VLOOKUP(D13,Darbuotojai!B9:E23,4,FALSE) -> 5.5681818 | G13: =NETWORKDAYS(DATE(2026,3,1),DATE(2026,3,31),DATE(2026,3,11)) -> 21 | H13: =RANDBETWEEN(15,G13) -> 18 | I13: =H13*8 -> 144 | J13: =E13*H13/G13 -> 840 | K13: =IF(H13=G13,50,0) -> 0 | L13: =IF(G13-H13>4,8*F13*(G13-H13),0) -> 0 | M13: 0 | N13: =IF(G13-H13<4,8*F13*(G13-H13),0) -> 133.63636 | O13: =SUM(J13:N13) -> 973.63636 | P13: =IF(O13<=730,460,IF(O13<1670,460-0.26*(O13-730),MAX(0,400-0.18*(O13-642)))) -> 396.65455 | Q13: =(O13-P13)*$G$1 -> 115.39636 | R13: =(O13*$G$4) -> 67.959818 | S13: =O13*$G$4 -> 67.959818 | T13: =O13*$G$6 -> 29.209091 | U13: =SUM(Q13:T13) -> 280.52509 | V13: =O13-U13 -> 693.11127 | W13: =O13*$G$5 -> 17.233364 | X13: =O13*$L$1 -> 1.9472727 | Y13: =V13-X13 -> 691.164
A14: darbo užmokestis | B14: 5 | C14: =EOMONTH(DATE(2026,3,31),0) -> 46112 | D14: Darbuotojas5 | E14: =VLOOKUP(D14,Darbuotojai!B10:D24,3,FALSE) -> 1199 | F14: =VLOOKUP(D14,Darbuotojai!B10:E24,4,FALSE) -> 6.8125 | G14: =NETWORKDAYS(DATE(2026,3,1),DATE(2026,3,31),DATE(2026,3,11)) -> 21 | H14: =RANDBETWEEN(15,G14) -> 21 | I14: =H14*8 -> 168 | J14: =E14*H14/G14 -> 1199 | K14: =IF(H14=G14,50,0) -> 50 | L14: =IF(G14-H14>4,8*F14*(G14-H14),0) -> 0 | M14: 0 | N14: =IF(G14-H14<4,8*F14*(G14-H14),0) -> 0 | O14: =SUM(J14:N14) -> 1249 | P14: =IF(O14<=730,460,IF(O14<1670,460-0.26*(O14-730),MAX(0,400-0.18*(O14-642)))) -> 325.06 | Q14: =(O14-P14)*$G$1 -> 184.788 | R14: =(O14*$G$4) -> 87.1802 | S14: =O14*$G$4 -> 87.1802 | T14: =O14*$G$6 -> 37.47 | U14: =SUM(Q14:T14) -> 396.6184 | V14: =O14-U14 -> 852.3816 | W14: =O14*$G$5 -> 22.1073 | X14: =O14*$L$1 -> 2.498 | Y14: =V14-X14 -> 849.8836
A15: darbo užmokestis | B15: 6 | C15: =EOMONTH(DATE(2026,3,31),0) -> 46112 | D15: Darbuotojas6 | E15: =VLOOKUP(D15,Darbuotojai!B11:D25,3,FALSE) -> 2800 | F15: =VLOOKUP(D15,Darbuotojai!B11:E25,4,FALSE) -> 15.909091 | G15: =NETWORKDAYS(DATE(2026,3,1),DATE(2026,3,31),DATE(2026,3,11)) -> 21 | H15: =RANDBETWEEN(15,G15) -> 16 | I15: =H15*8 -> 128 | J15: =E15*H15/G15 -> 2133.3333 | K15: =IF(H15=G15,50,0) -> 0 | L15: =IF(G15-H15>4,8*F15*(G15-H15),0) -> 636.36364 | M15: 0 | N15: =IF(G15-H15<4,8*F15*(G15-H15),0) -> 0 | O15: =SUM(J15:N15) -> 2769.697 | P15: =IF(O15<=730,460,IF(O15<1670,460-0.26*(O15-730),MAX(0,400-0.18*(O15-642)))) -> 17.014545 | Q15: =(O15-P15)*$G$1 -> 550.53648 | R15: =(O15*$G$4) -> 193.32485 | S15: =O15*$G$4 -> 193.32485 | T15: =O15*$G$6 -> 83.090909 | U15: =SUM(Q15:T15) -> 1020.2771 | V15: =O15-U15 -> 1749.4199 | W15: =O15*$G$5 -> 49.023636 | X15: =O15*$L$1 -> 5.5393939 | Y15: =V15-X15 -> 1743.8805
A16: darbo užmokestis | B16: 7 | C16: =EOMONTH(DATE(2026,3,31),0) -> 46112 | D16: Darbuotojas7 | E16: =VLOOKUP(D16,Darbuotojai!B12:D26,3,FALSE) -> 1199 | F16: =VLOOKUP(D16,Darbuotojai!B12:E26,4,FALSE) -> 6.8125 | G16: =NETWORKDAYS(DATE(2026,3,1),DATE(2026,3,31),DATE(2026,3,11)) -> 21 | H16: =RANDBETWEEN(15,G16) -> 19 | I16: =H16*8 -> 152 | J16: =E16*H16/G16 -> 1084.8095 | K16: =IF(H16=G16,50,0) -> 0 | L16: =IF(G16-H16>4,8*F16*(G16-H16),0) -> 0 | M16: 0 | N16: =IF(G16-H16<4,8*F16*(G16-H16),0) -> 109 | O16: =SUM(J16:N16) -> 1193.8095 | P16: =IF(O16<=730,460,IF(O16<1670,460-0.26*(O16-730),MAX(0,400-0.18*(O16-642)))) -> 339.40952 | Q16: =(O16-P16)*$G$1 -> 170.88 | R16: =(O16*$G$4) -> 83.327905 | S16: =O16*$G$4 -> 83.327905 | T16: =O16*$G$6 -> 35.814286 | U16: =SUM(Q16:T16) -> 373.3501 | V16: =O16-U16 -> 820.45943 | W16: =O16*$G$5 -> 21.130429 | X16: =O16*$L$1 -> 2.387619 | Y16: =V16-X16 -> 818.07181
A17: darbo užmokestis | B17: 8 | C17: =EOMONTH(DATE(2026,3,31),0) -> 46112 | D17: Darbuotojas8 | E17: =VLOOKUP(D17,Darbuotojai!B13:D27,3,FALSE) -> 980 | F17: =VLOOKUP(D17,Darbuotojai!B13:E27,4,FALSE) -> 5.5681818 | G17: =NETWORKDAYS(DATE(2026,3,1),DATE(2026,3,31),DATE(2026,3,11)) -> 21 | H17: =RANDBETWEEN(15,G17) -> 15 | I17: =H17*8 -> 120 | J17: =E17*H17/G17 -> 700 | K17: =IF(H17=G17,50,0) -> 0 | L17: =IF(G17-H17>4,8*F17*(G17-H17),0) -> 267.27273 | M17: 0 | N17: =IF(G17-H17<4,8*F17*(G17-H17),0) -> 0 | O17: =SUM(J17:N17) -> 967.27273 | P17: =IF(O17<=730,460,IF(O17<1670,460-0.26*(O17-730),MAX(0,400-0.18*(O17-642)))) -> 398.30909 | Q17: =(O17-P17)*$G$1 -> 113.79273 | R17: =(O17*$G$4) -> 67.515636 | S17: =O17*$G$4 -> 67.515636 | T17: =O17*$G$6 -> 29.018182 | U17: =SUM(Q17:T17) -> 277.84218 | V17: =O17-U17 -> 689.43055 | W17: =O17*$G$5 -> 17.120727 | X17: =O17*$L$1 -> 1.9345455 | Y17: =V17-X17 -> 687.496
A18: darbo užmokestis | B18: 9 | C18: =EOMONTH(DATE(2026,3,31),0) -> 46112 | D18: Darbuotojas9 | E18: =VLOOKUP(D18,Darbuotojai!B14:D28,3,FALSE) -> 1600 | F18: =VLOOKUP(D18,Darbuotojai!B14:E28,4,FALSE) -> 9.0909091 | G18: =NETWORKDAYS(DATE(2026,3,1),DATE(2026,3,31),DATE(2026,3,11)) -> 21 | H18: =RANDBETWEEN(15,G18) -> 18 | I18: =H18*8 -> 144 | J18: =E18*H18/G18 -> 1371.4286 | K18: =IF(H18=G18,50,0) -> 0 | L18: =IF(G18-H18>4,8*F18*(G18-H18),0) -> 0 | M18: 0 | N18: =IF(G18-H18<4,8*F18*(G18-H18),0) -> 218.18182 | O18: =SUM(J18:N18) -> 1589.6104 | P18: =IF(O18<=730,460,IF(O18<1670,460-0.26*(O18-730),MAX(0,400-0.18*(O18-642)))) -> 236.5013 | Q18: =(O18-P18)*$G$1 -> 270.62182 | R18: =(O18*$G$4) -> 110.95481 | S18: =O18*$G$4 -> 110.95481 | T18: =O18*$G$6 -> 47.688312 | U18: =SUM(Q18:T18) -> 540.21974 | V18: =O18-U18 -> 1049.3906 | W18: =O18*$G$5 -> 28.136104 | X18: =O18*$L$1 -> 3.1792208 | Y18: =V18-X18 -> 1046.2114
A19: darbo užmokestis | B19: 10 | C19: =EOMONTH(DATE(2026,3,31),0) -> 46112 | D19: Darbuotojas10 | E19: =VLOOKUP(D19,Darbuotojai!B15:D29,3,FALSE) -> 980 | F19: =VLOOKUP(D19,Darbuotojai!B15:E29,4,FALSE) -> 5.5681818 | G19: =NETWORKDAYS(DATE(2026,3,1),DATE(2026,3,31),DATE(2026,3,11)) -> 21 | H19: =RANDBETWEEN(15,G19) -> 18 | I19: =H19*8 -> 144 | J19: =E19*H19/G19 -> 840 | K19: =IF(H19=G19,50,0) -> 0 | L19: =IF(G19-H19>4,8*F19*(G19-H19),0) -> 0 | M19: 0 | N19: =IF(G19-H19<4,8*F19*(G19-H19),0) -> 133.63636 | O19: =SUM(J19:N19) -> 973.63636 | P19: =IF(O19<=730,460,IF(O19<1670,460-0.26*(O19-730),MAX(0,400-0.18*(O19-642)))) -> 396.65455 | Q19: =(O19-P19)*$G$1 -> 115.39636 | R19: =(O19*$G$4) -> 67.959818 | S19: =O19*$G$4 -> 67.959818 | T19: =O19*$G$6 -> 29.209091 | U19: =SUM(Q19:T19) -> 280.52509 | V19: =O19-U19 -> 693.11127 | W19: =O19*$G$5 -> 17.233364 | X19: =O19*$L$1 -> 1.9472727 | Y19: =V19-X19 -> 691.164
A20: darbo užmokestis | B20: 11 | C20: =EOMONTH(DATE(2026,3,31),0) -> 46112 | D20: Darbuotojas11 | E20: =VLOOKUP(D20,Darbuotojai!B16:D30,3,FALSE) -> 980 | F20: =VLOOKUP(D20,Darbuotojai!B16:E30,4,FALSE) -> 5.5681818 | G20: =NETWORKDAYS(DATE(2026,3,1),DATE(2026,3,31),DATE(2026,3,11)) -> 21 | H20: =RANDBETWEEN(15,G20) -> 15 | I20: =H20*8 -> 120 | J20: =E20*H20/G20 -> 700 | K20: =IF(H20=G20,50,0) -> 0 | L20: =IF(G20-H20>4,8*F20*(G20-H20),0) -> 267.27273 | M20: 0 | N20: =IF(G20-H20<4,8*F20*(G20-H20),0) -> 0 | O20: =SUM(J20:N20) -> 967.27273 | P20: =IF(O20<=730,460,IF(O20<1670,460-0.26*(O20-730),MAX(0,400-0.18*(O20-642)))) -> 398.30909 | Q20: =(O20-P20)*$G$1 -> 113.79273 | R20: =(O20*$G$4) -> 67.515636 | S20: =O20*$G$4 -> 67.515636 | T20: =O20*$G$6 -> 29.018182 | U20: =SUM(Q20:T20) -> 277.84218 | V20: =O20-U20 -> 689.43055 | W20: =O20*$G$5 -> 17.120727 | X20: =O20*$L$1 -> 1.9345455 | Y20: =V20-X20 -> 687.496
A21: darbo užmokestis | B21: 12 | C21: =EOMONTH(DATE(2026,3,31),0) -> 46112 | D21: Darbuotojas12 | E21: =VLOOKUP(D21,Darbuotojai!B17:D31,3,FALSE) -> 980 | F21: =VLOOKUP(D21,Darbuotojai!B17:E31,4,FALSE) -> 5.5681818 | G21: =NETWORKDAYS(DATE(2026,3,1),DATE(2026,3,31),DATE(2026,3,11)) -> 21 | H21: =RANDBETWEEN(15,G21) -> 21 | I21: =H21*8 -> 168 | J21: =E21*H21/G21 -> 980 | K21: =IF(H21=G21,50,0) -> 50 | L21: =IF(G21-H21>4,8*F21*(G21-H21),0) -> 0 | M21: 0 | N21: =IF(G21-H21<4,8*F21*(G21-H21),0) -> 0 | O21: =SUM(J21:N21) -> 1030 | P21: =IF(O21<=730,460,IF(O21<1670,460-0.26*(O21-730),MAX(0,400-0.18*(O21-642)))) -> 382 | Q21: =(O21-P21)*$G$1 -> 129.6 | R21: =(O21*$G$4) -> 71.894 | S21: =O21*$G$4 -> 71.894 | T21: =O21*$G$6 -> 30.9 | U21: =SUM(Q21:T21) -> 304.288 | V21: =O21-U21 -> 725.712 | W21: =O21*$G$5 -> 18.231 | X21: =O21*$L$1 -> 2.06 | Y21: =V21-X21 -> 723.652
... A24: darbo užmokestis | B24: 15 | C24: =EOMONTH(DATE(2026,3,31),0) -> 46112 | D24: Darbuotojas15 | E24: =VLOOKUP(D24,Darbuotojai!B20:D34,3,FALSE) -> 1090 | F24: =VLOOKUP(D24,Darbuotojai!B20:E34,4,FALSE) -> 6.1931818 | G24: =NETWORKDAYS(DATE(2026,3,1),DATE(2026,3,31),DATE(2026,3,11)) -> 21 | H24: =RANDBETWEEN(15,G24) -> 15 | I24: =H24*8 -> 120 | J24: =E24*H24/G24 -> 778.57143 | K24: =IF(H24=G24,50,0) -> 0 | L24: =IF(G24-H24>4,8*F24*(G24-H24),0) -> 297.27273 | M24: 0 | N24: =IF(G24-H24<4,8*F24*(G24-H24),0) -> 0 | O24: =SUM(J24:N24) -> 1075.8442 | P24: =IF(O24<=730,460,IF(O24<1670,460-0.26*(O24-730),MAX(0,400-0.18*(O24-642)))) -> 370.08052 | Q24: =(O24-P24)*$G$1 -> 141.15273 | R24: =(O24*$G$4) -> 75.093922 | S24: =O24*$G$4 -> 75.093922 | T24: =O24*$G$6 -> 32.275325 | U24: =SUM(Q24:T24) -> 323.6159 | V24: =O24-U24 -> 752.22826 | W24: =O24*$G$5 -> 19.042442 | X24: =O24*$L$1 -> 2.1516883 | Y24: =V24-X24 -> 750.07657
L25: ,
L26: ,
L27: ,
L28: ,
L29: ,
L30: ,
L31: ,
L32: ,
L33: ,
L34: ,
L35: ,
L36: ,
... L83: ,

Sheet suvestinė
A3: 1 | B3: Keli darbuotojai dirbo 18 ir daugiau dienų
A4: 2 | B4: Darbuotojų, kurie dirbo mažiau nei 18 dienų, išmokamų atlyginimų suma
A5: 3 | B5: Vidutinė avanso suma
A6: 4 | B6: Darbuotojų, kurių valandinis įkainis mažiau nei 8 eurai, sumokamų VSD vidurkis
A7: 5 | B7: Pritaikyto NPD mediana
A8: 6 | B8: 2 didžiausia GPM reikšmė
