Workbook

Sheet Užduotis
A1: Savarankiško darbo užduotis:
A3: Darbalapis "Darbuotojai"
B4: Stulpelio pavadinimas | C4: Užduotis | D4: Pastabos
A5: 1 | B5: Eil. Nr. | C5: Sukurkite seką
A6: 2 | B6: Pavardė, vardas | C6: Sukurkite seką "Darbuotojas1" ir t.t.
A7: 3 | B7: Pareigos | C7: Sudarykite sąrašą ir parinkite vieną iš pateiktų pareigybių kiekvienam darbuotojui. Pareigybių skaičius duotas "Pareigybės" lape | D7: sąrašas
A8: 4 | B8: Pareiginis atlyginimas, € | C8: Parinkite kiekvienam darbuotojui pareiginį atlyginimą pagal pareigas | D8: vlookup()
A9: 5 | B9: Valandinis tarifinis atlygis, € | C9: Apskaičiuokite iš pareiginio atlyginimo imdami vidutinį mėnesio darbo dienų skaičių 22
A10: 6 | B10: Avansas, € | C10: Avansą parinkite atsitiktiniu būdu 150 arba 200 eurų | D10: choose()
A11: 7 | B11: Asmens kodas | C11: nepildyti
A12: 8 | B12: Tel. Nr. | C12: sujunkite "+370 6" ir 7 atsitiktiniai skaičiai | D12: concatenate()
A13: 9 | B13: Adresas | C13: sugalvokite patys
A16: Darbalapis "Darbo užmokestis"
B17: Stulpelio pavadinimas | C17: Užduotis
A18: 1 | B18: A5 | C18: Įrašykite kovo mėnesį
A19: 2 | B19: Registras | C19: Darbo užmokestis
A20: 3 | B20: Op. Nr. | C20: tarkime, kad darote registrą kovo mėnesiui, tada rašykite visur 03
A21: 4 | B21: Skaičiavimo data | C21: Pasirinkite šių metų kovo datą formatas: 2022/kov/31 | D21: eomonth()
A22: 5 | B22: Pavardė, vardas | C22: nukopijuokite darbuotojus iš darbuotojų lapo
A23: 6 | B23: Pareiginis atlyginimas, € | C23: Parinkite kiekvienam darbuotojui pareiginį atlyginimą iš darbuotojų lapo | D23: vlookup()
A24: 7 | B24: Valandinis tarifinis atlygis, € | C24: Parinkite kiekvienam darbuotojui pareiginį valandinį atlyginimą iš darbuotojų lapo | D24: vlookup()
A25: 8 | B25: Nustatytas darbo dienų skaičius | C25: apskaičiuokite darbo dienų skaičių su funkcija Networkdays(). Nepamirškite švenčių dienų.
A26: 9 | B26: Faktiškai dirbta, d. | C26: parinkite atsitiktiniu būdu nuo 15 iki mėnesio darbo dienų skaičiaus | D26: randbetween()
A27: 10 | B27: Faktiškai dirbta, val. | C27: dienos * 8 val.
A28: 11 | B28: Atlyginimas, € | C28: atlyginimas priskaičiuotas už dirbtas dienas | D28: atlyginimas*fakt.dirbtų d./d.d.skaičius
A29: 12 | B29: Mėnesinė priemoka, € | C29: Skirkite mėnesinę priemoką 50 eurų, jei dirbo visas darbo dienas | D29: IF
A30: 13 | B30: Eilinės atostogos, € | C30: Jei darbuotojas nedirbo daugiau nei 4 dienas, tada jis tas dienas buvo atostogose. Paskaičiuokite už tas dienas atostoginius | D30: IF
A31: 14 | B31: Kompensacija už nepanaudotas atostogas, € | C31: 0
A32: 15 | B32: Nedarbingumo pašalpa darbdavio lėšomis, € | C32: Jei darbuotojas nedirbo 4 ar mažiau dienų, tada jis sirgo. Paskaičiuokite už tas 1-2 dienas darbdavio mokamą atlyginimą | D32: IF
A33: 16 | B33: Priskaičiuota iš viso, € | C33: Visos priskaičiuotos sumos
A34: 17 | B34: pritaikytas NPD, € | C34: paskaičiuokite pagal dešinėje duotas formules | H34: Neapmokestinamo minimumo skaičiavimas:
A35: 18 | B35: GPM, € | C35: GMP=(Priskaičiuota - NPD)*20% | D35: koeficientams suteikite vardus | G35: 1) | H35: NPD max - 460 Eur. Taikomas pajamoms iki 730 Eur.
A36: 19 | B36: VSD ir PSD įmokos, € | C36: 14,29% nuo priskaičiuoto atlygio atėmus nedarbingumo pašalpos sumą, PSD - 6,98% | G36: 2) | H36: NPD = 460 – 0,26* (gyventojo mėnesio su darbo santykiais arba jų esmę atitinkančiais santykiais susijusios pajamos – 730) | R36: jei Du<1678
A37: 20 | B37: Papildomas pensijinis kaupimas | C37: 3% nuo priskaičiuoto atlygio | G37: 3) | H37: NPD = 400 – 0,18* (gyventojo mėnesio su darbo santykiais arba jų esmę atitinkančiais santykiais susijusios pajamos – 642) | R37: jei Du>1678
A38: 21 | B38: Išskaičiuota iš viso, € | C38: visa išskaičiuota suma mokesčiams | G38: 4) | H38: Jei neigiamas tai rašome 0
A39: 22 | B39: Išmokėtina suma, € | C39: Išmokama = priskaičiuota - išskaičiuota
A40: 23 | B40: Darbdavio VSD įmokos, € | C40: VSD (1,77%) * priskaičiuota
A41: 24 | B41: Avansas, € | C41: Parinkite iš darbuotojų lapo | D41: vlookup()
A42: 25 | B42: Išmokėtina suma po avanso, € | C42: Išmokama suma atėmus avansą
A43: 26 | B43: Garantinis fondas | C43: 0,2% nuo visiems darbuotojams priskaičiuotų atlyginimų
...

Sheet Pareigybės
A3: Eil. Nr. | B3: Pareigybė | C3: Pareiginis atlyginimas, € | D3: Darbuotojų skaičius
A4: 1 | B4: Vadovas | C4: 2800 | D4: 1
A5: 2 | B5: Buhalterė | C5: 1600 | D5: 2
A6: 3 | B6: Administratorė | C6: 1505 | D6: 1
A7: 4 | B7: Vadybininkas | C7: 1199 | D7: 2
A8: 5 | B8: Sandėlininkas | C8: 1090 | D8: 2
A9: 6 | B9: Gamybos darbuotojas | C9: 980 | D9: 7

Sheet Darbuotojai
A1: Darbuotojai
A5: Eil. Nr. | B5: Pavardė, vardas | C5: Pareigos | D5: Pareiginis atlyginimas, € | E5: Valandinis tarifinis atlygis, € | F5: Avansas, € | G5: Asmens kodas | H5: Tel. Nr. | I5: Adresas
A6: 1 | B6: Darbuotojas1 | C6: =Pareigybės!B4 -> Vadovas | D6: =VLOOKUP(C6,Pareigybės!$B$4:$C$9,2,0) -> 2800 | E6: =D6/(22*8) -> 15.909091 | F6: =CHOOSE(RANDBETWEEN(1,2),150,200) -> 150 | G6: x | H6: =CONCATENATE(3706,RANDBETWEEN(0,9),RANDBETWEEN(0,9),RANDBETWEEN(0,9),RANDBETWEEN(0,9),RANDBETWEEN(0,9),RANDBETWEEN(0,9),RANDBETWEEN(0,9)) -> 37067779269 | I6: Jaunystės 1
A7: 2 | B7: Darbuotojas2 | C7: =Pareigybės!$B$5 -> Buhalterė | D7: =VLOOKUP(C7,Pareigybės!$B$4:$C$9,2,0) -> 1600 | E7: =D7/(22*8) -> 9.0909091 | F7: =CHOOSE(RANDBETWEEN(1,2),150,200) -> 200 | G7: x | H7: =CONCATENATE(3706,RANDBETWEEN(0,9),RANDBETWEEN(0,9),RANDBETWEEN(0,9),RANDBETWEEN(0,9),RANDBETWEEN(0,9),RANDBETWEEN(0,9),RANDBETWEEN(0,9)) -> 37066834428 | I7: Jaunystės 2
A8: 3 | B8: Darbuotojas3 | C8: =Pareigybės!$B$5 -> Buhalterė | D8: =VLOOKUP(C8,Pareigybės!$B$4:$C$9,2,0) -> 1600 | E8: =D8/(22*8) -> 9.0909091 | F8: =CHOOSE(RANDBETWEEN(1,2),150,200) -> 200 | G8: x | H8: =CONCATENATE(3706,RANDBETWEEN(0,9),RANDBETWEEN(0,9),RANDBETWEEN(0,9),RANDBETWEEN(0,9),RANDBETWEEN(0,9),RANDBETWEEN(0,9),RANDBETWEEN(0,9)) -> 37061833774 | I8: Jaunystės 3
A9: 4 | B9: Darbuotojas4 | C9: =Pareigybės!$B$6 -> Administratorė | D9: =VLOOKUP(C9,Pareigybės!$B$4:$C$9,2,0) -> 1505 | E9: =D9/(22*8) -> 8.5511364 | F9: =CHOOSE(RANDBETWEEN(1,2),150,200) -> 200 | G9: x | H9: =CONCATENATE(3706,RANDBETWEEN(0,9),RANDBETWEEN(0,9),RANDBETWEEN(0,9),RANDBETWEEN(0,9),RANDBETWEEN(0,9),RANDBETWEEN(0,9),RANDBETWEEN(0,9)) -> 37069186926 | I9: Jaunystės 4
A10: 5 | B10: Darbuotojas5 | C10: =Pareigybės!$B$7 -> Vadybininkas | D10: =VLOOKUP(C10,Pareigybės!$B$4:$C$9,2,0) -> 1199 | E10: =D10/(22*8) -> 6.8125 | F10: =CHOOSE(RANDBETWEEN(1,2),150,200) -> 200 | G10: x | H10: =CONCATENATE(3706,RANDBETWEEN(0,9),RANDBETWEEN(0,9),RANDBETWEEN(0,9),RANDBETWEEN(0,9),RANDBETWEEN(0,9),RANDBETWEEN(0,9),RANDBETWEEN(0,9)) -> 37065913347 | I10: Jaunystės 5
A11: 6 | B11: Darbuotojas6 | C11: =Pareigybės!$B$7 -> Vadybininkas | D11: =VLOOKUP(C11,Pareigybės!$B$4:$C$9,2,0) -> 1199 | E11: =D11/(22*8) -> 6.8125 | F11: =CHOOSE(RANDBETWEEN(1,2),150,200) -> 150 | G11: x | H11: =CONCATENATE(3706,RANDBETWEEN(0,9),RANDBETWEEN(0,9),RANDBETWEEN(0,9),RANDBETWEEN(0,9),RANDBETWEEN(0,9),RANDBETWEEN(0,9),RANDBETWEEN(0,9)) -> 37063513645 | I11: Jaunystės 6
A12: 7 | B12: Darbuotojas7 | C12: =Pareigybės!$B$8 -> Sandėlininkas | D12: =VLOOKUP(C12,Pareigybės!$B$4:$C$9,2,0) -> 1090 | E12: =D12/(22*8) -> 6.1931818 | F12: =CHOOSE(RANDBETWEEN(1,2),150,200) -> 150 | G12: x | H12: =CONCATENATE(3706,RANDBETWEEN(0,9),RANDBETWEEN(0,9),RANDBETWEEN(0,9),RANDBETWEEN(0,9),RANDBETWEEN(0,9),RANDBETWEEN(0,9),RANDBETWEEN(0,9)) -> 37063539796 | I12: Jaunystės 7
A13: 8 | B13: Darbuotojas8 | C13: =Pareigybės!$B$8 -> Sandėlininkas | D13: =VLOOKUP(C13,Pareigybės!$B$4:$C$9,2,0) -> 1090 | E13: =D13/(22*8) -> 6.1931818 | F13: =CHOOSE(RANDBETWEEN(1,2),150,200) -> 200 | G13: x | H13: =CONCATENATE(3706,RANDBETWEEN(0,9),RANDBETWEEN(0,9),RANDBETWEEN(0,9),RANDBETWEEN(0,9),RANDBETWEEN(0,9),RANDBETWEEN(0,9),RANDBETWEEN(0,9)) -> 37060996537 | I13: Jaunystės 8
A14: 9 | B14: Darbuotojas9 | C14: =Pareigybės!$B$9 -> Gamybos darbuotojas | D14: =VLOOKUP(C14,Pareigybės!$B$4:$C$9,2,0) -> 980 | E14: =D14/(22*8) -> 5.5681818 | F14: =CHOOSE(RANDBETWEEN(1,2),150,200) -> 150 | G14: x | H14: =CONCATENATE(3706,RANDBETWEEN(0,9),RANDBETWEEN(0,9),RANDBETWEEN(0,9),RANDBETWEEN(0,9),RANDBETWEEN(0,9),RANDBETWEEN(0,9),RANDBETWEEN(0,9)) -> 37064914560 | I14: Jaunystės 9
A15: 10 | B15: Darbuotojas10 | C15: =Pareigybės!$B$9 -> Gamybos darbuotojas | D15: =VLOOKUP(C15,Pareigybės!$B$4:$C$9,2,0) -> 980 | E15: =D15/(22*8) -> 5.5681818 | F15: =CHOOSE(RANDBETWEEN(1,2),150,200) -> 200 | G15: x | H15: =CONCATENATE(3706,RANDBETWEEN(0,9),RANDBETWEEN(0,9),RANDBETWEEN(0,9),RANDBETWEEN(0,9),RANDBETWEEN(0,9),RANDBETWEEN(0,9),RANDBETWEEN(0,9)) -> 37065334320 | I15: Jaunystės 10
A16: 11 | B16: Darbuotojas11 | C16: =Pareigybės!$B$9 -> Gamybos darbuotojas | D16: =VLOOKUP(C16,Pareigybės!$B$4:$C$9,2,0) -> 980 | E16: =D16/(22*8) -> 5.5681818 | F16: =CHOOSE(RANDBETWEEN(1,2),150,200) -> 150 | G16: x | H16: =CONCATENATE(3706,RANDBETWEEN(0,9),RANDBETWEEN(0,9),RANDBETWEEN(0,9),RANDBETWEEN(0,9),RANDBETWEEN(0,9),RANDBETWEEN(0,9),RANDBETWEEN(0,9)) -> 37068489642 | I16: Jaunystės 11
A17: 12 | B17: Darbuotojas12 | C17: =Pareigybės!$B$9 -> Gamybos darbuotojas | D17: =VLOOKUP(C17,Pareigybės!$B$4:$C$9,2,0) -> 980 | E17: =D17/(22*8) -> 5.5681818 | F17: =CHOOSE(RANDBETWEEN(1,2),150,200) -> 200 | G17: x | H17: =CONCATENATE(3706,RANDBETWEEN(0,9),RANDBETWEEN(0,9),RANDBETWEEN(0,9),RANDBETWEEN(0,9),RANDBETWEEN(0,9),RANDBETWEEN(0,9),RANDBETWEEN(0,9)) -> 37068456194 | I17: Jaunystės 12
A18: 13 | B18: Darbuotojas13 | C18: =Pareigybės!$B$9 -> Gamybos darbuotojas | D18: =VLOOKUP(C18,Pareigybės!$B$4:$C$9,2,0) -> 980 | E18: =D18/(22*8) -> 5.5681818 | F18: =CHOOSE(RANDBETWEEN(1,2),150,200) -> 200 | G18: x | H18: =CONCATENATE(3706,RANDBETWEEN(0,9),RANDBETWEEN(0,9),RANDBETWEEN(0,9),RANDBETWEEN(0,9),RANDBETWEEN(0,9),RANDBETWEEN(0,9),RANDBETWEEN(0,9)) -> 37061539330 | I18: Jaunystės 13
A19: 14 | B19: Darbuotojas14 | C19: =Pareigybės!$B$9 -> Gamybos darbuotojas | D19: =VLOOKUP(C19,Pareigybės!$B$4:$C$9,2,0) -> 980 | E19: =D19/(22*8) -> 5.5681818 | F19: =CHOOSE(RANDBETWEEN(1,2),150,200) -> 200 | G19: x | H19: =CONCATENATE(3706,RANDBETWEEN(0,9),RANDBETWEEN(0,9),RANDBETWEEN(0,9),RANDBETWEEN(0,9),RANDBETWEEN(0,9),RANDBETWEEN(0,9),RANDBETWEEN(0,9)) -> 37064434751 | I19: Jaunystės 14
A20: 15 | B20: Darbuotojas15 | C20: =Pareigybės!$B$9 -> Gamybos darbuotojas | D20: =VLOOKUP(C20,Pareigybės!$B$4:$C$9,2,0) -> 980 | E20: =D20/(22*8) -> 5.5681818 | F20: =CHOOSE(RANDBETWEEN(1,2),150,200) -> 200 | G20: x | H20: =CONCATENATE(3706,RANDBETWEEN(0,9),RANDBETWEEN(0,9),RANDBETWEEN(0,9),RANDBETWEEN(0,9),RANDBETWEEN(0,9),RANDBETWEEN(0,9),RANDBETWEEN(0,9)) -> 37068830701 | I20: Jaunystės 15

Sheet Darbo užmokestis
A1: UAB "Jaunystė" | F1: GPM1 | G1: 0.2 | J1: Garantinis fondas | L1: 0.002 | N1: Ilgalaikio darbo išmokų fondo įmoka | R1: 0.0016
A2: Įmonės kodas 1222555888 | F2: GPM2 | G2: 0.27 | J2: Įmoka | N2: Soc. draudimo įmokos nelaimingų atsitikimų draudimui | R2: 0.0014
A3: Darbo užmokesčio registras | F3: VSD darbuotojo | G3: 0.1429
F4: PSD | G4: 0.0698
F5: VSD darbdavio | G5: 0.0177
F6: Papildomas pensijinis kaupimas | G6: 0.03
A7: mėnuo | F7: Nedarbingumo pašalpa | G7: 0.65 | I7: Iš viso: | J7: =SUM(J10:J24) -> 16367.286 | K7: =SUM(K10:K24) -> 100 | L7: =SUM(L10:L24) -> 1491.1364 | M7: =SUM(M10:M24) -> 0 | N7: =SUM(N10:N24) -> 628.875 | O7: =SUM(O10:O24) -> 18587.297 | P7: =SUM(P10:P24) -> 5008.0628 | Q7: =SUM(Q10:Q24) -> 2715.8469 | ... Y7: =SUM(Y10:Y24) -> 8855.1362
A9: Registras | B9: Op. Nr. | C9: Skaičiavimo data | D9: Pavardė, vardas | E9: Pareiginis atlyginimas, € | F9: Valandinis tarifinis atlygis, € | G9: Nustatytas darbo dienų skaičius | H9: Faktiškai dirbta, d. | I9: Faktiškai dirbta, val. | J9: Atlyginimas, € | K9: Mėnesinė priemoka, € | L9: Eilinės atostogos, € | M9: Kompensacija už nepanaudotas atostogas, € | N9: Nedarbingumo pašalpa darbdavio lėšomis, € | O9: Priskaičiuota iš viso, € | P9: pritaikytas NPD, € | Q9: GPM, € | R9: VSD įmoka, € | S9: PSD įmoka, € | T9: Papildomas pensijinis kaupimas | U9: Išskaičiuota iš viso, € | V9: Išmokėtina suma, € | W9: Darbdavio VSD įmokos, € | X9: Avansas, € | Y9: Išmokėtina suma po avanso, €
A10: darbo užmokestis | B10: 3 | C10: =EOMONTH(DATE(2026,3,1),0) -> 46112 | D10: =Darbuotojai!B6 -> Darbuotojas1 | E10: =Darbuotojai!D6 -> 2800 | F10: =VLOOKUP(D10,Darbuotojai!B6:E20,4,FALSE) -> 15.909091 | G10: =NETWORKDAYS(DATE(2026,3,1),DATE(2026,3,31),DATE(2026,3,11)) -> 21 | H10: =RANDBETWEEN(15,G10) -> 21 | I10: =H10*8 -> 168 | J10: =E10*H10/G10 -> 2800 | K10: =IF(H10=21,50,0) -> 50 | L10: =IF(G10-H10>4,(G10-H10)*8*F10,0) -> 0 | M10: =Užduotis!$C$31 -> 0 | N10: =IF(G10-H10<=4,(G10-H10)*8*F10*$G$7,0) -> 0 | O10: =SUM(J10:N10) -> 2850 | P10: =IF(O10<=730,460,IF(O10<1670,460-0.26*(O10-730),MAX(0,400-0.18*(O10-642)))) -> 2.56 | Q10: =(O10-P10)*20% -> 569.488 | R10: =$G$3*(O10-N10) -> 407.265 | S10: =J10*$G$4 -> 195.44 | T10: =$G$6*O10 -> 85.5 | U10: =SUM(Q10:T10) -> 1257.693 | V10: =O10-U10 -> 1592.307 | W10: =$G$5*O10 -> 50.445 | X10: =VLOOKUP(D10,Darbuotojai!B6:F20,5,0) -> 150 | Y10: ='Darbo užmokestis'!V10-'Darbo užmokestis'!X10 -> 1442.307
A11: darbo užmokestis | B11: 3 | C11: =EOMONTH(DATE(2026,3,1),0) -> 46112 | D11: =Darbuotojai!B7 -> Darbuotojas2 | E11: =Darbuotojai!D7 -> 1600 | F11: =VLOOKUP(D11,Darbuotojai!B7:E21,4,FALSE) -> 9.0909091 | G11: =NETWORKDAYS(DATE(2026,3,1),DATE(2026,3,31),DATE(2026,3,11)) -> 21 | H11: =RANDBETWEEN(15,G11) -> 15 | I11: =H11*8 -> 120 | J11: =E11*H11/G11 -> 1142.8571 | K11: =IF(H11=21,50,0) -> 0 | L11: =IF(G11-H11>4,(G11-H11)*8*F11,0) -> 436.36364 | M11: =Užduotis!$C$31 -> 0 | N11: =IF(G11-H11<=4,(G11-H11)*8*F11*$G$7,0) -> 0 | O11: =SUM(J11:N11) -> 1579.2208 | P11: =IF(O11<=730,460,IF(O11<1670,460-0.26*(O11-730),MAX(0,400-0.18*(O11-642)))) -> 239.2026 | Q11: =(O11-P11)*20% -> 268.00364 | R11: =$G$3*(O11-N11) -> 225.67065 | S11: =J11*$G$4 -> 79.771429 | T11: =$G$6*O11 -> 47.376623 | U11: =SUM(Q11:T11) -> 620.82234 | V11: =O11-U11 -> 958.39844 | W11: =$G$5*O11 -> 27.952208 | X11: =VLOOKUP(D11,Darbuotojai!B7:F21,5,0) -> 200 | Y11: ='Darbo užmokestis'!V11-'Darbo užmokestis'!X11 -> 758.39844
A12: darbo užmokestis | B12: 3 | C12: =EOMONTH(DATE(2026,3,1),0) -> 46112 | D12: =Darbuotojai!B8 -> Darbuotojas3 | E12: =Darbuotojai!D8 -> 1600 | F12: =VLOOKUP(D12,Darbuotojai!B8:E22,4,FALSE) -> 9.0909091 | G12: =NETWORKDAYS(DATE(2026,3,1),DATE(2026,3,31),DATE(2026,3,11)) -> 21 | H12: =RANDBETWEEN(15,G12) -> 19 | I12: =H12*8 -> 152 | J12: =E12*H12/G12 -> 1447.619 | K12: =IF(H12=21,50,0) -> 0 | L12: =IF(G12-H12>4,(G12-H12)*8*F12,0) -> 0 | M12: =Užduotis!$C$31 -> 0 | N12: =IF(G12-H12<=4,(G12-H12)*8*F12*$G$7,0) -> 94.545455 | O12: =SUM(J12:N12) -> 1542.1645 | P12: =IF(O12<=730,460,IF(O12<1670,460-0.26*(O12-730),MAX(0,400-0.18*(O12-642)))) -> 248.83723 | Q12: =(O12-P12)*20% -> 258.66545 | R12: =$G$3*(O12-N12) -> 206.86476 | S12: =J12*$G$4 -> 101.04381 | T12: =$G$6*O12 -> 46.264935 | U12: =SUM(Q12:T12) -> 612.83896 | V12: =O12-U12 -> 929.32554 | W12: =$G$5*O12 -> 27.296312 | X12: =VLOOKUP(D12,Darbuotojai!B8:F22,5,0) -> 200 | Y12: ='Darbo užmokestis'!V12-'Darbo užmokestis'!X12 -> 729.32554
A13: darbo užmokestis | B13: 3 | C13: =EOMONTH(DATE(2026,3,1),0) -> 46112 | D13: =Darbuotojai!B9 -> Darbuotojas4 | E13: =Darbuotojai!D9 -> 1505 | F13: =VLOOKUP(D13,Darbuotojai!B9:E23,4,FALSE) -> 8.5511364 | G13: =NETWORKDAYS(DATE(2026,3,1),DATE(2026,3,31),DATE(2026,3,11)) -> 21 | H13: =RANDBETWEEN(15,G13) -> 16 | I13: =H13*8 -> 128 | J13: =E13*H13/G13 -> 1146.6667 | K13: =IF(H13=21,50,0) -> 0 | L13: =IF(G13-H13>4,(G13-H13)*8*F13,0) -> 342.04545 | M13: =Užduotis!$C$31 -> 0 | N13: =IF(G13-H13<=4,(G13-H13)*8*F13*$G$7,0) -> 0 | O13: =SUM(J13:N13) -> 1488.7121 | P13: =IF(O13<=730,460,IF(O13<1670,460-0.26*(O13-730),MAX(0,400-0.18*(O13-642)))) -> 262.73485 | Q13: =(O13-P13)*20% -> 245.19545 | R13: =$G$3*(O13-N13) -> 212.73696 | S13: =J13*$G$4 -> 80.037333 | T13: =$G$6*O13 -> 44.661364 | U13: =SUM(Q13:T13) -> 582.63111 | V13: =O13-U13 -> 906.08101 | W13: =$G$5*O13 -> 26.350205 | X13: =VLOOKUP(D13,Darbuotojai!B9:F23,5,0) -> 200 | Y13: ='Darbo užmokestis'!V13-'Darbo užmokestis'!X13 -> 706.08101
A14: darbo užmokestis | B14: 3 | C14: =EOMONTH(DATE(2026,3,1),0) -> 46112 | D14: =Darbuotojai!B10 -> Darbuotojas5 | E14: =Darbuotojai!D10 -> 1199 | F14: =VLOOKUP(D14,Darbuotojai!B10:E24,4,FALSE) -> 6.8125 | G14: =NETWORKDAYS(DATE(2026,3,1),DATE(2026,3,31),DATE(2026,3,11)) -> 21 | H14: =RANDBETWEEN(15,G14) -> 20 | I14: =H14*8 -> 160 | J14: =E14*H14/G14 -> 1141.9048 | K14: =IF(H14=21,50,0) -> 0 | L14: =IF(G14-H14>4,(G14-H14)*8*F14,0) -> 0 | M14: =Užduotis!$C$31 -> 0 | N14: =IF(G14-H14<=4,(G14-H14)*8*F14*$G$7,0) -> 35.425 | O14: =SUM(J14:N14) -> 1177.3298 | P14: =IF(O14<=730,460,IF(O14<1670,460-0.26*(O14-730),MAX(0,400-0.18*(O14-642)))) -> 343.69426 | Q14: =(O14-P14)*20% -> 166.7271 | R14: =$G$3*(O14-N14) -> 163.17819 | S14: =J14*$G$4 -> 79.704952 | T14: =$G$6*O14 -> 35.319893 | U14: =SUM(Q14:T14) -> 444.93014 | V14: =O14-U14 -> 732.39963 | W14: =$G$5*O14 -> 20.838737 | X14: =VLOOKUP(D14,Darbuotojai!B10:F24,5,0) -> 200 | Y14: ='Darbo užmokestis'!V14-'Darbo užmokestis'!X14 -> 532.39963
A15: darbo užmokestis | B15: 3 | C15: =EOMONTH(DATE(2026,3,1),0) -> 46112 | D15: =Darbuotojai!B11 -> Darbuotojas6 | E15: =Darbuotojai!D11 -> 1199 | F15: =VLOOKUP(D15,Darbuotojai!B11:E25,4,FALSE) -> 6.8125 | G15: =NETWORKDAYS(DATE(2026,3,1),DATE(2026,3,31),DATE(2026,3,11)) -> 21 | H15: =RANDBETWEEN(15,G15) -> 17 | I15: =H15*8 -> 136 | J15: =E15*H15/G15 -> 970.61905 | K15: =IF(H15=21,50,0) -> 0 | L15: =IF(G15-H15>4,(G15-H15)*8*F15,0) -> 0 | M15: =Užduotis!$C$31 -> 0 | N15: =IF(G15-H15<=4,(G15-H15)*8*F15*$G$7,0) -> 141.7 | O15: =SUM(J15:N15) -> 1112.319 | P15: =IF(O15<=730,460,IF(O15<1670,460-0.26*(O15-730),MAX(0,400-0.18*(O15-642)))) -> 360.59705 | Q15: =(O15-P15)*20% -> 150.3444 | R15: =$G$3*(O15-N15) -> 138.70146 | S15: =J15*$G$4 -> 67.74921 | T15: =$G$6*O15 -> 33.369571 | U15: =SUM(Q15:T15) -> 390.16464 | V15: =O15-U15 -> 722.1544 | W15: =$G$5*O15 -> 19.688047 | X15: =VLOOKUP(D15,Darbuotojai!B11:F25,5,0) -> 150 | Y15: ='Darbo užmokestis'!V15-'Darbo užmokestis'!X15 -> 572.1544
A16: darbo užmokestis | B16: 3 | C16: =EOMONTH(DATE(2026,3,1),0) -> 46112 | D16: =Darbuotojai!B12 -> Darbuotojas7 | E16: =Darbuotojai!D12 -> 1090 | F16: =VLOOKUP(D16,Darbuotojai!B12:E26,4,FALSE) -> 6.1931818 | G16: =NETWORKDAYS(DATE(2026,3,1),DATE(2026,3,31),DATE(2026,3,11)) -> 21 | H16: =RANDBETWEEN(15,G16) -> 20 | I16: =H16*8 -> 160 | J16: =E16*H16/G16 -> 1038.0952 | K16: =IF(H16=21,50,0) -> 0 | L16: =IF(G16-H16>4,(G16-H16)*8*F16,0) -> 0 | M16: =Užduotis!$C$31 -> 0 | N16: =IF(G16-H16<=4,(G16-H16)*8*F16*$G$7,0) -> 32.204545 | O16: =SUM(J16:N16) -> 1070.2998 | P16: =IF(O16<=730,460,IF(O16<1670,460-0.26*(O16-730),MAX(0,400-0.18*(O16-642)))) -> 371.52206 | Q16: =(O16-P16)*20% -> 139.75555 | R16: =$G$3*(O16-N16) -> 148.34381 | S16: =J16*$G$4 -> 72.459048 | T16: =$G$6*O16 -> 32.108994 | U16: =SUM(Q16:T16) -> 392.6674 | V16: =O16-U16 -> 677.63239 | W16: =$G$5*O16 -> 18.944306 | X16: =VLOOKUP(D16,Darbuotojai!B12:F26,5,0) -> 150 | Y16: ='Darbo užmokestis'!V16-'Darbo užmokestis'!X16 -> 527.63239
A17: darbo užmokestis | B17: 3 | C17: =EOMONTH(DATE(2026,3,1),0) -> 46112 | D17: =Darbuotojai!B13 -> Darbuotojas8 | E17: =Darbuotojai!D13 -> 1090 | F17: =VLOOKUP(D17,Darbuotojai!B13:E27,4,FALSE) -> 6.1931818 | G17: =NETWORKDAYS(DATE(2026,3,1),DATE(2026,3,31),DATE(2026,3,11)) -> 21 | H17: =RANDBETWEEN(15,G17) -> 19 | I17: =H17*8 -> 152 | J17: =E17*H17/G17 -> 986.19048 | K17: =IF(H17=21,50,0) -> 0 | L17: =IF(G17-H17>4,(G17-H17)*8*F17,0) -> 0 | M17: =Užduotis!$C$31 -> 0 | N17: =IF(G17-H17<=4,(G17-H17)*8*F17*$G$7,0) -> 64.409091 | O17: =SUM(J17:N17) -> 1050.5996 | P17: =IF(O17<=730,460,IF(O17<1670,460-0.26*(O17-730),MAX(0,400-0.18*(O17-642)))) -> 376.64411 | Q17: =(O17-P17)*20% -> 134.79109 | R17: =$G$3*(O17-N17) -> 140.92662 | S17: =J17*$G$4 -> 68.836095 | T17: =$G$6*O17 -> 31.517987 | U17: =SUM(Q17:T17) -> 376.07179 | V17: =O17-U17 -> 674.52777 | W17: =$G$5*O17 -> 18.595612 | X17: =VLOOKUP(D17,Darbuotojai!B13:F27,5,0) -> 200 | Y17: ='Darbo užmokestis'!V17-'Darbo užmokestis'!X17 -> 474.52777
A18: darbo užmokestis | B18: 3 | C18: =EOMONTH(DATE(2026,3,1),0) -> 46112 | D18: =Darbuotojai!B14 -> Darbuotojas9 | E18: =Darbuotojai!D14 -> 980 | F18: =VLOOKUP(D18,Darbuotojai!B14:E28,4,FALSE) -> 5.5681818 | G18: =NETWORKDAYS(DATE(2026,3,1),DATE(2026,3,31),DATE(2026,3,11)) -> 21 | H18: =RANDBETWEEN(15,G18) -> 15 | I18: =H18*8 -> 120 | J18: =E18*H18/G18 -> 700 | K18: =IF(H18=21,50,0) -> 0 | L18: =IF(G18-H18>4,(G18-H18)*8*F18,0) -> 267.27273 | M18: =Užduotis!$C$31 -> 0 | N18: =IF(G18-H18<=4,(G18-H18)*8*F18*$G$7,0) -> 0 | O18: =SUM(J18:N18) -> 967.27273 | P18: =IF(O18<=730,460,IF(O18<1670,460-0.26*(O18-730),MAX(0,400-0.18*(O18-642)))) -> 398.30909 | Q18: =(O18-P18)*20% -> 113.79273 | R18: =$G$3*(O18-N18) -> 138.22327 | S18: =J18*$G$4 -> 48.86 | T18: =$G$6*O18 -> 29.018182 | U18: =SUM(Q18:T18) -> 329.89418 | V18: =O18-U18 -> 637.37855 | W18: =$G$5*O18 -> 17.120727 | X18: =VLOOKUP(D18,Darbuotojai!B14:F28,5,0) -> 150 | Y18: ='Darbo užmokestis'!V18-'Darbo užmokestis'!X18 -> 487.37855
A19: darbo užmokestis | B19: 3 | C19: =EOMONTH(DATE(2026,3,1),0) -> 46112 | D19: =Darbuotojai!B15 -> Darbuotojas10 | E19: =Darbuotojai!D15 -> 980 | F19: =VLOOKUP(D19,Darbuotojai!B15:E29,4,FALSE) -> 5.5681818 | G19: =NETWORKDAYS(DATE(2026,3,1),DATE(2026,3,31),DATE(2026,3,11)) -> 21 | H19: =RANDBETWEEN(15,G19) -> 17 | I19: =H19*8 -> 136 | J19: =E19*H19/G19 -> 793.33333 | K19: =IF(H19=21,50,0) -> 0 | L19: =IF(G19-H19>4,(G19-H19)*8*F19,0) -> 0 | M19: =Užduotis!$C$31 -> 0 | N19: =IF(G19-H19<=4,(G19-H19)*8*F19*$G$7,0) -> 115.81818 | O19: =SUM(J19:N19) -> 909.15152 | P19: =IF(O19<=730,460,IF(O19<1670,460-0.26*(O19-730),MAX(0,400-0.18*(O19-642)))) -> 413.42061 | Q19: =(O19-P19)*20% -> 99.146182 | R19: =$G$3*(O19-N19) -> 113.36733 | S19: =J19*$G$4 -> 55.374667 | T19: =$G$6*O19 -> 27.274545 | U19: =SUM(Q19:T19) -> 295.16273 | V19: =O19-U19 -> 613.98879 | W19: =$G$5*O19 -> 16.091982 | X19: =VLOOKUP(D19,Darbuotojai!B15:F29,5,0) -> 200 | Y19: ='Darbo užmokestis'!V19-'Darbo užmokestis'!X19 -> 413.98879
A20: darbo užmokestis | B20: 3 | C20: =EOMONTH(DATE(2026,3,1),0) -> 46112 | D20: =Darbuotojai!B16 -> Darbuotojas11 | E20: =Darbuotojai!D16 -> 980 | F20: =VLOOKUP(D20,Darbuotojai!B16:E30,4,FALSE) -> 5.5681818 | G20: =NETWORKDAYS(DATE(2026,3,1),DATE(2026,3,31),DATE(2026,3,11)) -> 21 | H20: =RANDBETWEEN(15,G20) -> 16 | I20: =H20*8 -> 128 | J20: =E20*H20/G20 -> 746.66667 | K20: =IF(H20=21,50,0) -> 0 | L20: =IF(G20-H20>4,(G20-H20)*8*F20,0) -> 222.72727 | M20: =Užduotis!$C$31 -> 0 | N20: =IF(G20-H20<=4,(G20-H20)*8*F20*$G$7,0) -> 0 | O20: =SUM(J20:N20) -> 969.39394 | P20: =IF(O20<=730,460,IF(O20<1670,460-0.26*(O20-730),MAX(0,400-0.18*(O20-642)))) -> 397.75758 | Q20: =(O20-P20)*20% -> 114.32727 | R20: =$G$3*(O20-N20) -> 138.52639 | S20: =J20*$G$4 -> 52.117333 | T20: =$G$6*O20 -> 29.081818 | U20: =SUM(Q20:T20) -> 334.05282 | V20: =O20-U20 -> 635.34112 | W20: =$G$5*O20 -> 17.158273 | X20: =VLOOKUP(D20,Darbuotojai!B16:F30,5,0) -> 150 | Y20: ='Darbo užmokestis'!V20-'Darbo užmokestis'!X20 -> 485.34112
A21: darbo užmokestis | B21: 3 | C21: =EOMONTH(DATE(2026,3,1),0) -> 46112 | D21: =Darbuotojai!B17 -> Darbuotojas12 | E21: =Darbuotojai!D17 -> 980 | F21: =VLOOKUP(D21,Darbuotojai!B17:E31,4,FALSE) -> 5.5681818 | G21: =NETWORKDAYS(DATE(2026,3,1),DATE(2026,3,31),DATE(2026,3,11)) -> 21 | H21: =RANDBETWEEN(15,G21) -> 19 | I21: =H21*8 -> 152 | J21: =E21*H21/G21 -> 886.66667 | K21: =IF(H21=21,50,0) -> 0 | L21: =IF(G21-H21>4,(G21-H21)*8*F21,0) -> 0 | M21: =Užduotis!$C$31 -> 0 | N21: =IF(G21-H21<=4,(G21-H21)*8*F21*$G$7,0) -> 57.909091 | O21: =SUM(J21:N21) -> 944.57576 | P21: =IF(O21<=730,460,IF(O21<1670,460-0.26*(O21-730),MAX(0,400-0.18*(O21-642)))) -> 404.2103 | Q21: =(O21-P21)*20% -> 108.07309 | R21: =$G$3*(O21-N21) -> 126.70467 | S21: =J21*$G$4 -> 61.889333 | T21: =$G$6*O21 -> 28.337273 | U21: =SUM(Q21:T21) -> 325.00436 | V21: =O21-U21 -> 619.57139 | W21: =$G$5*O21 -> 16.718991 | X21: =VLOOKUP(D21,Darbuotojai!B17:F31,5,0) -> 200 | Y21: ='Darbo užmokestis'!V21-'Darbo užmokestis'!X21 -> 419.57139
... A24: darbo užmokestis | B24: 3 | C24: =EOMONTH(DATE(2026,3,1),0) -> 46112 | D24: =Darbuotojai!B20 -> Darbuotojas15 | E24: =Darbuotojai!D20 -> 980 | F24: =VLOOKUP(D24,Darbuotojai!B20:E34,4,FALSE) -> 5.5681818 | G24: =NETWORKDAYS(DATE(2026,3,1),DATE(2026,3,31),DATE(2026,3,11)) -> 21 | H24: =RANDBETWEEN(15,G24) -> 16 | I24: =H24*8 -> 128 | J24: =E24*H24/G24 -> 746.66667 | K24: =IF(H24=21,50,0) -> 0 | L24: =IF(G24-H24>4,(G24-H24)*8*F24,0) -> 222.72727 | M24: =Užduotis!$C$31 -> 0 | N24: =IF(G24-H24<=4,(G24-H24)*8*F24*$G$7,0) -> 0 | O24: =SUM(J24:N24) -> 969.39394 | P24: =IF(O24<=730,460,IF(O24<1670,460-0.26*(O24-730),MAX(0,400-0.18*(O24-642)))) -> 397.75758 | Q24: =(O24-P24)*20% -> 114.32727 | R24: =$G$3*(O24-N24) -> 138.52639 | S24: =J24*$G$4 -> 52.117333 | T24: =$G$6*O24 -> 29.081818 | U24: =SUM(Q24:T24) -> 334.05282 | V24: =O24-U24 -> 635.34112 | W24: =$G$5*O24 -> 17.158273 | X24: =VLOOKUP(D24,Darbuotojai!B20:F34,5,0) -> 200 | Y24: ='Darbo užmokestis'!V24-'Darbo užmokestis'!X24 -> 435.34112

Sheet suvestinė
A3: 1 | B3: Keli darbuotojai dirbo 18 ir daugiau dienų | C3: =COUNTIF('Darbo užmokestis'!H10:H24,">=18") -> 8
A4: 2 | B4: Darbuotojų, kurie dirbo mažiau nei 18 dienų, išmokamų atlyginimų suma
A5: 3 | B5: Vidutinė avanso suma | C5: =AVERAGE('Darbo užmokestis'!X10:X24) -> 183.33333
A6: 4 | B6: Darbuotojų, kurių valandinis įkainis mažiau nei 8 eurai, sumokamų VSD vidurkis
A7: 5 | B7: Pritaikyto NPD mediana | C7: =MEDIAN('Darbo užmokestis'!P10:P24) -> 376.64411
A8: 6 | B8: 2 didžiausia GPM reikšmė
