Workbook

Sheet Užduotis
A1: Savarankiško darbo užduotis:
A3: Darbalapis "Darbuotojai"
B4: Stulpelio pavadinimas | C4: Užduotis | D4: Pastabos
A5: 1 | B5: Eil. Nr. | C5: Sukurkite seką
A6: 2 | B6: Pavardė, vardas | C6: Sukurkite seką "Darbuotojas1" ir t.t.
A7: 3 | B7: Pareigos | C7: Sudarykite sąrašą ir parinkite vieną iš pateiktų pareigybių kiekvienam darbuotojui. Pareigybių skaičius duotas "Pareigybės" lape | D7: sąrašas
A8: 4 | B8: Pareiginis atlyginimas, € | C8: Parinkite kiekvienam darbuotojui pareiginį atlyginimą pagal pareigas | D8: vlookup()
A9: 5 | B9: Valandinis tarifinis atlygis, € | C9: Apskaičiuokite iš pareiginio atlyginimo imdami vidutinį mėnesio darbo dienų skaičių 22
A10: 6 | B10: Avansas, € | C10: Avansą parinkite atsitiktiniu būdu 150 arba 200 eurų | D10: choose()
A11: 7 | B11: Asmens kodas | C11: nepildyti
A12: 8 | B12: Tel. Nr. | C12: sujunkite "+370 6" ir 7 atsitiktiniai skaičiai | D12: concatenate()
A13: 9 | B13: Adresas | C13: sugalvokite patys
A16: Darbalapis "Darbo užmokestis"
B17: Stulpelio pavadinimas | C17: Užduotis
A18: 1 | B18: A5 | C18: Įrašykite kovo mėnesį
A19: 2 | B19: Registras | C19: Darbo užmokestis
A20: 3 | B20: Op. Nr. | C20: tarkime, kad darote registrą kovo mėnesiui, tada rašykite visur 03
A21: 4 | B21: Skaičiavimo data | C21: Pasirinkite šių metų kovo datą formatas: 2022/kov/31 | D21: eomonth()
A22: 5 | B22: Pavardė, vardas | C22: nukopijuokite darbuotojus iš darbuotojų lapo
A23: 6 | B23: Pareiginis atlyginimas, € | C23: Parinkite kiekvienam darbuotojui pareiginį atlyginimą iš darbuotojų lapo | D23: vlookup()
A24: 7 | B24: Valandinis tarifinis atlygis, € | C24: Parinkite kiekvienam darbuotojui pareiginį valandinį atlyginimą iš darbuotojų lapo | D24: vlookup()
A25: 8 | B25: Nustatytas darbo dienų skaičius | C25: apskaičiuokite darbo dienų skaičių su funkcija Networkdays(). Nepamirškite švenčių dienų.
A26: 9 | B26: Faktiškai dirbta, d. | C26: parinkite atsitiktiniu būdu nuo 15 iki mėnesio darbo dienų skaičiaus | D26: randbetween()
A27: 10 | B27: Faktiškai dirbta, val. | C27: dienos * 8 val.
A28: 11 | B28: Atlyginimas, € | C28: f | D28: atlyginimas*fakt.dirbtų d./d.d.skaičius
A29: 12 | B29: Mėnesinė priemoka, € | C29: Skirkite mėnesinę priemoką 50 eurų, jei dirbo visas darbo dienas | D29: IF
A30: 13 | B30: Eilinės atostogos, € | C30: Jei darbuotojas nedirbo daugiau nei 4 dienas, tada jis tas dienas buvo atostogose. Paskaičiuokite už tas dienas atostoginius | D30: IF
A31: 14 | B31: Kompensacija už nepanaudotas atostogas, € | C31: 0
A32: 15 | B32: Nedarbingumo pašalpa darbdavio lėšomis, € | C32: Jei darbuotojas nedirbo 4 ar mažiau dienų, tada jis sirgo. Paskaičiuokite už tas 1-2 dienas darbdavio mokamą atlyginimą | D32: IF
A33: 16 | B33: Priskaičiuota iš viso, € | C33: Visos priskaičiuotos sumos
A34: 17 | B34: pritaikytas NPD, € | C34: paskaičiuokite pagal dešinėje duotas formules | H34: Neapmokestinamo minimumo skaičiavimas:
A35: 18 | B35: GPM, € | C35: GMP=(Priskaičiuota - NPD)*20% | D35: koeficientams suteikite vardus | G35: 1) | H35: NPD max - 460 Eur. Taikomas pajamoms iki 730 Eur.
A36: 19 | B36: VSD ir PSD įmokos, € | C36: 14,29% nuo priskaičiuoto atlygio atėmus nedarbingumo pašalpos sumą, PSD - 6,98% | G36: 2) | H36: NPD = 460 – 0,26* (gyventojo mėnesio su darbo santykiais arba jų esmę atitinkančiais santykiais susijusios pajamos – 730) | R36: jei Du<1678
A37: 20 | B37: Papildomas pensijinis kaupimas | C37: 3% nuo priskaičiuoto atlygio | G37: 3) | H37: NPD = 400 – 0,18* (gyventojo mėnesio su darbo santykiais arba jų esmę atitinkančiais santykiais susijusios pajamos – 642) | R37: jei Du>1678
A38: 21 | B38: Išskaičiuota iš viso, € | C38: visa išskaičiuota suma mokesčiams | G38: 4) | H38: Jei neigiamas tai rašome 0
A39: 22 | B39: Išmokėtina suma, € | C39: Išmokama = priskaičiuota - išskaičiuota
A40: 23 | B40: Darbdavio VSD įmokos, € | C40: VSD (1,77%) * priskaičiuota
A41: 24 | B41: Avansas, € | C41: Parinkite iš darbuotojų lapo | D41: vlookup()
A42: 25 | B42: Išmokėtina suma po avanso, € | C42: Išmokama suma atėmus avansą
A43: 26 | B43: Garantinis fondas | C43: 0,2% nuo visiems darbuotojams priskaičiuotų atlyginimų
...

Sheet Pareigybės
A3: Eil. Nr. | B3: Pareigybė | C3: Pareiginis atlyginimas, € | D3: Darbuotojų skaičius
A4: 1 | B4: Vadovas | C4: 2800 | D4: 1
A5: 2 | B5: Buhalterė | C5: 1600 | D5: 2
A6: 3 | B6: Administratorė | C6: 1505 | D6: 1
A7: 4 | B7: Vadybininkas | C7: 1199 | D7: 2
A8: 5 | B8: Sandėlininkas | C8: 1090 | D8: 2
A9: 6 | B9: Gamybos darbuotojas | C9: 980 | D9: 7

Sheet Darbuotojai
A1: Darbuotojai
A5: Eil. Nr. | B5: Pavardė, vardas | C5: Pareigos | D5: Pareiginis atlyginimas, € | E5: Valandinis tarifinis atlygis, € | F5: Avansas, € | G5: Asmens kodas | H5: Tel. Nr. | I5: Adresas
A6: 1 | B6: Darbuotojas 1 | C6: =Pareigybės!B7 -> Vadybininkas | D6: =VLOOKUP(C6,Pareigybės!$B$4:$C$9,2,FALSE) -> 1199 | E6: =D6/22/8 -> 6.8125 | F6: =CHOOSE(RANDBETWEEN(1,2),150,200) -> 150 | G6: x | H6: =CONCATENATE("+",3706,RANDBETWEEN(1000000,9999999)) -> +37067293265 | I6: Jaunystės 1
A7: 2 | B7: Darbuotojas 2 | C7: =Pareigybės!B8 -> Sandėlininkas | D7: =VLOOKUP(C7,Pareigybės!$B$4:$C$9,2,FALSE) -> 1090 | E7: =D7/22/8 -> 6.1931818 | F7: =CHOOSE(RANDBETWEEN(1,2),150,200) -> 200 | G7: x | H7: =CONCATENATE("+",3706,RANDBETWEEN(1000000,9999999)) -> +37068721163 | I7: Jaunystės 2
A8: 3 | B8: Darbuotojas 3 | C8: =Pareigybės!$B$9 -> Gamybos darbuotojas | D8: =VLOOKUP(C8,Pareigybės!$B$4:$C$9,2,FALSE) -> 980 | E8: =D8/22/8 -> 5.5681818 | F8: =CHOOSE(RANDBETWEEN(1,2),150,200) -> 200 | G8: x | H8: =CONCATENATE("+",3706,RANDBETWEEN(1000000,9999999)) -> +37067453909 | I8: Jaunystės 3
A9: 4 | B9: Darbuotojas 4 | C9: =Pareigybės!$B$9 -> Gamybos darbuotojas | D9: =VLOOKUP(C9,Pareigybės!$B$4:$C$9,2,FALSE) -> 980 | E9: =D9/22/8 -> 5.5681818 | F9: =CHOOSE(RANDBETWEEN(1,2),150,200) -> 150 | G9: x | H9: =CONCATENATE("+",3706,RANDBETWEEN(1000000,9999999)) -> +37062628548 | I9: Jaunystės 4
A10: 5 | B10: Darbuotojas 5 | C10: =Pareigybės!$B$9 -> Gamybos darbuotojas | D10: =VLOOKUP(C10,Pareigybės!$B$4:$C$9,2,FALSE) -> 980 | E10: =D10/22/8 -> 5.5681818 | F10: =CHOOSE(RANDBETWEEN(1,2),150,200) -> 200 | G10: x | H10: =CONCATENATE("+",3706,RANDBETWEEN(1000000,9999999)) -> +37063970405 | I10: Jaunystės 5
A11: 6 | B11: Darbuotojas 6 | C11: =Pareigybės!B8 -> Sandėlininkas | D11: =VLOOKUP(C11,Pareigybės!$B$4:$C$9,2,FALSE) -> 1090 | E11: =D11/22/8 -> 6.1931818 | F11: =CHOOSE(RANDBETWEEN(1,2),150,200) -> 200 | G11: x | H11: =CONCATENATE("+",3706,RANDBETWEEN(1000000,9999999)) -> +37065458993 | I11: Jaunystės 6
A12: 7 | B12: Darbuotojas 7 | C12: =Pareigybės!B5 -> Buhalterė | D12: =VLOOKUP(C12,Pareigybės!$B$4:$C$9,2,FALSE) -> 1600 | E12: =D12/22/8 -> 9.0909091 | F12: =CHOOSE(RANDBETWEEN(1,2),150,200) -> 200 | G12: x | H12: =CONCATENATE("+",3706,RANDBETWEEN(1000000,9999999)) -> +37061623420 | I12: Jaunystės 7
A13: 8 | B13: Darbuotojas 8 | C13: =Pareigybės!B7 -> Vadybininkas | D13: =VLOOKUP(C13,Pareigybės!$B$4:$C$9,2,FALSE) -> 1199 | E13: =D13/22/8 -> 6.8125 | F13: =CHOOSE(RANDBETWEEN(1,2),150,200) -> 200 | G13: x | H13: =CONCATENATE("+",3706,RANDBETWEEN(1000000,9999999)) -> +37061390467 | I13: Jaunystės 8
A14: 9 | B14: Darbuotojas 9 | C14: =Pareigybės!B5 -> Buhalterė | D14: =VLOOKUP(C14,Pareigybės!$B$4:$C$9,2,FALSE) -> 1600 | E14: =D14/22/8 -> 9.0909091 | F14: =CHOOSE(RANDBETWEEN(1,2),150,200) -> 200 | G14: x | H14: =CONCATENATE("+",3706,RANDBETWEEN(1000000,9999999)) -> +37067047463 | I14: Jaunystės 9
A15: 10 | B15: Darbuotojas 10 | C15: =Pareigybės!$B$9 -> Gamybos darbuotojas | D15: =VLOOKUP(C15,Pareigybės!$B$4:$C$9,2,FALSE) -> 980 | E15: =D15/22/8 -> 5.5681818 | F15: =CHOOSE(RANDBETWEEN(1,2),150,200) -> 200 | G15: x | H15: =CONCATENATE("+",3706,RANDBETWEEN(1000000,9999999)) -> +37067879476 | I15: Jaunystės 10
A16: 11 | B16: Darbuotojas 11 | C16: =Pareigybės!$B$9 -> Gamybos darbuotojas | D16: =VLOOKUP(C16,Pareigybės!$B$4:$C$9,2,FALSE) -> 980 | E16: =D16/22/8 -> 5.5681818 | F16: =CHOOSE(RANDBETWEEN(1,2),150,200) -> 150 | G16: x | H16: =CONCATENATE("+",3706,RANDBETWEEN(1000000,9999999)) -> +37068366163 | I16: Jaunystės 11
A17: 12 | B17: Darbuotojas 12 | C17: =Pareigybės!$B$9 -> Gamybos darbuotojas | D17: =VLOOKUP(C17,Pareigybės!$B$4:$C$9,2,FALSE) -> 980 | E17: =D17/22/8 -> 5.5681818 | F17: =CHOOSE(RANDBETWEEN(1,2),150,200) -> 150 | G17: x | H17: =CONCATENATE("+",3706,RANDBETWEEN(1000000,9999999)) -> +37066686400 | I17: Jaunystės 12
A18: 13 | B18: Darbuotojas 13 | C18: =Pareigybės!$B$9 -> Gamybos darbuotojas | D18: =VLOOKUP(C18,Pareigybės!$B$4:$C$9,2,FALSE) -> 980 | E18: =D18/22/8 -> 5.5681818 | F18: =CHOOSE(RANDBETWEEN(1,2),150,200) -> 200 | G18: x | H18: =CONCATENATE("+",3706,RANDBETWEEN(1000000,9999999)) -> +37066180114 | I18: Jaunystės 13
A19: 14 | B19: Darbuotojas 14 | C19: =Pareigybės!B6 -> Administratorė | D19: =VLOOKUP(C19,Pareigybės!$B$4:$C$9,2,FALSE) -> 1505 | E19: =D19/22/8 -> 8.5511364 | F19: =CHOOSE(RANDBETWEEN(1,2),150,200) -> 150 | G19: x | H19: =CONCATENATE("+",3706,RANDBETWEEN(1000000,9999999)) -> +37067299124 | I19: Jaunystės 14
A20: 15 | B20: Darbuotojas 15 | C20: =Pareigybės!B4 -> Vadovas | D20: =VLOOKUP(C20,Pareigybės!$B$4:$C$9,2,FALSE) -> 2800 | E20: =D20/22/8 -> 15.909091 | F20: =CHOOSE(RANDBETWEEN(1,2),150,200) -> 200 | G20: x | H20: =CONCATENATE("+",3706,RANDBETWEEN(1000000,9999999)) -> +37065490178 | I20: Jaunystės 15

Sheet Darbo užmokestis
A1: UAB "Jaunystė" | F1: GPM1 | G1: 0.2 | J1: Garantinis fondas | L1: 0.002 | N1: Ilgalaikio darbo išmokų fondo įmoka | R1: 0.0016 | S1: =J7*R1 -> 25.963962
A2: Įmonės kodas 1222555888 | F2: GPM2 | G2: 0.27 | J2: Įmoka | L2: =O7*$L$1 -> 38.121589 | N2: Soc. draudimo įmokos nelaimingų atsitikimų draudimui | R2: 0.0014 | S2: =J7*R2 -> 22.718467
A3: Darbo užmokesčio registras | F3: VSD darbuotojo | G3: 0.1429
F4: PSD | G4: 0.0698
A5: kovas | F5: VSD darbdavio | G5: 0.0177
F6: Papildomas pensijinis kaupimas | G6: 0.03
A7: mėnuo | F7: Nedarbingumo pašalpa | G7: 0.65 | I7: Iš viso: | J7: =SUM(J10:J24) -> 16227.476 | K7: =SUM(K10:K24) -> 150 | L7: =SUM(L10:L24) -> 1802.9545 | M7: =SUM(M10:M24) -> 0 | N7: =SUM(N10:N24) -> 880.36364 | O7: =SUM(O10:O24) -> 19060.794 | P7: =SUM(P10:P24) -> 2553.2004 | Q7: =SUM(Q10:Q24) -> 3301.5188 | ... Y7: =SUM(Y10:Y24) -> 12027.648
A9: Registras | B9: Op. Nr. | C9: Skaičiavimo data | D9: Pavardė, vardas | E9: Pareiginis atlyginimas, € | F9: Valandinis tarifinis atlygis, € | G9: Nustatytas darbo dienų skaičius | H9: Faktiškai dirbta, d. | I9: Faktiškai dirbta, val. | J9: Atlyginimas, € | K9: Mėnesinė priemoka, € | L9: Eilinės atostogos, € | M9: Kompensacija už nepanaudotas atostogas, € | N9: Nedarbingumo pašalpa darbdavio lėšomis, € | O9: Priskaičiuota iš viso, € | P9: pritaikytas NPD, € | Q9: GPM, € | R9: VSD įmoka, € | S9: PSD įmoka, € | T9: Papildomas pensijinis kaupimas | U9: Išskaičiuota iš viso, € | V9: Išmokėtina suma, € | W9: Darbdavio VSD įmokos, € | X9: Avansas, € | Y9: Išmokėtina suma po avanso, €
A10: darbo užmokestis | B10: ="03" -> 03 | C10: =EOMONTH(DATE(2026,3,1),0) -> 46112 | D10: =Darbuotojai!B20 -> Darbuotojas 15 | E10: =VLOOKUP(D10,Darbuotojai!$B$6:$D$20,3,FALSE) -> 2800 | F10: =VLOOKUP(D10,Darbuotojai!$B$6:$E$20,4,FALSE) -> 15.909091 | G10: =NETWORKDAYS(DATE(2026,3,1),DATE(2026,3,31),DATE(2026,3,11)) -> 21 | H10: =RANDBETWEEN(15,G10) -> 20 | I10: =H10*8 -> 160 | J10: =E10*'Darbo užmokestis'!H24/'Darbo užmokestis'!G24 -> 2800 | K10: =IF(G10=H10,50,0) -> 0 | L10: =IF(G10-H10>4,8*F10*(G10-H10),0) -> 0 | M10: 0 | N10: =IF(G10-H10<=4,F10*8*RANDBETWEEN(1,2),0) -> 254.54545 | O10: =J10+K10+L10+M10+N10 -> 3054.5455 | P10: =IF(IF(O10<=730,460,IF(O10<1678,460-0.26*O10,IF(O10>1678,460-0.18*O10)))>0,IF(O10<=730,460,IF(O10<1678,460-0.26*O10,IF(O10>1678,460-0.18*O10))),0) -> 0 | Q10: =(O10-P10)*20% -> 610.90909 | R10: =(O10-N10)*14.29% -> 400.12 | S10: =O10*6.98% -> 213.20727 | T10: =J10*3% -> 84 | U10: =SUM(P10:S10) -> 1224.2364 | V10: =O10-U10 -> 1830.3091 | W10: =O10*1.77% -> 54.065455 | X10: =VLOOKUP(D10,Darbuotojai!B20:F34,5,FALSE) -> 200 | Y10: =V10+X10 -> 2030.3091
A11: darbo užmokestis | B11: ="03" -> 03 | C11: =EOMONTH(DATE(2026,3,1),0) -> 46112 | D11: =Darbuotojai!B12 -> Darbuotojas 7 | E11: =VLOOKUP(D11,Darbuotojai!$B$6:$D$20,3,FALSE) -> 1600 | F11: =VLOOKUP(D11,Darbuotojai!$B$6:$E$20,4,FALSE) -> 9.0909091 | G11: =NETWORKDAYS(DATE(2026,3,1),DATE(2026,3,31),DATE(2026,3,11)) -> 21 | H11: =RANDBETWEEN(15,G11) -> 15 | I11: =H11*8 -> 120 | J11: =E11*'Darbo užmokestis'!H16/'Darbo užmokestis'!G16 -> 1295.2381 | K11: =IF(G11=H11,50,0) -> 0 | L11: =IF(G11-H11>4,8*F11*(G11-H11),0) -> 436.36364 | M11: 0 | N11: =IF(G11-H11<=4,F11*8*RANDBETWEEN(1,2),0) -> 0 | O11: =J11+K11+L11+M11+N11 -> 1731.6017 | P11: =IF(IF(O11<=730,460,IF(O11<1678,460-0.26*O11,IF(O11>1678,460-0.18*O11)))>0,IF(O11<=730,460,IF(O11<1678,460-0.26*O11,IF(O11>1678,460-0.18*O11))),0) -> 148.31169 | Q11: =(O11-P11)*20% -> 316.65801 | R11: =(O11-N11)*14.29% -> 247.44589 | S11: =O11*6.98% -> 120.8658 | T11: =J11*3% -> 38.857143 | U11: =SUM(P11:S11) -> 833.28139 | V11: =O11-U11 -> 898.32035 | W11: =O11*1.77% -> 30.649351 | X11: =VLOOKUP(D11,Darbuotojai!B12:F26,5,FALSE) -> 200 | Y11: =V11+X11 -> 1098.3203
A12: darbo užmokestis | B12: ="03" -> 03 | C12: =EOMONTH(DATE(2026,3,1),0) -> 46112 | D12: =Darbuotojai!B14 -> Darbuotojas 9 | E12: =VLOOKUP(D12,Darbuotojai!$B$6:$D$20,3,FALSE) -> 1600 | F12: =VLOOKUP(D12,Darbuotojai!$B$6:$E$20,4,FALSE) -> 9.0909091 | G12: =NETWORKDAYS(DATE(2026,3,1),DATE(2026,3,31),DATE(2026,3,11)) -> 21 | H12: =RANDBETWEEN(15,G12) -> 21 | I12: =H12*8 -> 168 | J12: =E12*'Darbo užmokestis'!H18/'Darbo užmokestis'!G18 -> 1142.8571 | K12: =IF(G12=H12,50,0) -> 50 | L12: =IF(G12-H12>4,8*F12*(G12-H12),0) -> 0 | M12: 0 | N12: =IF(G12-H12<=4,F12*8*RANDBETWEEN(1,2),0) -> 145.45455 | O12: =J12+K12+L12+M12+N12 -> 1338.3117 | P12: =IF(IF(O12<=730,460,IF(O12<1678,460-0.26*O12,IF(O12>1678,460-0.18*O12)))>0,IF(O12<=730,460,IF(O12<1678,460-0.26*O12,IF(O12>1678,460-0.18*O12))),0) -> 112.03896 | Q12: =(O12-P12)*20% -> 245.25455 | R12: =(O12-N12)*14.29% -> 170.45929 | S12: =O12*6.98% -> 93.414156 | T12: =J12*3% -> 34.285714 | U12: =SUM(P12:S12) -> 621.16695 | V12: =O12-U12 -> 717.14474 | W12: =O12*1.77% -> 23.688117 | X12: =VLOOKUP(D12,Darbuotojai!B14:F28,5,FALSE) -> 200 | Y12: =V12+X12 -> 917.14474
A13: darbo užmokestis | B13: ="03" -> 03 | C13: =EOMONTH(DATE(2026,3,1),0) -> 46112 | D13: =Darbuotojai!B19 -> Darbuotojas 14 | E13: =VLOOKUP(D13,Darbuotojai!$B$6:$D$20,3,FALSE) -> 1505 | F13: =VLOOKUP(D13,Darbuotojai!$B$6:$E$20,4,FALSE) -> 8.5511364 | G13: =NETWORKDAYS(DATE(2026,3,1),DATE(2026,3,31),DATE(2026,3,11)) -> 21 | H13: =RANDBETWEEN(15,G13) -> 16 | I13: =H13*8 -> 128 | J13: =E13*'Darbo užmokestis'!H23/'Darbo užmokestis'!G23 -> 1361.6667 | K13: =IF(G13=H13,50,0) -> 0 | L13: =IF(G13-H13>4,8*F13*(G13-H13),0) -> 342.04545 | M13: 0 | N13: =IF(G13-H13<=4,F13*8*RANDBETWEEN(1,2),0) -> 0 | O13: =J13+K13+L13+M13+N13 -> 1703.7121 | P13: =IF(IF(O13<=730,460,IF(O13<1678,460-0.26*O13,IF(O13>1678,460-0.18*O13)))>0,IF(O13<=730,460,IF(O13<1678,460-0.26*O13,IF(O13>1678,460-0.18*O13))),0) -> 153.33182 | Q13: =(O13-P13)*20% -> 310.07606 | R13: =(O13-N13)*14.29% -> 243.46046 | S13: =O13*6.98% -> 118.91911 | T13: =J13*3% -> 40.85 | U13: =SUM(P13:S13) -> 825.78745 | V13: =O13-U13 -> 877.92467 | W13: =O13*1.77% -> 30.155705 | X13: =VLOOKUP(D13,Darbuotojai!B19:F33,5,FALSE) -> 150 | Y13: =V13+X13 -> 1027.9247
A14: darbo užmokestis | B14: ="03" -> 03 | C14: =EOMONTH(DATE(2026,3,1),0) -> 46112 | D14: =Darbuotojai!B6 -> Darbuotojas 1 | E14: =VLOOKUP(D14,Darbuotojai!$B$6:$D$20,3,FALSE) -> 1199 | F14: =VLOOKUP(D14,Darbuotojai!$B$6:$E$20,4,FALSE) -> 6.8125 | G14: =NETWORKDAYS(DATE(2026,3,1),DATE(2026,3,31),DATE(2026,3,11)) -> 21 | H14: =RANDBETWEEN(15,G14) -> 21 | I14: =H14*8 -> 168 | J14: =E14*'Darbo užmokestis'!H10/'Darbo užmokestis'!G10 -> 1141.9048 | K14: =IF(G14=H14,50,0) -> 50 | L14: =IF(G14-H14>4,8*F14*(G14-H14),0) -> 0 | M14: 0 | N14: =IF(G14-H14<=4,F14*8*RANDBETWEEN(1,2),0) -> 54.5 | O14: =J14+K14+L14+M14+N14 -> 1246.4048 | P14: =IF(IF(O14<=730,460,IF(O14<1678,460-0.26*O14,IF(O14>1678,460-0.18*O14)))>0,IF(O14<=730,460,IF(O14<1678,460-0.26*O14,IF(O14>1678,460-0.18*O14))),0) -> 135.93476 | Q14: =(O14-P14)*20% -> 222.094 | R14: =(O14-N14)*14.29% -> 170.32319 | S14: =O14*6.98% -> 86.999052 | T14: =J14*3% -> 34.257143 | U14: =SUM(P14:S14) -> 615.351 | V14: =O14-U14 -> 631.05376 | W14: =O14*1.77% -> 22.061364 | X14: =VLOOKUP(D14,Darbuotojai!B6:F20,5,FALSE) -> 150 | Y14: =V14+X14 -> 781.05376
A15: darbo užmokestis | B15: ="03" -> 03 | C15: =EOMONTH(DATE(2026,3,1),0) -> 46112 | D15: =Darbuotojai!B13 -> Darbuotojas 8 | E15: =VLOOKUP(D15,Darbuotojai!$B$6:$D$20,3,FALSE) -> 1199 | F15: =VLOOKUP(D15,Darbuotojai!$B$6:$E$20,4,FALSE) -> 6.8125 | G15: =NETWORKDAYS(DATE(2026,3,1),DATE(2026,3,31),DATE(2026,3,11)) -> 21 | H15: =RANDBETWEEN(15,G15) -> 19 | I15: =H15*8 -> 152 | J15: =E15*'Darbo užmokestis'!H17/'Darbo užmokestis'!G17 -> 1027.7143 | K15: =IF(G15=H15,50,0) -> 0 | L15: =IF(G15-H15>4,8*F15*(G15-H15),0) -> 0 | M15: 0 | N15: =IF(G15-H15<=4,F15*8*RANDBETWEEN(1,2),0) -> 54.5 | O15: =J15+K15+L15+M15+N15 -> 1082.2143 | P15: =IF(IF(O15<=730,460,IF(O15<1678,460-0.26*O15,IF(O15>1678,460-0.18*O15)))>0,IF(O15<=730,460,IF(O15<1678,460-0.26*O15,IF(O15>1678,460-0.18*O15))),0) -> 178.62429 | Q15: =(O15-P15)*20% -> 180.718 | R15: =(O15-N15)*14.29% -> 146.86037 | S15: =O15*6.98% -> 75.538557 | T15: =J15*3% -> 30.831429 | U15: =SUM(P15:S15) -> 581.74121 | V15: =O15-U15 -> 500.47307 | W15: =O15*1.77% -> 19.155193 | X15: =VLOOKUP(D15,Darbuotojai!B13:F27,5,FALSE) -> 200 | Y15: =V15+X15 -> 700.47307
A16: darbo užmokestis | B16: ="03" -> 03 | C16: =EOMONTH(DATE(2026,3,1),0) -> 46112 | D16: =Darbuotojai!B7 -> Darbuotojas 2 | E16: =VLOOKUP(D16,Darbuotojai!$B$6:$D$20,3,FALSE) -> 1090 | F16: =VLOOKUP(D16,Darbuotojai!$B$6:$E$20,4,FALSE) -> 6.1931818 | G16: =NETWORKDAYS(DATE(2026,3,1),DATE(2026,3,31),DATE(2026,3,11)) -> 21 | H16: =RANDBETWEEN(15,G16) -> 17 | I16: =H16*8 -> 136 | J16: =E16*'Darbo užmokestis'!H11/'Darbo užmokestis'!G11 -> 778.57143 | K16: =IF(G16=H16,50,0) -> 0 | L16: =IF(G16-H16>4,8*F16*(G16-H16),0) -> 0 | M16: 0 | N16: =IF(G16-H16<=4,F16*8*RANDBETWEEN(1,2),0) -> 99.090909 | O16: =J16+K16+L16+M16+N16 -> 877.66234 | P16: =IF(IF(O16<=730,460,IF(O16<1678,460-0.26*O16,IF(O16>1678,460-0.18*O16)))>0,IF(O16<=730,460,IF(O16<1678,460-0.26*O16,IF(O16>1678,460-0.18*O16))),0) -> 231.80779 | Q16: =(O16-P16)*20% -> 129.17091 | R16: =(O16-N16)*14.29% -> 111.25786 | S16: =O16*6.98% -> 61.260831 | T16: =J16*3% -> 23.357143 | U16: =SUM(P16:S16) -> 533.49739 | V16: =O16-U16 -> 344.16495 | W16: =O16*1.77% -> 15.534623 | X16: =VLOOKUP(D16,Darbuotojai!B7:F21,5,FALSE) -> 200 | Y16: =V16+X16 -> 544.16495
A17: darbo užmokestis | B17: ="03" -> 03 | C17: =EOMONTH(DATE(2026,3,1),0) -> 46112 | D17: =Darbuotojai!B11 -> Darbuotojas 6 | E17: =VLOOKUP(D17,Darbuotojai!$B$6:$D$20,3,FALSE) -> 1090 | F17: =VLOOKUP(D17,Darbuotojai!$B$6:$E$20,4,FALSE) -> 6.1931818 | G17: =NETWORKDAYS(DATE(2026,3,1),DATE(2026,3,31),DATE(2026,3,11)) -> 21 | H17: =RANDBETWEEN(15,G17) -> 18 | I17: =H17*8 -> 144 | J17: =E17*'Darbo užmokestis'!H15/'Darbo užmokestis'!G15 -> 986.19048 | K17: =IF(G17=H17,50,0) -> 0 | L17: =IF(G17-H17>4,8*F17*(G17-H17),0) -> 0 | M17: 0 | N17: =IF(G17-H17<=4,F17*8*RANDBETWEEN(1,2),0) -> 49.545455 | O17: =J17+K17+L17+M17+N17 -> 1035.7359 | P17: =IF(IF(O17<=730,460,IF(O17<1678,460-0.26*O17,IF(O17>1678,460-0.18*O17)))>0,IF(O17<=730,460,IF(O17<1678,460-0.26*O17,IF(O17>1678,460-0.18*O17))),0) -> 190.70866 | Q17: =(O17-P17)*20% -> 169.00545 | R17: =(O17-N17)*14.29% -> 140.92662 | S17: =O17*6.98% -> 72.294368 | T17: =J17*3% -> 29.585714 | U17: =SUM(P17:S17) -> 572.9351 | V17: =O17-U17 -> 462.80083 | W17: =O17*1.77% -> 18.332526 | X17: =VLOOKUP(D17,Darbuotojai!B11:F25,5,FALSE) -> 200 | Y17: =V17+X17 -> 662.80083
A18: darbo užmokestis | B18: ="03" -> 03 | C18: =EOMONTH(DATE(2026,3,1),0) -> 46112 | D18: =Darbuotojai!B8 -> Darbuotojas 3 | E18: =VLOOKUP(D18,Darbuotojai!$B$6:$D$20,3,FALSE) -> 980 | F18: =VLOOKUP(D18,Darbuotojai!$B$6:$E$20,4,FALSE) -> 5.5681818 | G18: =NETWORKDAYS(DATE(2026,3,1),DATE(2026,3,31),DATE(2026,3,11)) -> 21 | H18: =RANDBETWEEN(15,G18) -> 15 | I18: =H18*8 -> 120 | J18: =E18*'Darbo užmokestis'!H12/'Darbo užmokestis'!G12 -> 980 | K18: =IF(G18=H18,50,0) -> 0 | L18: =IF(G18-H18>4,8*F18*(G18-H18),0) -> 267.27273 | M18: 0 | N18: =IF(G18-H18<=4,F18*8*RANDBETWEEN(1,2),0) -> 0 | O18: =J18+K18+L18+M18+N18 -> 1247.2727 | P18: =IF(IF(O18<=730,460,IF(O18<1678,460-0.26*O18,IF(O18>1678,460-0.18*O18)))>0,IF(O18<=730,460,IF(O18<1678,460-0.26*O18,IF(O18>1678,460-0.18*O18))),0) -> 135.70909 | Q18: =(O18-P18)*20% -> 222.31273 | R18: =(O18-N18)*14.29% -> 178.23527 | S18: =O18*6.98% -> 87.059636 | T18: =J18*3% -> 29.4 | U18: =SUM(P18:S18) -> 623.31673 | V18: =O18-U18 -> 623.956 | W18: =O18*1.77% -> 22.076727 | X18: =VLOOKUP(D18,Darbuotojai!B8:F22,5,FALSE) -> 200 | Y18: =V18+X18 -> 823.956
A19: darbo užmokestis | B19: ="03" -> 03 | C19: =EOMONTH(DATE(2026,3,1),0) -> 46112 | D19: =Darbuotojai!B9 -> Darbuotojas 4 | E19: =VLOOKUP(D19,Darbuotojai!$B$6:$D$20,3,FALSE) -> 980 | F19: =VLOOKUP(D19,Darbuotojai!$B$6:$E$20,4,FALSE) -> 5.5681818 | G19: =NETWORKDAYS(DATE(2026,3,1),DATE(2026,3,31),DATE(2026,3,11)) -> 21 | H19: =RANDBETWEEN(15,G19) -> 16 | I19: =H19*8 -> 128 | J19: =E19*'Darbo užmokestis'!H13/'Darbo užmokestis'!G13 -> 746.66667 | K19: =IF(G19=H19,50,0) -> 0 | L19: =IF(G19-H19>4,8*F19*(G19-H19),0) -> 222.72727 | M19: 0 | N19: =IF(G19-H19<=4,F19*8*RANDBETWEEN(1,2),0) -> 0 | O19: =J19+K19+L19+M19+N19 -> 969.39394 | P19: =IF(IF(O19<=730,460,IF(O19<1678,460-0.26*O19,IF(O19>1678,460-0.18*O19)))>0,IF(O19<=730,460,IF(O19<1678,460-0.26*O19,IF(O19>1678,460-0.18*O19))),0) -> 207.95758 | Q19: =(O19-P19)*20% -> 152.28727 | R19: =(O19-N19)*14.29% -> 138.52639 | S19: =O19*6.98% -> 67.663697 | T19: =J19*3% -> 22.4 | U19: =SUM(P19:S19) -> 566.43494 | V19: =O19-U19 -> 402.959 | W19: =O19*1.77% -> 17.158273 | X19: =VLOOKUP(D19,Darbuotojai!B9:F23,5,FALSE) -> 150 | Y19: =V19+X19 -> 552.959
A20: darbo užmokestis | B20: ="03" -> 03 | C20: =EOMONTH(DATE(2026,3,1),0) -> 46112 | D20: =Darbuotojai!B10 -> Darbuotojas 5 | E20: =VLOOKUP(D20,Darbuotojai!$B$6:$D$20,3,FALSE) -> 980 | F20: =VLOOKUP(D20,Darbuotojai!$B$6:$E$20,4,FALSE) -> 5.5681818 | G20: =NETWORKDAYS(DATE(2026,3,1),DATE(2026,3,31),DATE(2026,3,11)) -> 21 | H20: =RANDBETWEEN(15,G20) -> 15 | I20: =H20*8 -> 120 | J20: =E20*'Darbo užmokestis'!H14/'Darbo užmokestis'!G14 -> 980 | K20: =IF(G20=H20,50,0) -> 0 | L20: =IF(G20-H20>4,8*F20*(G20-H20),0) -> 267.27273 | M20: 0 | N20: =IF(G20-H20<=4,F20*8*RANDBETWEEN(1,2),0) -> 0 | O20: =J20+K20+L20+M20+N20 -> 1247.2727 | P20: =IF(IF(O20<=730,460,IF(O20<1678,460-0.26*O20,IF(O20>1678,460-0.18*O20)))>0,IF(O20<=730,460,IF(O20<1678,460-0.26*O20,IF(O20>1678,460-0.18*O20))),0) -> 135.70909 | Q20: =(O20-P20)*20% -> 222.31273 | R20: =(O20-N20)*14.29% -> 178.23527 | S20: =O20*6.98% -> 87.059636 | T20: =J20*3% -> 29.4 | U20: =SUM(P20:S20) -> 623.31673 | V20: =O20-U20 -> 623.956 | W20: =O20*1.77% -> 22.076727 | X20: =VLOOKUP(D20,Darbuotojai!B10:F24,5,FALSE) -> 200 | Y20: =V20+X20 -> 823.956
A21: darbo užmokestis | B21: ="03" -> 03 | C21: =EOMONTH(DATE(2026,3,1),0) -> 46112 | D21: =Darbuotojai!B15 -> Darbuotojas 10 | E21: =VLOOKUP(D21,Darbuotojai!$B$6:$D$20,3,FALSE) -> 980 | F21: =VLOOKUP(D21,Darbuotojai!$B$6:$E$20,4,FALSE) -> 5.5681818 | G21: =NETWORKDAYS(DATE(2026,3,1),DATE(2026,3,31),DATE(2026,3,11)) -> 21 | H21: =RANDBETWEEN(15,G21) -> 18 | I21: =H21*8 -> 144 | J21: =E21*'Darbo užmokestis'!H19/'Darbo užmokestis'!G19 -> 746.66667 | K21: =IF(G21=H21,50,0) -> 0 | L21: =IF(G21-H21>4,8*F21*(G21-H21),0) -> 0 | M21: 0 | N21: =IF(G21-H21<=4,F21*8*RANDBETWEEN(1,2),0) -> 89.090909 | O21: =J21+K21+L21+M21+N21 -> 835.75758 | P21: =IF(IF(O21<=730,460,IF(O21<1678,460-0.26*O21,IF(O21>1678,460-0.18*O21)))>0,IF(O21<=730,460,IF(O21<1678,460-0.26*O21,IF(O21>1678,460-0.18*O21))),0) -> 242.70303 | Q21: =(O21-P21)*20% -> 118.61091 | R21: =(O21-N21)*14.29% -> 106.69867 | S21: =O21*6.98% -> 58.335879 | T21: =J21*3% -> 22.4 | U21: =SUM(P21:S21) -> 526.34848 | V21: =O21-U21 -> 309.40909 | W21: =O21*1.77% -> 14.792909 | X21: =VLOOKUP(D21,Darbuotojai!B15:F29,5,FALSE) -> 200 | Y21: =V21+X21 -> 509.40909
A22: darbo užmokestis | B22: ="03" -> 03 | C22: =EOMONTH(DATE(2026,3,1),0) -> 46112 | D22: =Darbuotojai!B16 -> Darbuotojas 11 | E22: =VLOOKUP(D22,Darbuotojai!$B$6:$D$20,3,FALSE) -> 980 | F22: =VLOOKUP(D22,Darbuotojai!$B$6:$E$20,4,FALSE) -> 5.5681818 | G22: =NETWORKDAYS(DATE(2026,3,1),DATE(2026,3,31),DATE(2026,3,11)) -> 21 | H22: =RANDBETWEEN(15,G22) -> 15 | I22: =H22*8 -> 120 | J22: =E22*'Darbo užmokestis'!H20/'Darbo užmokestis'!G20 -> 700 | K22: =IF(G22=H22,50,0) -> 0 | L22: =IF(G22-H22>4,8*F22*(G22-H22),0) -> 267.27273 | M22: 0 | N22: =IF(G22-H22<=4,F22*8*RANDBETWEEN(1,2),0) -> 0 | O22: =J22+K22+L22+M22+N22 -> 967.27273 | P22: =IF(IF(O22<=730,460,IF(O22<1678,460-0.26*O22,IF(O22>1678,460-0.18*O22)))>0,IF(O22<=730,460,IF(O22<1678,460-0.26*O22,IF(O22>1678,460-0.18*O22))),0) -> 208.50909 | Q22: =(O22-P22)*20% -> 151.75273 | R22: =(O22-N22)*14.29% -> 138.22327 | S22: =O22*6.98% -> 67.515636 | T22: =J22*3% -> 21 | U22: =SUM(P22:S22) -> 566.00073 | V22: =O22-U22 -> 401.272 | W22: =O22*1.77% -> 17.120727 | X22: =VLOOKUP(D22,Darbuotojai!B16:F30,5,FALSE) -> 150 | Y22: =V22+X22 -> 551.272
A23: darbo užmokestis | B23: ="03" -> 03 | C23: =EOMONTH(DATE(2026,3,1),0) -> 46112 | D23: =Darbuotojai!B17 -> Darbuotojas 12 | E23: =VLOOKUP(D23,Darbuotojai!$B$6:$D$20,3,FALSE) -> 980 | F23: =VLOOKUP(D23,Darbuotojai!$B$6:$E$20,4,FALSE) -> 5.5681818 | G23: =NETWORKDAYS(DATE(2026,3,1),DATE(2026,3,31),DATE(2026,3,11)) -> 21 | H23: =RANDBETWEEN(15,G23) -> 19 | I23: =H23*8 -> 152 | J23: =E23*'Darbo užmokestis'!H21/'Darbo užmokestis'!G21 -> 840 | K23: =IF(G23=H23,50,0) -> 0 | L23: =IF(G23-H23>4,8*F23*(G23-H23),0) -> 0 | M23: 0 | N23: =IF(G23-H23<=4,F23*8*RANDBETWEEN(1,2),0) -> 89.090909 | O23: =J23+K23+L23+M23+N23 -> 929.09091 | P23: =IF(IF(O23<=730,460,IF(O23<1678,460-0.26*O23,IF(O23>1678,460-0.18*O23)))>0,IF(O23<=730,460,IF(O23<1678,460-0.26*O23,IF(O23>1678,460-0.18*O23))),0) -> 218.43636 | Q23: =(O23-P23)*20% -> 142.13091 | R23: =(O23-N23)*14.29% -> 120.036 | S23: =O23*6.98% -> 64.850545 | T23: =J23*3% -> 25.2 | U23: =SUM(P23:S23) -> 545.45382 | V23: =O23-U23 -> 383.63709 | W23: =O23*1.77% -> 16.444909 | X23: =VLOOKUP(D23,Darbuotojai!B17:F31,5,FALSE) -> 150 | Y23: =V23+X23 -> 533.63709
A24: darbo užmokestis | B24: ="03" -> 03 | C24: =EOMONTH(DATE(2026,3,1),0) -> 46112 | D24: =Darbuotojai!B18 -> Darbuotojas 13 | E24: =VLOOKUP(D24,Darbuotojai!$B$6:$D$20,3,FALSE) -> 980 | F24: =VLOOKUP(D24,Darbuotojai!$B$6:$E$20,4,FALSE) -> 5.5681818 | G24: =NETWORKDAYS(DATE(2026,3,1),DATE(2026,3,31),DATE(2026,3,11)) -> 21 | H24: =RANDBETWEEN(15,G24) -> 21 | I24: =H24*8 -> 168 | J24: =E24*'Darbo užmokestis'!H22/'Darbo užmokestis'!G22 -> 700 | K24: =IF(G24=H24,50,0) -> 50 | L24: =IF(G24-H24>4,8*F24*(G24-H24),0) -> 0 | M24: 0 | N24: =IF(G24-H24<=4,F24*8*RANDBETWEEN(1,2),0) -> 44.545455 | O24: =J24+K24+L24+M24+N24 -> 794.54545 | P24: =IF(IF(O24<=730,460,IF(O24<1678,460-0.26*O24,IF(O24>1678,460-0.18*O24)))>0,IF(O24<=730,460,IF(O24<1678,460-0.26*O24,IF(O24>1678,460-0.18*O24))),0) -> 253.41818 | Q24: =(O24-P24)*20% -> 108.22545 | R24: =(O24-N24)*14.29% -> 107.175 | S24: =O24*6.98% -> 55.459273 | T24: =J24*3% -> 21 | U24: =SUM(P24:S24) -> 524.27791 | V24: =O24-U24 -> 270.26755 | W24: =O24*1.77% -> 14.063455 | X24: =VLOOKUP(D24,Darbuotojai!B18:F32,5,FALSE) -> 200 | Y24: =V24+X24 -> 470.26755

Sheet suvestinė
A3: 1 | B3: Keli darbuotojai dirbo 18 ir daugiau dienų | C3: =COUNTIF(Lentelė1[[#All],[Faktiškai dirbta, d.]],">18") -> 6
A4: 2 | B4: Darbuotojų, kurie dirbo mažiau nei 18 dienų, išmokamų atlyginimų suma | C4: =SUMIF(Lentelė1[Faktiškai dirbta, d.],"<18",Lentelė1[Išmokėtina suma, €]) -> 4172.553
A5: 3 | B5: Vidutinė avanso suma | C5: =AVERAGE(Lentelė1[Avansas, €]) -> 183.33333
A6: 4 | B6: Darbuotojų, kurių valandinis įkainis mažiau nei 8 eurai, sumokamų VSD vidurkis | C6: =AVERAGEIF(Lentelė1[Valandinis tarifinis atlygis, €],"<8",Lentelė1[VSD įmoka, €]) -> 139.68163
A7: 5 | B7: Pritaikyto NPD mediana | C7: =MEDIAN(Lentelė1[pritaikytas NPD, €]) -> 178.62429
A8: 6 | B8: 2 didžiausia GPM reikšmė | C8: =LARGE(Lentelė1[GPM, €],2) -> 316.65801
