Workbook

Sheet Užduotis
A1: Savarankiško darbo užduotis:
A3: Darbalapis "Darbuotojai"
B4: Stulpelio pavadinimas | C4: Užduotis | D4: Pastabos
A5: 1 | B5: Eil. Nr. | C5: Sukurkite seką
A6: 2 | B6: Pavardė, vardas | C6: Sukurkite seką "Darbuotojas1" ir t.t.
A7: 3 | B7: Pareigos | C7: Sudarykite sąrašą ir parinkite vieną iš pateiktų pareigybių kiekvienam darbuotojui. Pareigybių skaičius duotas "Pareigybės" lape | D7: sąrašas
A8: 4 | B8: Pareiginis atlyginimas, € | C8: Parinkite kiekvienam darbuotojui pareiginį atlyginimą pagal pareigas | D8: vlookup()
A9: 5 | B9: Valandinis tarifinis atlygis, € | C9: Apskaičiuokite iš pareiginio atlyginimo imdami vidutinį mėnesio darbo dienų skaičių 22
A10: 6 | B10: Avansas, € | C10: Avansą parinkite atsitiktiniu būdu 150 arba 200 eurų | D10: choose()
A11: 7 | B11: Asmens kodas | C11: nepildyti
A12: 8 | B12: Tel. Nr. | C12: sujunkite "+370 6" ir 7 atsitiktiniai skaičiai | D12: concatenate()
A13: 9 | B13: Adresas | C13: sugalvokite patys
A16: Darbalapis "Darbo užmokestis"
B17: Stulpelio pavadinimas | C17: Užduotis
A18: 1 | B18: A5 | C18: Įrašykite kovo mėnesį
A19: 2 | B19: Registras | C19: Darbo užmokestis
A20: 3 | B20: Op. Nr. | C20: tarkime, kad darote registrą kovo mėnesiui, tada rašykite visur 03
A21: 4 | B21: Skaičiavimo data | C21: Pasirinkite šių metų kovo datą formatas: 2022/kov/31 | D21: eomonth()
A22: 5 | B22: Pavardė, vardas | C22: nukopijuokite darbuotojus iš darbuotojų lapo
A23: 6 | B23: Pareiginis atlyginimas, € | C23: Parinkite kiekvienam darbuotojui pareiginį atlyginimą iš darbuotojų lapo | D23: vlookup()
A24: 7 | B24: Valandinis tarifinis atlygis, € | C24: Parinkite kiekvienam darbuotojui pareiginį valandinį atlyginimą iš darbuotojų lapo | D24: vlookup()
A25: 8 | B25: Nustatytas darbo dienų skaičius | C25: apskaičiuokite darbo dienų skaičių su funkcija Networkdays(). Nepamirškite švenčių dienų.
A26: 9 | B26: Faktiškai dirbta, d. | C26: parinkite atsitiktiniu būdu nuo 15 iki mėnesio darbo dienų skaičiaus | D26: randbetween()
A27: 10 | B27: Faktiškai dirbta, val. | C27: dienos * 8 val.
A28: 11 | B28: Atlyginimas, € | C28: atlyginimas priskaičiuotas už dirbtas dienas | D28: atlyginimas*fakt.dirbtų d./d.d.skaičius
A29: 12 | B29: Mėnesinė priemoka, € | C29: Skirkite mėnesinę priemoką 50 eurų, jei dirbo visas darbo dienas | D29: IF
A30: 13 | B30: Eilinės atostogos, € | C30: Jei darbuotojas nedirbo daugiau nei 4 dienas, tada jis tas dienas buvo atostogose. Paskaičiuokite už tas dienas atostoginius | D30: IF
A31: 14 | B31: Kompensacija už nepanaudotas atostogas, € | C31: 0
A32: 15 | B32: Nedarbingumo pašalpa darbdavio lėšomis, € | C32: Jei darbuotojas nedirbo 4 ar mažiau dienų, tada jis sirgo. Paskaičiuokite už tas 1-2 dienas darbdavio mokamą atlyginimą | D32: IF
A33: 16 | B33: Priskaičiuota iš viso, € | C33: Visos priskaičiuotos sumos
A34: 17 | B34: pritaikytas NPD, € | C34: paskaičiuokite pagal dešinėje duotas formules | H34: Neapmokestinamo minimumo skaičiavimas:
A35: 18 | B35: GPM, € | C35: GMP=(Priskaičiuota - NPD)*20% | D35: koeficientams suteikite vardus | G35: 1) | H35: NPD max - 460 Eur. Taikomas pajamoms iki 730 Eur.
A36: 19 | B36: VSD ir PSD įmokos, € | C36: 14,29% nuo priskaičiuoto atlygio atėmus nedarbingumo pašalpos sumą, PSD - 6,98% | G36: 2) | H36: NPD = 460 – 0,26* (gyventojo mėnesio su darbo santykiais arba jų esmę atitinkančiais santykiais susijusios pajamos – 730) | R36: jei Du<1678
A37: 20 | B37: Papildomas pensijinis kaupimas | C37: 3% nuo priskaičiuoto atlygio | G37: 3) | H37: NPD = 400 – 0,18* (gyventojo mėnesio su darbo santykiais arba jų esmę atitinkančiais santykiais susijusios pajamos – 642) | R37: jei Du>1678
A38: 21 | B38: Išskaičiuota iš viso, € | C38: visa išskaičiuota suma mokesčiams | G38: 4) | H38: Jei neigiamas tai rašome 0
A39: 22 | B39: Išmokėtina suma, € | C39: Išmokama = priskaičiuota - išskaičiuota
A40: 23 | B40: Darbdavio VSD įmokos, € | C40: VSD (1,77%) * priskaičiuota
A41: 24 | B41: Avansas, € | C41: Parinkite iš darbuotojų lapo | D41: vlookup()
A42: 25 | B42: Išmokėtina suma po avanso, € | C42: Išmokama suma atėmus avansą
A43: 26 | B43: Garantinis fondas | C43: 0,2% nuo visiems darbuotojams priskaičiuotų atlyginimų
...

Sheet Pareigybės
A3: Eil. Nr. | B3: Pareigybė | C3: Pareiginis atlyginimas, € | D3: Darbuotojų skaičius
A4: 1 | B4: Vadovas | C4: 2800 | D4: 1
A5: 2 | B5: Buhalterė | C5: 1600 | D5: 2
A6: 3 | B6: Administratorė | C6: 1505 | D6: 1
A7: 4 | B7: Vadybininkas | C7: 1199 | D7: 2
A8: 5 | B8: Sandėlininkas | C8: 1090 | D8: 2
A9: 6 | B9: Gamybos darbuotojas | C9: 980 | D9: 7

Sheet Darbuotojai
A1: Darbuotojai
A5: Eil. Nr. | B5: Pavardė, vardas | C5: Pareigos | D5: Pareiginis atlyginimas, € | E5: Valandinis tarifinis atlygis, € | F5: Avansas, € | G5: Asmens kodas | H5: Tel. Nr. | I5: Adresas
A6: 1. | B6: Darbuotojas1 | C6: =Pareigybės!B4 -> Vadovas | D6: =VLOOKUP(C6,Pareigybės!$B$4:$C$9,2,FALSE) -> 2800 | E6: =D6/22/8 -> 15.909091 | F6: =CHOOSE(RANDBETWEEN(1,2),150,200) -> 150 | G6: x | H6: =CONCATENATE("+370 6",RANDBETWEEN(10,99)," ",RANDBETWEEN(10000,99999)) -> +370 642 90124 | I6: Jaunystės 1
A7: 2. | B7: Darbuotojas2 | C7: =Pareigybės!B5 -> Buhalterė | D7: =VLOOKUP(C7,Pareigybės!$B$4:$C$9,2,FALSE) -> 1600 | E7: =D7/22/8 -> 9.0909091 | F7: =CHOOSE(RANDBETWEEN(1,2),150,200) -> 150 | G7: x | H7: =CONCATENATE("+370 6",RANDBETWEEN(10,99)," ",RANDBETWEEN(10000,99999)) -> +370 695 49209 | I7: Jaunystės 2
A8: 3. | B8: Darbuotojas3 | C8: =Pareigybės!B5 -> Buhalterė | D8: =VLOOKUP(C8,Pareigybės!$B$4:$C$9,2,FALSE) -> 1600 | E8: =D8/22/8 -> 9.0909091 | F8: =CHOOSE(RANDBETWEEN(1,2),150,200) -> 200 | G8: x | H8: =CONCATENATE("+370 6",RANDBETWEEN(10,99)," ",RANDBETWEEN(10000,99999)) -> +370 631 51756 | I8: Jaunystės 3
A9: 4. | B9: Darbuotojas4 | C9: =Pareigybės!B6 -> Administratorė | D9: =VLOOKUP(C9,Pareigybės!$B$4:$C$9,2,FALSE) -> 1505 | E9: =D9/22/8 -> 8.5511364 | F9: =CHOOSE(RANDBETWEEN(1,2),150,200) -> 200 | G9: x | H9: =CONCATENATE("+370 6",RANDBETWEEN(10,99)," ",RANDBETWEEN(10000,99999)) -> +370 633 63122 | I9: Jaunystės 4
A10: 5. | B10: Darbuotojas5 | C10: =Pareigybės!B7 -> Vadybininkas | D10: =VLOOKUP(C10,Pareigybės!$B$4:$C$9,2,FALSE) -> 1199 | E10: =D10/22/8 -> 6.8125 | F10: =CHOOSE(RANDBETWEEN(1,2),150,200) -> 200 | G10: x | H10: =CONCATENATE("+370 6",RANDBETWEEN(10,99)," ",RANDBETWEEN(10000,99999)) -> +370 698 24090 | I10: Jaunystės 5
A11: 6. | B11: Darbuotojas6 | C11: =Pareigybės!B7 -> Vadybininkas | D11: =VLOOKUP(C11,Pareigybės!$B$4:$C$9,2,FALSE) -> 1199 | E11: =D11/22/8 -> 6.8125 | F11: =CHOOSE(RANDBETWEEN(1,2),150,200) -> 200 | G11: x | H11: =CONCATENATE("+370 6",RANDBETWEEN(10,99)," ",RANDBETWEEN(10000,99999)) -> +370 676 27366 | I11: Jaunystės 6
A12: 7. | B12: Darbuotojas7 | C12: =Pareigybės!B8 -> Sandėlininkas | D12: =VLOOKUP(C12,Pareigybės!$B$4:$C$9,2,FALSE) -> 1090 | E12: =D12/22/8 -> 6.1931818 | F12: =CHOOSE(RANDBETWEEN(1,2),150,200) -> 150 | G12: x | H12: =CONCATENATE("+370 6",RANDBETWEEN(10,99)," ",RANDBETWEEN(10000,99999)) -> +370 676 31491 | I12: Jaunystės 7
A13: 8. | B13: Darbuotojas8 | C13: =Pareigybės!B8 -> Sandėlininkas | D13: =VLOOKUP(C13,Pareigybės!$B$4:$C$9,2,FALSE) -> 1090 | E13: =D13/22/8 -> 6.1931818 | F13: =CHOOSE(RANDBETWEEN(1,2),150,200) -> 200 | G13: x | H13: =CONCATENATE("+370 6",RANDBETWEEN(10,99)," ",RANDBETWEEN(10000,99999)) -> +370 642 70153 | I13: Jaunystės 8
A14: 9. | B14: Darbuotojas9 | C14: =Pareigybės!B9 -> Gamybos darbuotojas | D14: =VLOOKUP(C14,Pareigybės!$B$4:$C$9,2,FALSE) -> 980 | E14: =D14/22/8 -> 5.5681818 | F14: =CHOOSE(RANDBETWEEN(1,2),150,200) -> 150 | G14: x | H14: =CONCATENATE("+370 6",RANDBETWEEN(10,99)," ",RANDBETWEEN(10000,99999)) -> +370 615 90294 | I14: Jaunystės 9
A15: 10. | B15: Darbuotojas10 | C15: =Pareigybės!B9 -> Gamybos darbuotojas | D15: =VLOOKUP(C15,Pareigybės!$B$4:$C$9,2,FALSE) -> 980 | E15: =D15/22/8 -> 5.5681818 | F15: =CHOOSE(RANDBETWEEN(1,2),150,200) -> 150 | G15: x | H15: =CONCATENATE("+370 6",RANDBETWEEN(10,99)," ",RANDBETWEEN(10000,99999)) -> +370 648 95174 | I15: Jaunystės 10
A16: 11. | B16: Darbuotojas11 | C16: =Pareigybės!B9 -> Gamybos darbuotojas | D16: =VLOOKUP(C16,Pareigybės!$B$4:$C$9,2,FALSE) -> 980 | E16: =D16/22/8 -> 5.5681818 | F16: =CHOOSE(RANDBETWEEN(1,2),150,200) -> 150 | G16: x | H16: =CONCATENATE("+370 6",RANDBETWEEN(10,99)," ",RANDBETWEEN(10000,99999)) -> +370 678 63815 | I16: Jaunystės 11
A17: 12. | B17: Darbuotojas12 | C17: =Pareigybės!B9 -> Gamybos darbuotojas | D17: =VLOOKUP(C17,Pareigybės!$B$4:$C$9,2,FALSE) -> 980 | E17: =D17/22/8 -> 5.5681818 | F17: =CHOOSE(RANDBETWEEN(1,2),150,200) -> 200 | G17: x | H17: =CONCATENATE("+370 6",RANDBETWEEN(10,99)," ",RANDBETWEEN(10000,99999)) -> +370 667 13191 | I17: Jaunystės 12
A18: 13. | B18: Darbuotojas13 | C18: =Pareigybės!B9 -> Gamybos darbuotojas | D18: =VLOOKUP(C18,Pareigybės!$B$4:$C$9,2,FALSE) -> 980 | E18: =D18/22/8 -> 5.5681818 | F18: =CHOOSE(RANDBETWEEN(1,2),150,200) -> 200 | G18: x | H18: =CONCATENATE("+370 6",RANDBETWEEN(10,99)," ",RANDBETWEEN(10000,99999)) -> +370 670 48875 | I18: Jaunystės 13
A19: 14. | B19: Darbuotojas14 | C19: =Pareigybės!B9 -> Gamybos darbuotojas | D19: =VLOOKUP(C19,Pareigybės!$B$4:$C$9,2,FALSE) -> 980 | E19: =D19/22/8 -> 5.5681818 | F19: =CHOOSE(RANDBETWEEN(1,2),150,200) -> 150 | G19: x | H19: =CONCATENATE("+370 6",RANDBETWEEN(10,99)," ",RANDBETWEEN(10000,99999)) -> +370 617 93382 | I19: Jaunystės 14
A20: 15. | B20: Darbuotojas15 | C20: =Pareigybės!B9 -> Gamybos darbuotojas | D20: =VLOOKUP(C20,Pareigybės!$B$4:$C$9,2,FALSE) -> 980 | E20: =D20/22/8 -> 5.5681818 | F20: =CHOOSE(RANDBETWEEN(1,2),150,200) -> 200 | G20: x | H20: =CONCATENATE("+370 6",RANDBETWEEN(10,99)," ",RANDBETWEEN(10000,99999)) -> +370 622 59283 | I20: Jaunystės 15

Sheet Darbo užmokestis
A1: UAB "Jaunystė" | F1: GPM1 | G1: 0.2 | J1: Garantinis fondas | L1: 0.002 | N1: Ilgalaikio darbo išmokų fondo įmoka | R1: 0.0016 | S1: =PRODUCT(V7,R1) -> 9.8375065
A2: Įmonės kodas 1222555888 | F2: GPM2 | G2: 0.27 | J2: Įmoka | L2: =PRODUCT(V7,L1) -> 12.296883 | N2: Soc. draudimo įmokos nelaimingų atsitikimų draudimui | R2: 0.0014 | S2: =PRODUCT(V7,R2) -> 8.6078182
A3: Darbo užmokesčio registras | F3: VSD darbuotojo | G3: 0.1429
F4: PSD | G4: 0.0698
A5: Kovo | F5: VSD darbdavio | G5: 0.0177
F6: Papildomas pensijinis kaupimas | G6: 0.03
A7: mėnuo | F7: Nedarbingumo pašalpa | G7: 0.65 | I7: Iš viso: | J7: =SUM(J10:J24) -> 15683.545 | K7: =SUM(K10:K24) -> 50 | L7: =SUM(L10:L24) -> 1969.8719 | M7: =SUM(M10:M24) -> 0 | N7: =SUM(N10:N24) -> 469.29752 | O7: =SUM(O10:O24) -> 18172.715 | P7: =SUM(P10:P24) -> 5098.79 | Q7: =SUM(Q10:Q24) -> 2614.785 | ... Y7: =SUM(Y10:Y24) -> 3498.4416
A9: Registras | B9: Op. Nr. | C9: Skaičiavimo data | D9: Pavardė, vardas | E9: Pareiginis atlyginimas, € | F9: Valandinis tarifinis atlygis, € | G9: Nustatytas darbo dienų skaičius | H9: Faktiškai dirbta, d. | I9: Faktiškai dirbta, val. | J9: Atlyginimas, € | K9: Mėnesinė priemoka, € | L9: Eilinės atostogos, € | M9: Kompensacija už nepanaudotas atostogas, € | N9: Nedarbingumo pašalpa darbdavio lėšomis, € | O9: Priskaičiuota iš viso, € | P9: pritaikytas NPD, € | Q9: GPM, € | R9: VSD įmoka, € | S9: PSD įmoka, € | T9: Papildomas pensijinis kaupimas | U9: Išskaičiuota iš viso, € | V9: Išmokėtina suma, € | W9: Darbdavio VSD įmokos, € | X9: Avansas, € | Y9: Išmokėtina suma po avanso, €
A10: darbo užmokestis | B10: ="03" -> 03 | C10: =DATE(2026,3,15) -> 46096 | D10: =Darbuotojai!B6 -> Darbuotojas1 | E10: =Darbuotojai!D6 -> 2800 | F10: =Darbuotojai!E6 -> 15.909091 | G10: =NETWORKDAYS(2026-3-31,2026-3-1,2026-3-11) -> 22 | H10: =RANDBETWEEN(15,G10) -> 21 | I10: =PRODUCT(H10,8) -> 168 | J10: =PRODUCT(F10,I10) -> 2672.7273 | K10: =IF(H10=G10,50,0) -> 0 | L10: =IF(G10-H10>4,J10/G10*(G10-H10),0) -> 0 | M10: 0 | N10: =IF(G10-H10<=4,J10/G10*(G10-H10),0) -> 121.4876 | O10: =SUM(J10:N10) -> 2794.2149 | P10: =IF(IF(O10<=730,460,IF(O10<1678,460-0.26*O10,IF(O10>1678,460-0.18*O10)))>0,IF(O10<=730,460,IF(O10<1678,460-0.26*O10,IF(O10>1678,460-0.18*O10))),0) -> 0 | Q10: =PRODUCT(O10-P10,$G$1) -> 558.84298 | R10: =PRODUCT(O10-N10,$G$3) -> 381.93273 | S10: =PRODUCT(O10-N10,$G$4) -> 186.55636 | T10: =PRODUCT($G$6,O10) -> 83.826446 | U10: =SUM(P10:T10) -> 1211.1585 | V10: =O10-U10 -> 1583.0564 | W10: =PRODUCT($G$5,O10) -> 49.457603 | X10: =Darbuotojai!F6 -> 150 | Y10: =V10-X10 -> 1433.0564
A11: darbo užmokestis | B11: ="03" -> 03 | C11: =DATE(2026,3,15) -> 46096 | D11: =Darbuotojai!B7 -> Darbuotojas2 | E11: =Darbuotojai!D7 -> 1600 | F11: =Darbuotojai!E7 -> 9.0909091 | G11: =NETWORKDAYS(2026-3-31,2026-3-1,2026-3-11) -> 22 | H11: =RANDBETWEEN(15,G11) -> 22 | I11: =PRODUCT(H11,8) -> 176 | J11: =PRODUCT(F11,I11) -> 1600 | K11: =IF(H11=G11,50,0) -> 50 | L11: =IF(G11-H11>4,J11/G11*(G11-H11),0) -> 0 | M11: 0 | N11: =IF(G11-H11<=4,J11/G11*(G11-H11),0) -> 0 | O11: =SUM(J11:N11) -> 1650 | P11: =MAX(0,IF(O11<=730,460,IF(O11<=1678,460-0.26*(O11-730),400-0.18*(O11-642)))) -> 220.8 | Q11: =PRODUCT(O11-P11,$G$1) -> 285.84 | R11: =PRODUCT(O11-N11,$G$3) -> 235.785 | S11: =PRODUCT(O11-N11,$G$4) -> 115.17 | T11: =PRODUCT($G$6,O11) -> 49.5 | U11: =SUM(P11:T11) -> 907.095 | V11: =O11-U11 -> 742.905 | W11: =PRODUCT($G$5,O11) -> 29.205 | X11: =Darbuotojai!F7 -> 150 | Y11: =V11-X11 -> 592.905
A12: darbo užmokestis | B12: ="03" -> 03 | C12: =DATE(2026,3,15) -> 46096 | D12: =Darbuotojai!B8 -> Darbuotojas3 | E12: =Darbuotojai!D8 -> 1600 | F12: =Darbuotojai!E8 -> 9.0909091 | G12: =NETWORKDAYS(2026-3-31,2026-3-1,2026-3-11) -> 22 | H12: =RANDBETWEEN(15,G12) -> 21 | I12: =PRODUCT(H12,8) -> 168 | J12: =PRODUCT(F12,I12) -> 1527.2727 | K12: =IF(H12=G12,50,0) -> 0 | L12: =IF(G12-H12>4,J12/G12*(G12-H12),0) -> 0 | M12: 0 | N12: =IF(G12-H12<=4,J12/G12*(G12-H12),0) -> 69.421488 | O12: =SUM(J12:N12) -> 1596.6942 | P12: =MAX(0,IF(O12<=730,460,IF(O12<=1678,460-0.26*(O12-730),400-0.18*(O12-642)))) -> 234.6595 | Q12: =PRODUCT(O12-P12,$G$1) -> 272.40694 | R12: =PRODUCT(O12-N12,$G$3) -> 218.24727 | S12: =PRODUCT(O12-N12,$G$4) -> 106.60364 | T12: =PRODUCT($G$6,O12) -> 47.900826 | U12: =SUM(P12:T12) -> 879.81818 | V12: =O12-U12 -> 716.87603 | W12: =PRODUCT($G$5,O12) -> 28.261488 | X12: =Darbuotojai!F8 -> 200 | Y12: =V12-X12 -> 516.87603
A13: darbo užmokestis | B13: ="03" -> 03 | C13: =DATE(2026,3,15) -> 46096 | D13: =Darbuotojai!B9 -> Darbuotojas4 | E13: =Darbuotojai!D9 -> 1505 | F13: =Darbuotojai!E9 -> 8.5511364 | G13: =NETWORKDAYS(2026-3-31,2026-3-1,2026-3-11) -> 22 | H13: =RANDBETWEEN(15,G13) -> 16 | I13: =PRODUCT(H13,8) -> 128 | J13: =PRODUCT(F13,I13) -> 1094.5455 | K13: =IF(H13=G13,50,0) -> 0 | L13: =IF(G13-H13>4,J13/G13*(G13-H13),0) -> 298.5124 | M13: 0 | N13: =IF(G13-H13<=4,J13/G13*(G13-H13),0) -> 0 | O13: =SUM(J13:N13) -> 1393.0579 | P13: =MAX(0,IF(O13<=730,460,IF(O13<=1678,460-0.26*(O13-730),400-0.18*(O13-642)))) -> 287.60496 | Q13: =PRODUCT(O13-P13,$G$1) -> 221.09058 | R13: =PRODUCT(O13-N13,$G$3) -> 199.06797 | S13: =PRODUCT(O13-N13,$G$4) -> 97.235438 | T13: =PRODUCT($G$6,O13) -> 41.791736 | U13: =SUM(P13:T13) -> 846.79068 | V13: =O13-U13 -> 546.26717 | W13: =PRODUCT($G$5,O13) -> 24.657124 | X13: =Darbuotojai!F9 -> 200 | Y13: =V13-X13 -> 346.26717
A14: darbo užmokestis | B14: ="03" -> 03 | C14: =DATE(2026,3,15) -> 46096 | D14: =Darbuotojai!B10 -> Darbuotojas5 | E14: =Darbuotojai!D10 -> 1199 | F14: =Darbuotojai!E10 -> 6.8125 | G14: =NETWORKDAYS(2026-3-31,2026-3-1,2026-3-11) -> 22 | H14: =RANDBETWEEN(15,G14) -> 16 | I14: =PRODUCT(H14,8) -> 128 | J14: =PRODUCT(F14,I14) -> 872 | K14: =IF(H14=G14,50,0) -> 0 | L14: =IF(G14-H14>4,J14/G14*(G14-H14),0) -> 237.81818 | M14: 0 | N14: =IF(G14-H14<=4,J14/G14*(G14-H14),0) -> 0 | O14: =SUM(J14:N14) -> 1109.8182 | P14: =MAX(0,IF(O14<=730,460,IF(O14<=1678,460-0.26*(O14-730),400-0.18*(O14-642)))) -> 361.24727 | Q14: =PRODUCT(O14-P14,$G$1) -> 149.71418 | R14: =PRODUCT(O14-N14,$G$3) -> 158.59302 | S14: =PRODUCT(O14-N14,$G$4) -> 77.465309 | T14: =PRODUCT($G$6,O14) -> 33.294545 | U14: =SUM(P14:T14) -> 780.31433 | V14: =O14-U14 -> 329.50385 | W14: =PRODUCT($G$5,O14) -> 19.643782 | X14: =Darbuotojai!F10 -> 200 | Y14: =V14-X14 -> 129.50385
A15: darbo užmokestis | B15: ="03" -> 03 | C15: =DATE(2026,3,15) -> 46096 | D15: =Darbuotojai!B11 -> Darbuotojas6 | E15: =Darbuotojai!D11 -> 1199 | F15: =Darbuotojai!E11 -> 6.8125 | G15: =NETWORKDAYS(2026-3-31,2026-3-1,2026-3-11) -> 22 | H15: =RANDBETWEEN(15,G15) -> 16 | I15: =PRODUCT(H15,8) -> 128 | J15: =PRODUCT(F15,I15) -> 872 | K15: =IF(H15=G15,50,0) -> 0 | L15: =IF(G15-H15>4,J15/G15*(G15-H15),0) -> 237.81818 | M15: 0 | N15: =IF(G15-H15<=4,J15/G15*(G15-H15),0) -> 0 | O15: =SUM(J15:N15) -> 1109.8182 | P15: =MAX(0,IF(O15<=730,460,IF(O15<=1678,460-0.26*(O15-730),400-0.18*(O15-642)))) -> 361.24727 | Q15: =PRODUCT(O15-P15,$G$1) -> 149.71418 | R15: =PRODUCT(O15-N15,$G$3) -> 158.59302 | S15: =PRODUCT(O15-N15,$G$4) -> 77.465309 | T15: =PRODUCT($G$6,O15) -> 33.294545 | U15: =SUM(P15:T15) -> 780.31433 | V15: =O15-U15 -> 329.50385 | W15: =PRODUCT($G$5,O15) -> 19.643782 | X15: =Darbuotojai!F11 -> 200 | Y15: =V15-X15 -> 129.50385
A16: darbo užmokestis | B16: ="03" -> 03 | C16: =DATE(2026,3,15) -> 46096 | D16: =Darbuotojai!B12 -> Darbuotojas7 | E16: =Darbuotojai!D12 -> 1090 | F16: =Darbuotojai!E12 -> 6.1931818 | G16: =NETWORKDAYS(2026-3-31,2026-3-1,2026-3-11) -> 22 | H16: =RANDBETWEEN(15,G16) -> 20 | I16: =PRODUCT(H16,8) -> 160 | J16: =PRODUCT(F16,I16) -> 990.90909 | K16: =IF(H16=G16,50,0) -> 0 | L16: =IF(G16-H16>4,J16/G16*(G16-H16),0) -> 0 | M16: 0 | N16: =IF(G16-H16<=4,J16/G16*(G16-H16),0) -> 90.082645 | O16: =SUM(J16:N16) -> 1080.9917 | P16: =MAX(0,IF(O16<=730,460,IF(O16<=1678,460-0.26*(O16-730),400-0.18*(O16-642)))) -> 368.74215 | Q16: =PRODUCT(O16-P16,$G$1) -> 142.44992 | R16: =PRODUCT(O16-N16,$G$3) -> 141.60091 | S16: =PRODUCT(O16-N16,$G$4) -> 69.165455 | T16: =PRODUCT($G$6,O16) -> 32.429752 | U16: =SUM(P16:T16) -> 754.38818 | V16: =O16-U16 -> 326.60355 | W16: =PRODUCT($G$5,O16) -> 19.133554 | X16: =Darbuotojai!F12 -> 150 | Y16: =V16-X16 -> 176.60355
A17: darbo užmokestis | B17: ="03" -> 03 | C17: =DATE(2026,3,15) -> 46096 | D17: =Darbuotojai!B13 -> Darbuotojas8 | E17: =Darbuotojai!D13 -> 1090 | F17: =Darbuotojai!E13 -> 6.1931818 | G17: =NETWORKDAYS(2026-3-31,2026-3-1,2026-3-11) -> 22 | H17: =RANDBETWEEN(15,G17) -> 17 | I17: =PRODUCT(H17,8) -> 136 | J17: =PRODUCT(F17,I17) -> 842.27273 | K17: =IF(H17=G17,50,0) -> 0 | L17: =IF(G17-H17>4,J17/G17*(G17-H17),0) -> 191.42562 | M17: 0 | N17: =IF(G17-H17<=4,J17/G17*(G17-H17),0) -> 0 | O17: =SUM(J17:N17) -> 1033.6983 | P17: =MAX(0,IF(O17<=730,460,IF(O17<=1678,460-0.26*(O17-730),400-0.18*(O17-642)))) -> 381.03843 | Q17: =PRODUCT(O17-P17,$G$1) -> 130.53198 | R17: =PRODUCT(O17-N17,$G$3) -> 147.71549 | S17: =PRODUCT(O17-N17,$G$4) -> 72.152145 | T17: =PRODUCT($G$6,O17) -> 31.01095 | U17: =SUM(P17:T17) -> 762.449 | V17: =O17-U17 -> 271.24935 | W17: =PRODUCT($G$5,O17) -> 18.296461 | X17: =Darbuotojai!F13 -> 200 | Y17: =V17-X17 -> 71.249345
A18: darbo užmokestis | B18: ="03" -> 03 | C18: =DATE(2026,3,15) -> 46096 | D18: =Darbuotojai!B14 -> Darbuotojas9 | E18: =Darbuotojai!D14 -> 980 | F18: =Darbuotojai!E14 -> 5.5681818 | G18: =NETWORKDAYS(2026-3-31,2026-3-1,2026-3-11) -> 22 | H18: =RANDBETWEEN(15,G18) -> 15 | I18: =PRODUCT(H18,8) -> 120 | J18: =PRODUCT(F18,I18) -> 668.18182 | K18: =IF(H18=G18,50,0) -> 0 | L18: =IF(G18-H18>4,J18/G18*(G18-H18),0) -> 212.60331 | M18: 0 | N18: =IF(G18-H18<=4,J18/G18*(G18-H18),0) -> 0 | O18: =SUM(J18:N18) -> 880.78512 | P18: =MAX(0,IF(O18<=730,460,IF(O18<=1678,460-0.26*(O18-730),400-0.18*(O18-642)))) -> 420.79587 | Q18: =PRODUCT(O18-P18,$G$1) -> 91.997851 | R18: =PRODUCT(O18-N18,$G$3) -> 125.86419 | S18: =PRODUCT(O18-N18,$G$4) -> 61.478802 | T18: =PRODUCT($G$6,O18) -> 26.423554 | U18: =SUM(P18:T18) -> 726.56027 | V18: =O18-U18 -> 154.22486 | W18: =PRODUCT($G$5,O18) -> 15.589897 | X18: =Darbuotojai!F14 -> 150 | Y18: =V18-X18 -> 4.2248554
A19: darbo užmokestis | B19: ="03" -> 03 | C19: =DATE(2026,3,15) -> 46096 | D19: =Darbuotojai!B15 -> Darbuotojas10 | E19: =Darbuotojai!D15 -> 980 | F19: =Darbuotojai!E15 -> 5.5681818 | G19: =NETWORKDAYS(2026-3-31,2026-3-1,2026-3-11) -> 22 | H19: =RANDBETWEEN(15,G19) -> 18 | I19: =PRODUCT(H19,8) -> 144 | J19: =PRODUCT(F19,I19) -> 801.81818 | K19: =IF(H19=G19,50,0) -> 0 | L19: =IF(G19-H19>4,J19/G19*(G19-H19),0) -> 0 | M19: 0 | N19: =IF(G19-H19<=4,J19/G19*(G19-H19),0) -> 145.78512 | O19: =SUM(J19:N19) -> 947.60331 | P19: =MAX(0,IF(O19<=730,460,IF(O19<=1678,460-0.26*(O19-730),400-0.18*(O19-642)))) -> 403.42314 | Q19: =PRODUCT(O19-P19,$G$1) -> 108.83603 | R19: =PRODUCT(O19-N19,$G$3) -> 114.57982 | S19: =PRODUCT(O19-N19,$G$4) -> 55.966909 | T19: =PRODUCT($G$6,O19) -> 28.428099 | U19: =SUM(P19:T19) -> 711.234 | V19: =O19-U19 -> 236.36931 | W19: =PRODUCT($G$5,O19) -> 16.772579 | X19: =Darbuotojai!F15 -> 150 | Y19: =V19-X19 -> 86.369306
A20: darbo užmokestis | B20: ="03" -> 03 | C20: =DATE(2026,3,15) -> 46096 | D20: =Darbuotojai!B16 -> Darbuotojas11 | E20: =Darbuotojai!D16 -> 980 | F20: =Darbuotojai!E16 -> 5.5681818 | G20: =NETWORKDAYS(2026-3-31,2026-3-1,2026-3-11) -> 22 | H20: =RANDBETWEEN(15,G20) -> 17 | I20: =PRODUCT(H20,8) -> 136 | J20: =PRODUCT(F20,I20) -> 757.27273 | K20: =IF(H20=G20,50,0) -> 0 | L20: =IF(G20-H20>4,J20/G20*(G20-H20),0) -> 172.10744 | M20: 0 | N20: =IF(G20-H20<=4,J20/G20*(G20-H20),0) -> 0 | O20: =SUM(J20:N20) -> 929.38017 | P20: =MAX(0,IF(O20<=730,460,IF(O20<=1678,460-0.26*(O20-730),400-0.18*(O20-642)))) -> 408.16116 | Q20: =PRODUCT(O20-P20,$G$1) -> 104.2438 | R20: =PRODUCT(O20-N20,$G$3) -> 132.80843 | S20: =PRODUCT(O20-N20,$G$4) -> 64.870736 | T20: =PRODUCT($G$6,O20) -> 27.881405 | U20: =SUM(P20:T20) -> 737.96552 | V20: =O20-U20 -> 191.41464 | W20: =PRODUCT($G$5,O20) -> 16.450029 | X20: =Darbuotojai!F16 -> 150 | Y20: =V20-X20 -> 41.41464
A21: darbo užmokestis | B21: ="03" -> 03 | C21: =DATE(2026,3,15) -> 46096 | D21: =Darbuotojai!B17 -> Darbuotojas12 | E21: =Darbuotojai!D17 -> 980 | F21: =Darbuotojai!E17 -> 5.5681818 | G21: =NETWORKDAYS(2026-3-31,2026-3-1,2026-3-11) -> 22 | H21: =RANDBETWEEN(15,G21) -> 16 | I21: =PRODUCT(H21,8) -> 128 | J21: =PRODUCT(F21,I21) -> 712.72727 | K21: =IF(H21=G21,50,0) -> 0 | L21: =IF(G21-H21>4,J21/G21*(G21-H21),0) -> 194.38017 | M21: 0 | N21: =IF(G21-H21<=4,J21/G21*(G21-H21),0) -> 0 | O21: =SUM(J21:N21) -> 907.10744 | P21: =MAX(0,IF(O21<=730,460,IF(O21<=1678,460-0.26*(O21-730),400-0.18*(O21-642)))) -> 413.95207 | Q21: =PRODUCT(O21-P21,$G$1) -> 98.631074 | R21: =PRODUCT(O21-N21,$G$3) -> 129.62565 | S21: =PRODUCT(O21-N21,$G$4) -> 63.316099 | T21: =PRODUCT($G$6,O21) -> 27.213223 | U21: =SUM(P21:T21) -> 732.73812 | V21: =O21-U21 -> 174.36932 | W21: =PRODUCT($G$5,O21) -> 16.055802 | X21: =Darbuotojai!F17 -> 200 | Y21: =V21-X21 -> -25.630678
A22: darbo užmokestis | B22: ="03" -> 03 | C22: =DATE(2026,3,15) -> 46096 | D22: =Darbuotojai!B18 -> Darbuotojas13 | E22: =Darbuotojai!D18 -> 980 | F22: =Darbuotojai!E18 -> 5.5681818 | G22: =NETWORKDAYS(2026-3-31,2026-3-1,2026-3-11) -> 22 | H22: =RANDBETWEEN(15,G22) -> 21 | I22: =PRODUCT(H22,8) -> 168 | J22: =PRODUCT(F22,I22) -> 935.45455 | K22: =IF(H22=G22,50,0) -> 0 | L22: =IF(G22-H22>4,J22/G22*(G22-H22),0) -> 0 | M22: 0 | N22: =IF(G22-H22<=4,J22/G22*(G22-H22),0) -> 42.520661 | O22: =SUM(J22:N22) -> 977.97521 | P22: =MAX(0,IF(O22<=730,460,IF(O22<=1678,460-0.26*(O22-730),400-0.18*(O22-642)))) -> 395.52645 | Q22: =PRODUCT(O22-P22,$G$1) -> 116.48975 | R22: =PRODUCT(O22-N22,$G$3) -> 133.67645 | S22: =PRODUCT(O22-N22,$G$4) -> 65.294727 | T22: =PRODUCT($G$6,O22) -> 29.339256 | U22: =SUM(P22:T22) -> 740.32664 | V22: =O22-U22 -> 237.64857 | W22: =PRODUCT($G$5,O22) -> 17.310161 | X22: =Darbuotojai!F18 -> 200 | Y22: =V22-X22 -> 37.64857
... A24: darbo užmokestis | B24: ="03" -> 03 | C24: =DATE(2026,3,15) -> 46096 | D24: =Darbuotojai!B20 -> Darbuotojas15 | E24: =Darbuotojai!D20 -> 980 | F24: =Darbuotojai!E20 -> 5.5681818 | G24: =NETWORKDAYS(2026-3-31,2026-3-1,2026-3-11) -> 22 | H24: =RANDBETWEEN(15,G24) -> 15 | I24: =PRODUCT(H24,8) -> 120 | J24: =PRODUCT(F24,I24) -> 668.18182 | K24: =IF(H24=G24,50,0) -> 0 | L24: =IF(G24-H24>4,J24/G24*(G24-H24),0) -> 212.60331 | M24: 0 | N24: =IF(G24-H24<=4,J24/G24*(G24-H24),0) -> 0 | O24: =SUM(J24:N24) -> 880.78512 | P24: =MAX(0,IF(O24<=730,460,IF(O24<=1678,460-0.26*(O24-730),400-0.18*(O24-642)))) -> 420.79587 | Q24: =PRODUCT(O24-P24,$G$1) -> 91.997851 | R24: =PRODUCT(O24-N24,$G$3) -> 125.86419 | S24: =PRODUCT(O24-N24,$G$4) -> 61.478802 | T24: =PRODUCT($G$6,O24) -> 26.423554 | U24: =SUM(P24:T24) -> 726.56027 | V24: =O24-U24 -> 154.22486 | W24: =PRODUCT($G$5,O24) -> 15.589897 | X24: =Darbuotojai!F20 -> 200 | Y24: =V24-X24 -> -45.775145

Sheet suvestinė
A3: 1 | B3: Keli darbuotojai dirbo 18 ir daugiau dienų | C3: =COUNTIF(Lentelė1[Faktiškai dirbta, d.],">=18") -> 6
A4: 2 | B4: Darbuotojų, kurie dirbo mažiau nei 18 dienų, išmokamų atlyginimų suma | C4: =SUMIF(Lentelė1[Faktiškai dirbta, d.],"<18",Lentelė1[Išmokėtina suma, €]) -> 2304.9828
A5: 3 | B5: Vidutinė avanso suma | C5: =AVERAGE(Lentelė1[Avansas, €]) -> 176.66667
A6: 4 | B6: Darbuotojų, kurių valandinis įkainis mažiau nei 8 eurai, sumokamų VSD vidurkis | C6: =AVERAGEIF(Lentelė1[Valandinis tarifinis atlygis, €],"<=8",Lentelė1[VSD įmoka, €]) -> 135.88958
A7: 5 | B7: Pritaikyto NPD mediana | C7: =MEDIAN(Lentelė1[pritaikytas NPD, €]) -> 381.03843
A8: 6 | B8: 2 didžiausia GPM reikšmė | C8: =LARGE(Lentelė1[GPM, €],2) -> 285.84
