Workbook

Sheet Užduotis
A1: Savarankiško darbo užduotis:
A3: Darbalapis "Darbuotojai"
B4: Stulpelio pavadinimas | C4: Užduotis | D4: Pastabos
A5: 1 | B5: Eil. Nr. | C5: Sukurkite seką
A6: 2 | B6: Pavardė, vardas | C6: Sukurkite seką "Darbuotojas1" ir t.t.
A7: 3 | B7: Pareigos | C7: Sudarykite sąrašą ir parinkite vieną iš pateiktų pareigybių kiekvienam darbuotojui. Pareigybių skaičius duotas "Pareigybės" lape | D7: sąrašas
A8: 4 | B8: Pareiginis atlyginimas, € | C8: Parinkite kiekvienam darbuotojui pareiginį atlyginimą pagal pareigas | D8: vlookup()
A9: 5 | B9: Valandinis tarifinis atlygis, € | C9: Apskaičiuokite iš pareiginio atlyginimo imdami vidutinį mėnesio darbo dienų skaičių 22
A10: 6 | B10: Avansas, € | C10: Avansą parinkite atsitiktiniu būdu 150 arba 200 eurų | D10: choose()
A11: 7 | B11: Asmens kodas | C11: nepildyti
A12: 8 | B12: Tel. Nr. | C12: sujunkite "+370 6" ir 7 atsitiktiniai skaičiai | D12: concatenate()
A13: 9 | B13: Adresas | C13: sugalvokite patys
A16: Darbalapis "Darbo užmokestis"
B17: Stulpelio pavadinimas | C17: Užduotis
A18: 1 | B18: A5 | C18: Įrašykite kovo mėnesį
A19: 2 | B19: Registras | C19: Darbo užmokestis
A20: 3 | B20: Op. Nr. | C20: tarkime, kad darote registrą kovo mėnesiui, tada rašykite visur 03
A21: 4 | B21: Skaičiavimo data | C21: Pasirinkite šių metų kovo datą formatas: 2022/kov/31 | D21: eomonth()
A22: 5 | B22: Pavardė, vardas | C22: nukopijuokite darbuotojus iš darbuotojų lapo
A23: 6 | B23: Pareiginis atlyginimas, € | C23: Parinkite kiekvienam darbuotojui pareiginį atlyginimą iš darbuotojų lapo | D23: vlookup()
A24: 7 | B24: Valandinis tarifinis atlygis, € | C24: Parinkite kiekvienam darbuotojui pareiginį valandinį atlyginimą iš darbuotojų lapo | D24: vlookup()
A25: 8 | B25: Nustatytas darbo dienų skaičius | C25: apskaičiuokite darbo dienų skaičių su funkcija Networkdays(). Nepamirškite švenčių dienų.
A26: 9 | B26: Faktiškai dirbta, d. | C26: parinkite atsitiktiniu būdu nuo 15 iki mėnesio darbo dienų skaičiaus | D26: randbetween()
A27: 10 | B27: Faktiškai dirbta, val. | C27: dienos * 8 val.
A28: 11 | B28: Atlyginimas, € | C28: atlyginimas priskaičiuotas už dirbtas dienas | D28: atlyginimas*fakt.dirbtų d./d.d.skaičius
A29: 12 | B29: Mėnesinė priemoka, € | C29: Skirkite mėnesinę priemoką 50 eurų, jei dirbo visas darbo dienas | D29: IF
A30: 13 | B30: Eilinės atostogos, € | C30: Jei darbuotojas nedirbo daugiau nei 4 dienas, tada jis tas dienas buvo atostogose. Paskaičiuokite už tas dienas atostoginius | D30: IF
A31: 14 | B31: Kompensacija už nepanaudotas atostogas, € | C31: 0
A32: 15 | B32: Nedarbingumo pašalpa darbdavio lėšomis, € | C32: Jei darbuotojas nedirbo 4 ar mažiau dienų, tada jis sirgo. Paskaičiuokite už tas 1-2 dienas darbdavio mokamą atlyginimą | D32: IF
A33: 16 | B33: Priskaičiuota iš viso, € | C33: Visos priskaičiuotos sumos
A34: 17 | B34: pritaikytas NPD, € | C34: paskaičiuokite pagal dešinėje duotas formules | H34: Neapmokestinamo minimumo skaičiavimas:
A35: 18 | B35: GPM, € | C35: GMP=(Priskaičiuota - NPD)*20% | D35: koeficientams suteikite vardus | G35: 1) | H35: NPD max - 460 Eur. Taikomas pajamoms iki 730 Eur.
A36: 19 | B36: VSD ir PSD įmokos, € | C36: 14,29% nuo priskaičiuoto atlygio atėmus nedarbingumo pašalpos sumą, PSD - 6,98% | G36: 2) | H36: NPD = 460 – 0,26* (gyventojo mėnesio su darbo santykiais arba jų esmę atitinkančiais santykiais susijusios pajamos – 730) | R36: jei Du<1678
A37: 20 | B37: Papildomas pensijinis kaupimas | C37: 3% nuo priskaičiuoto atlygio | G37: 3) | H37: NPD = 400 – 0,18* (gyventojo mėnesio su darbo santykiais arba jų esmę atitinkančiais santykiais susijusios pajamos – 642) | R37: jei Du>1678
A38: 21 | B38: Išskaičiuota iš viso, € | C38: visa išskaičiuota suma mokesčiams | G38: 4) | H38: Jei neigiamas tai rašome 0
A39: 22 | B39: Išmokėtina suma, € | C39: Išmokama = priskaičiuota - išskaičiuota
A40: 23 | B40: Darbdavio VSD įmokos, € | C40: VSD (1,77%) * priskaičiuota
A41: 24 | B41: Avansas, € | C41: Parinkite iš darbuotojų lapo | D41: vlookup()
A42: 25 | B42: Išmokėtina suma po avanso, € | C42: Išmokama suma atėmus avansą
A43: 26 | B43: Garantinis fondas | C43: 0,2% nuo visiems darbuotojams priskaičiuotų atlyginimų
...

Sheet Pareigybės
A3: Eil. Nr. | B3: Pareigybė | C3: Pareiginis atlyginimas, € | D3: Darbuotojų skaičius
A4: 1 | B4: Vadovas | C4: 2800 | D4: 1
A5: 2 | B5: Buhalterė | C5: 1600 | D5: 2
A6: 3 | B6: Administratorė | C6: 1505 | D6: 1
A7: 4 | B7: Vadybininkas | C7: 1199 | D7: 2
A8: 5 | B8: Sandėlininkas | C8: 1090 | D8: 2
A9: 6 | B9: Gamybos darbuotojas | C9: 980 | D9: 7

Sheet Darbuotojai
A1: Darbuotojai
E2: Tarkim, kad per dieną dirba 8 val.
A5: Eil. Nr. | B5: Pavardė, vardas | C5: Pareigos | D5: Pareiginis atlyginimas, € | E5: Valandinis tarifinis atlygis, € | F5: Avansas, € | G5: Asmens kodas | H5: Tel. Nr. | I5: Adresas
A6: 1. | B6: Darbuotojas1 | C6: =Pareigybės!B4 -> Vadovas | D6: =VLOOKUP(C6,Pareigybės!$B$4:$C$9,2,FALSE) -> 2800 | E6: =D6/(22*8) -> 15.909091 | F6: =CHOOSE(RANDBETWEEN(1,2),150,200) -> 150 | G6: x | H6: =CONCATENATE("+",3706,RANDBETWEEN(1000000,9999999)) -> +37063484021 | I6: Jaunystės 1
A7: 2. | B7: Darbuotojas2 | C7: =Pareigybės!B5 -> Buhalterė | D7: =VLOOKUP(C7,Pareigybės!$B$4:$C$9,2,FALSE) -> 1600 | E7: =D7/(22*8) -> 9.0909091 | F7: =CHOOSE(RANDBETWEEN(1,2),150,200) -> 200 | G7: x | H7: =CONCATENATE("+",3706,RANDBETWEEN(1000000,9999999)) -> +37068740130 | I7: Jaunystės 2
A8: 3. | B8: Darbuotojas3 | C8: =Pareigybės!B5 -> Buhalterė | D8: =VLOOKUP(C8,Pareigybės!$B$4:$C$9,2,FALSE) -> 1600 | E8: =D8/(22*8) -> 9.0909091 | F8: =CHOOSE(RANDBETWEEN(1,2),150,200) -> 150 | G8: x | H8: =CONCATENATE("+",3706,RANDBETWEEN(1000000,9999999)) -> +37064256368 | I8: Jaunystės 3
A9: 4. | B9: Darbuotojas4 | C9: =Pareigybės!B6 -> Administratorė | D9: =VLOOKUP(C9,Pareigybės!$B$4:$C$9,2,FALSE) -> 1505 | E9: =D9/(22*8) -> 8.5511364 | F9: =CHOOSE(RANDBETWEEN(1,2),150,200) -> 150 | G9: x | H9: =CONCATENATE("+",3706,RANDBETWEEN(1000000,9999999)) -> +37063316052 | I9: Jaunystės 4
A10: 5. | B10: Darbuotojas5 | C10: =Pareigybės!B7 -> Vadybininkas | D10: =VLOOKUP(C10,Pareigybės!$B$4:$C$9,2,FALSE) -> 1199 | E10: =D10/(22*8) -> 6.8125 | F10: =CHOOSE(RANDBETWEEN(1,2),150,200) -> 200 | G10: x | H10: =CONCATENATE("+",3706,RANDBETWEEN(1000000,9999999)) -> +37062538299 | I10: Jaunystės 5
A11: 6. | B11: Darbuotojas6 | C11: =Pareigybės!B7 -> Vadybininkas | D11: =VLOOKUP(C11,Pareigybės!$B$4:$C$9,2,FALSE) -> 1199 | E11: =D11/(22*8) -> 6.8125 | F11: =CHOOSE(RANDBETWEEN(1,2),150,200) -> 150 | G11: x | H11: =CONCATENATE("+",3706,RANDBETWEEN(1000000,9999999)) -> +37067910065 | I11: Jaunystės 6
A12: 7. | B12: Darbuotojas7 | C12: =Pareigybės!B8 -> Sandėlininkas | D12: =VLOOKUP(C12,Pareigybės!$B$4:$C$9,2,FALSE) -> 1090 | E12: =D12/(22*8) -> 6.1931818 | F12: =CHOOSE(RANDBETWEEN(1,2),150,200) -> 150 | G12: x | H12: =CONCATENATE("+",3706,RANDBETWEEN(1000000,9999999)) -> +37063919075 | I12: Jaunystės 7
A13: 8. | B13: Darbuotojas8 | C13: =Pareigybės!B8 -> Sandėlininkas | D13: =VLOOKUP(C13,Pareigybės!$B$4:$C$9,2,FALSE) -> 1090 | E13: =D13/(22*8) -> 6.1931818 | F13: =CHOOSE(RANDBETWEEN(1,2),150,200) -> 200 | G13: x | H13: =CONCATENATE("+",3706,RANDBETWEEN(1000000,9999999)) -> +37065567225 | I13: Jaunystės 8
A14: 9. | B14: Darbuotojas9 | C14: =Pareigybės!B9 -> Gamybos darbuotojas | D14: =VLOOKUP(C14,Pareigybės!$B$4:$C$9,2,FALSE) -> 980 | E14: =D14/(22*8) -> 5.5681818 | F14: =CHOOSE(RANDBETWEEN(1,2),150,200) -> 150 | G14: x | H14: =CONCATENATE("+",3706,RANDBETWEEN(1000000,9999999)) -> +37065022650 | I14: Jaunystės 9
A15: 10. | B15: Darbuotojas10 | C15: =Pareigybės!B9 -> Gamybos darbuotojas | D15: =VLOOKUP(C15,Pareigybės!$B$4:$C$9,2,FALSE) -> 980 | E15: =D15/(22*8) -> 5.5681818 | F15: =CHOOSE(RANDBETWEEN(1,2),150,200) -> 200 | G15: x | H15: =CONCATENATE("+",3706,RANDBETWEEN(1000000,9999999)) -> +37069543141 | I15: Jaunystės 10
A16: 11. | B16: Darbuotojas11 | C16: =Pareigybės!B9 -> Gamybos darbuotojas | D16: =VLOOKUP(C16,Pareigybės!$B$4:$C$9,2,FALSE) -> 980 | E16: =D16/(22*8) -> 5.5681818 | F16: =CHOOSE(RANDBETWEEN(1,2),150,200) -> 200 | G16: x | H16: =CONCATENATE("+",3706,RANDBETWEEN(1000000,9999999)) -> +37062238819 | I16: Jaunystės 11
A17: 12. | B17: Darbuotojas12 | C17: =Pareigybės!B9 -> Gamybos darbuotojas | D17: =VLOOKUP(C17,Pareigybės!$B$4:$C$9,2,FALSE) -> 980 | E17: =D17/(22*8) -> 5.5681818 | F17: =CHOOSE(RANDBETWEEN(1,2),150,200) -> 200 | G17: x | H17: =CONCATENATE("+",3706,RANDBETWEEN(1000000,9999999)) -> +37063308466 | I17: Jaunystės 12
A18: 13. | B18: Darbuotojas13 | C18: =Pareigybės!B9 -> Gamybos darbuotojas | D18: =VLOOKUP(C18,Pareigybės!$B$4:$C$9,2,FALSE) -> 980 | E18: =D18/(22*8) -> 5.5681818 | F18: =CHOOSE(RANDBETWEEN(1,2),150,200) -> 150 | G18: x | H18: =CONCATENATE("+",3706,RANDBETWEEN(1000000,9999999)) -> +37065602713 | I18: Jaunystės 13
A19: 14. | B19: Darbuotojas14 | C19: =Pareigybės!B9 -> Gamybos darbuotojas | D19: =VLOOKUP(C19,Pareigybės!$B$4:$C$9,2,FALSE) -> 980 | E19: =D19/(22*8) -> 5.5681818 | F19: =CHOOSE(RANDBETWEEN(1,2),150,200) -> 200 | G19: x | H19: =CONCATENATE("+",3706,RANDBETWEEN(1000000,9999999)) -> +37067237027 | I19: Jaunystės 14
A20: 15. | B20: Darbuotojas15 | C20: =Pareigybės!B9 -> Gamybos darbuotojas | D20: =VLOOKUP(C20,Pareigybės!$B$4:$C$9,2,FALSE) -> 980 | E20: =D20/(22*8) -> 5.5681818 | F20: =CHOOSE(RANDBETWEEN(1,2),150,200) -> 150 | G20: x | H20: =CONCATENATE("+",3706,RANDBETWEEN(1000000,9999999)) -> +37067369004 | I20: Jaunystės 15

Sheet Darbo užmokestis
A1: UAB "Jaunystė" | F1: GPM1 | G1: 0.2 | J1: Garantinis fondas | L1: 0.002 | N1: Ilgalaikio darbo išmokų fondo įmoka | R1: 0.0016 | S1: =J7*R1 -> 26.399086
A2: Įmonės kodas 1222555888 | F2: GPM2 | G2: 0.27 | J2: Įmoka | L2: =O7*$L$1 -> 37.863857 | N2: Soc. draudimo įmokos nelaimingų atsitikimų draudimui | R2: 0.0014 | S2: =J7*R2 -> 23.0992
A3: Darbo užmokesčio registras | F3: VSD darbuotojo | G3: 0.1429
F4: PSD | G4: 0.0698
A5: Kovas | F5: VSD darbdavio | G5: 0.0177
F6: Papildomas pensijinis kaupimas | G6: 0.03
A7: mėnuo | F7: Nedarbingumo pašalpa | G7: 0.65 | I7: Iš viso: | J7: =SUM(J10:J24) -> 16499.429 | K7: =SUM(K10:K24) -> 100 | L7: =SUM(L10:L24) -> 1550.6364 | M7: =SUM(M10:M24) -> 0 | N7: =SUM(N10:N24) -> 781.86364 | O7: =SUM(O10:O24) -> 18931.929 | P7: =SUM(P10:P24) -> 2244.1228 | Q7: =SUM(Q10:Q24) -> 3337.5612 | ... Y7: =SUM(Y10:Y24) -> 12035.152
A9: Registras | B9: Op. Nr. | C9: Skaičiavimo data | D9: Pavardė, vardas | E9: Pareiginis atlyginimas, € | F9: Valandinis tarifinis atlygis, € | G9: Nustatytas darbo dienų skaičius | H9: Faktiškai dirbta, d. | I9: Faktiškai dirbta, val. | J9: Atlyginimas, € | K9: Mėnesinė priemoka, € | L9: Eilinės atostogos, € | M9: Kompensacija už nepanaudotas atostogas, € | N9: Nedarbingumo pašalpa darbdavio lėšomis, € | O9: Priskaičiuota iš viso, € | P9: pritaikytas NPD, € | Q9: GPM, € | R9: VSD įmoka, € | S9: PSD įmoka, € | T9: Papildomas pensijinis kaupimas | U9: Išskaičiuota iš viso, € | V9: Išmokėtina suma, € | W9: Darbdavio VSD įmokos, € | X9: Avansas, € | Y9: Išmokėtina suma po avanso, €
A10: darbo užmokestis | B10: ="03" -> 03 | C10: =EOMONTH(DATE(2022,3,1),0) -> 44651 | D10: =Darbuotojai!B6 -> Darbuotojas1 | E10: =VLOOKUP(D10,Darbuotojai!$B$6:$D$20,3,FALSE) -> 2800 | F10: =VLOOKUP(D10,Darbuotojai!$B$6:$E$20,4,FALSE) -> 15.909091 | G10: =NETWORKDAYS(DATE(2026,3,1),DATE(2026,3,31),DATE(2026,3,11)) -> 21 | H10: =RANDBETWEEN(15,G10) -> 20 | I10: 8 | J10: =E10*'Darbo užmokestis'!H10/'Darbo užmokestis'!G10 -> 2666.6667 | K10: =IF(G10=H10,50,0) -> 0 | L10: =IF(G10-H10>4,F10*I10*(G10-H10),0) -> 0 | M10: 0 | N10: =IF(G10-H10<=4,F10*I10*(G10-H10),0) -> 127.27273 | O10: =SUM(J10:N10) -> 2793.9394 | P10: =IF(IF(O10<=730,460,IF(O10<1678,460-0.26*O10,IF(O10>1678,460-0.18*O10)))>0,IF(O10<=730,460,IF(O10<1678,460-0.26*O10,IF(O10>1678,460-0.18*O10))),0) -> 0 | Q10: =(O10-P10)*20% -> 558.78788 | R10: =(O10-N10)*14.29% -> 381.06667 | S10: =O10*6.98% -> 195.01697 | T10: =O10*3% -> 83.818182 | U10: =SUM(P10:S10) -> 1134.8715 | V10: =O10-U10 -> 1659.0679 | W10: =O10*1.77% -> 49.452727 | X10: =VLOOKUP(D10,Darbuotojai!B6:F20,5,FALSE) -> 150 | Y10: =V10+X10 -> 1809.0679
A11: darbo užmokestis | B11: ="03" -> 03 | C11: =EOMONTH(DATE(2022,3,1),0) -> 44651 | D11: =Darbuotojai!B7 -> Darbuotojas2 | E11: =VLOOKUP(D11,Darbuotojai!$B$6:$D$20,3,FALSE) -> 1600 | F11: =VLOOKUP(D11,Darbuotojai!$B$6:$E$20,4,FALSE) -> 9.0909091 | G11: =NETWORKDAYS(DATE(2026,3,1),DATE(2026,3,31),DATE(2026,3,11)) -> 21 | H11: =RANDBETWEEN(15,G11) -> 15 | I11: 8 | J11: =E11*'Darbo užmokestis'!H11/'Darbo užmokestis'!G11 -> 1142.8571 | K11: =IF(G11=H11,50,0) -> 0 | L11: =IF(G11-H11>4,F11*I11*(G11-H11),0) -> 436.36364 | M11: 0 | N11: =IF(G11-H11<=4,F11*I11*(G11-H11),0) -> 0 | O11: =SUM(J11:N11) -> 1579.2208 | P11: =IF(IF(O11<=730,460,IF(O11<1678,460-0.26*O11,IF(O11>1678,460-0.18*O11)))>0,IF(O11<=730,460,IF(O11<1678,460-0.26*O11,IF(O11>1678,460-0.18*O11))),0) -> 49.402597 | Q11: =(O11-P11)*20% -> 305.96364 | R11: =(O11-N11)*14.29% -> 225.67065 | S11: =O11*6.98% -> 110.22961 | T11: =O11*3% -> 47.376623 | U11: =SUM(P11:S11) -> 691.26649 | V11: =O11-U11 -> 887.95429 | W11: =O11*1.77% -> 27.952208 | X11: =VLOOKUP(D11,Darbuotojai!B7:F21,5,FALSE) -> 200 | Y11: =V11+X11 -> 1087.9543
A12: darbo užmokestis | B12: ="03" -> 03 | C12: =EOMONTH(DATE(2022,3,1),0) -> 44651 | D12: =Darbuotojai!B8 -> Darbuotojas3 | E12: =VLOOKUP(D12,Darbuotojai!$B$6:$D$20,3,FALSE) -> 1600 | F12: =VLOOKUP(D12,Darbuotojai!$B$6:$E$20,4,FALSE) -> 9.0909091 | G12: =NETWORKDAYS(DATE(2026,3,1),DATE(2026,3,31),DATE(2026,3,11)) -> 21 | H12: =RANDBETWEEN(15,G12) -> 19 | I12: 8 | J12: =E12*'Darbo užmokestis'!H12/'Darbo užmokestis'!G12 -> 1447.619 | K12: =IF(G12=H12,50,0) -> 0 | L12: =IF(G12-H12>4,F12*I12*(G12-H12),0) -> 0 | M12: 0 | N12: =IF(G12-H12<=4,F12*I12*(G12-H12),0) -> 145.45455 | O12: =SUM(J12:N12) -> 1593.0736 | P12: =IF(IF(O12<=730,460,IF(O12<1678,460-0.26*O12,IF(O12>1678,460-0.18*O12)))>0,IF(O12<=730,460,IF(O12<1678,460-0.26*O12,IF(O12>1678,460-0.18*O12))),0) -> 45.800866 | Q12: =(O12-P12)*20% -> 309.45455 | R12: =(O12-N12)*14.29% -> 206.86476 | S12: =O12*6.98% -> 111.19654 | T12: =O12*3% -> 47.792208 | U12: =SUM(P12:S12) -> 673.31671 | V12: =O12-U12 -> 919.75688 | W12: =O12*1.77% -> 28.197403 | X12: =VLOOKUP(D12,Darbuotojai!B8:F22,5,FALSE) -> 150 | Y12: =V12+X12 -> 1069.7569
A13: darbo užmokestis | B13: ="03" -> 03 | C13: =EOMONTH(DATE(2022,3,1),0) -> 44651 | D13: =Darbuotojai!B9 -> Darbuotojas4 | E13: =VLOOKUP(D13,Darbuotojai!$B$6:$D$20,3,FALSE) -> 1505 | F13: =VLOOKUP(D13,Darbuotojai!$B$6:$E$20,4,FALSE) -> 8.5511364 | G13: =NETWORKDAYS(DATE(2026,3,1),DATE(2026,3,31),DATE(2026,3,11)) -> 21 | H13: =RANDBETWEEN(15,G13) -> 20 | I13: 8 | J13: =E13*'Darbo užmokestis'!H13/'Darbo užmokestis'!G13 -> 1433.3333 | K13: =IF(G13=H13,50,0) -> 0 | L13: =IF(G13-H13>4,F13*I13*(G13-H13),0) -> 0 | M13: 0 | N13: =IF(G13-H13<=4,F13*I13*(G13-H13),0) -> 68.409091 | O13: =SUM(J13:N13) -> 1501.7424 | P13: =IF(IF(O13<=730,460,IF(O13<1678,460-0.26*O13,IF(O13>1678,460-0.18*O13)))>0,IF(O13<=730,460,IF(O13<1678,460-0.26*O13,IF(O13>1678,460-0.18*O13))),0) -> 69.54697 | Q13: =(O13-P13)*20% -> 286.43909 | R13: =(O13-N13)*14.29% -> 204.82333 | S13: =O13*6.98% -> 104.82162 | T13: =O13*3% -> 45.052273 | U13: =SUM(P13:S13) -> 665.63102 | V13: =O13-U13 -> 836.11141 | W13: =O13*1.77% -> 26.580841 | X13: =VLOOKUP(D13,Darbuotojai!B9:F23,5,FALSE) -> 150 | Y13: =V13+X13 -> 986.11141
A14: darbo užmokestis | B14: ="03" -> 03 | C14: =EOMONTH(DATE(2022,3,1),0) -> 44651 | D14: =Darbuotojai!B10 -> Darbuotojas5 | E14: =VLOOKUP(D14,Darbuotojai!$B$6:$D$20,3,FALSE) -> 1199 | F14: =VLOOKUP(D14,Darbuotojai!$B$6:$E$20,4,FALSE) -> 6.8125 | G14: =NETWORKDAYS(DATE(2026,3,1),DATE(2026,3,31),DATE(2026,3,11)) -> 21 | H14: =RANDBETWEEN(15,G14) -> 15 | I14: 8 | J14: =E14*'Darbo užmokestis'!H14/'Darbo užmokestis'!G14 -> 856.42857 | K14: =IF(G14=H14,50,0) -> 0 | L14: =IF(G14-H14>4,F14*I14*(G14-H14),0) -> 327 | M14: 0 | N14: =IF(G14-H14<=4,F14*I14*(G14-H14),0) -> 0 | O14: =SUM(J14:N14) -> 1183.4286 | P14: =IF(IF(O14<=730,460,IF(O14<1678,460-0.26*O14,IF(O14>1678,460-0.18*O14)))>0,IF(O14<=730,460,IF(O14<1678,460-0.26*O14,IF(O14>1678,460-0.18*O14))),0) -> 152.30857 | Q14: =(O14-P14)*20% -> 206.224 | R14: =(O14-N14)*14.29% -> 169.11194 | S14: =O14*6.98% -> 82.603314 | T14: =O14*3% -> 35.502857 | U14: =SUM(P14:S14) -> 610.24783 | V14: =O14-U14 -> 573.18074 | W14: =O14*1.77% -> 20.946686 | X14: =VLOOKUP(D14,Darbuotojai!B10:F24,5,FALSE) -> 200 | Y14: =V14+X14 -> 773.18074
A15: darbo užmokestis | B15: ="03" -> 03 | C15: =EOMONTH(DATE(2022,3,1),0) -> 44651 | D15: =Darbuotojai!B11 -> Darbuotojas6 | E15: =VLOOKUP(D15,Darbuotojai!$B$6:$D$20,3,FALSE) -> 1199 | F15: =VLOOKUP(D15,Darbuotojai!$B$6:$E$20,4,FALSE) -> 6.8125 | G15: =NETWORKDAYS(DATE(2026,3,1),DATE(2026,3,31),DATE(2026,3,11)) -> 21 | H15: =RANDBETWEEN(15,G15) -> 17 | I15: 8 | J15: =E15*'Darbo užmokestis'!H15/'Darbo užmokestis'!G15 -> 970.61905 | K15: =IF(G15=H15,50,0) -> 0 | L15: =IF(G15-H15>4,F15*I15*(G15-H15),0) -> 0 | M15: 0 | N15: =IF(G15-H15<=4,F15*I15*(G15-H15),0) -> 218 | O15: =SUM(J15:N15) -> 1188.619 | P15: =IF(IF(O15<=730,460,IF(O15<1678,460-0.26*O15,IF(O15>1678,460-0.18*O15)))>0,IF(O15<=730,460,IF(O15<1678,460-0.26*O15,IF(O15>1678,460-0.18*O15))),0) -> 150.95905 | Q15: =(O15-P15)*20% -> 207.532 | R15: =(O15-N15)*14.29% -> 138.70146 | S15: =O15*6.98% -> 82.96561 | T15: =O15*3% -> 35.658571 | U15: =SUM(P15:S15) -> 580.15812 | V15: =O15-U15 -> 608.46093 | W15: =O15*1.77% -> 21.038557 | X15: =VLOOKUP(D15,Darbuotojai!B11:F25,5,FALSE) -> 150 | Y15: =V15+X15 -> 758.46093
A16: darbo užmokestis | B16: ="03" -> 03 | C16: =EOMONTH(DATE(2022,3,1),0) -> 44651 | D16: =Darbuotojai!B12 -> Darbuotojas7 | E16: =VLOOKUP(D16,Darbuotojai!$B$6:$D$20,3,FALSE) -> 1090 | F16: =VLOOKUP(D16,Darbuotojai!$B$6:$E$20,4,FALSE) -> 6.1931818 | G16: =NETWORKDAYS(DATE(2026,3,1),DATE(2026,3,31),DATE(2026,3,11)) -> 21 | H16: =RANDBETWEEN(15,G16) -> 15 | I16: 8 | J16: =E16*'Darbo užmokestis'!H16/'Darbo užmokestis'!G16 -> 778.57143 | K16: =IF(G16=H16,50,0) -> 0 | L16: =IF(G16-H16>4,F16*I16*(G16-H16),0) -> 297.27273 | M16: 0 | N16: =IF(G16-H16<=4,F16*I16*(G16-H16),0) -> 0 | O16: =SUM(J16:N16) -> 1075.8442 | P16: =IF(IF(O16<=730,460,IF(O16<1678,460-0.26*O16,IF(O16>1678,460-0.18*O16)))>0,IF(O16<=730,460,IF(O16<1678,460-0.26*O16,IF(O16>1678,460-0.18*O16))),0) -> 180.28052 | Q16: =(O16-P16)*20% -> 179.11273 | R16: =(O16-N16)*14.29% -> 153.73813 | S16: =O16*6.98% -> 75.093922 | T16: =O16*3% -> 32.275325 | U16: =SUM(P16:S16) -> 588.2253 | V16: =O16-U16 -> 487.61886 | W16: =O16*1.77% -> 19.042442 | X16: =VLOOKUP(D16,Darbuotojai!B12:F26,5,FALSE) -> 150 | Y16: =V16+X16 -> 637.61886
A17: darbo užmokestis | B17: ="03" -> 03 | C17: =EOMONTH(DATE(2022,3,1),0) -> 44651 | D17: =Darbuotojai!B13 -> Darbuotojas8 | E17: =VLOOKUP(D17,Darbuotojai!$B$6:$D$20,3,FALSE) -> 1090 | F17: =VLOOKUP(D17,Darbuotojai!$B$6:$E$20,4,FALSE) -> 6.1931818 | G17: =NETWORKDAYS(DATE(2026,3,1),DATE(2026,3,31),DATE(2026,3,11)) -> 21 | H17: =RANDBETWEEN(15,G17) -> 21 | I17: 8 | J17: =E17*'Darbo užmokestis'!H17/'Darbo užmokestis'!G17 -> 1090 | K17: =IF(G17=H17,50,0) -> 50 | L17: =IF(G17-H17>4,F17*I17*(G17-H17),0) -> 0 | M17: 0 | N17: =IF(G17-H17<=4,F17*I17*(G17-H17),0) -> 0 | O17: =SUM(J17:N17) -> 1140 | P17: =IF(IF(O17<=730,460,IF(O17<1678,460-0.26*O17,IF(O17>1678,460-0.18*O17)))>0,IF(O17<=730,460,IF(O17<1678,460-0.26*O17,IF(O17>1678,460-0.18*O17))),0) -> 163.6 | Q17: =(O17-P17)*20% -> 195.28 | R17: =(O17-N17)*14.29% -> 162.906 | S17: =O17*6.98% -> 79.572 | T17: =O17*3% -> 34.2 | U17: =SUM(P17:S17) -> 601.358 | V17: =O17-U17 -> 538.642 | W17: =O17*1.77% -> 20.178 | X17: =VLOOKUP(D17,Darbuotojai!B13:F27,5,FALSE) -> 200 | Y17: =V17+X17 -> 738.642
A18: darbo užmokestis | B18: ="03" -> 03 | C18: =EOMONTH(DATE(2022,3,1),0) -> 44651 | D18: =Darbuotojai!B14 -> Darbuotojas9 | E18: =VLOOKUP(D18,Darbuotojai!$B$6:$D$20,3,FALSE) -> 980 | F18: =VLOOKUP(D18,Darbuotojai!$B$6:$E$20,4,FALSE) -> 5.5681818 | G18: =NETWORKDAYS(DATE(2026,3,1),DATE(2026,3,31),DATE(2026,3,11)) -> 21 | H18: =RANDBETWEEN(15,G18) -> 20 | I18: 8 | J18: =E18*'Darbo užmokestis'!H18/'Darbo užmokestis'!G18 -> 933.33333 | K18: =IF(G18=H18,50,0) -> 0 | L18: =IF(G18-H18>4,F18*I18*(G18-H18),0) -> 0 | M18: 0 | N18: =IF(G18-H18<=4,F18*I18*(G18-H18),0) -> 44.545455 | O18: =SUM(J18:N18) -> 977.87879 | P18: =IF(IF(O18<=730,460,IF(O18<1678,460-0.26*O18,IF(O18>1678,460-0.18*O18)))>0,IF(O18<=730,460,IF(O18<1678,460-0.26*O18,IF(O18>1678,460-0.18*O18))),0) -> 205.75152 | Q18: =(O18-P18)*20% -> 154.42545 | R18: =(O18-N18)*14.29% -> 133.37333 | S18: =O18*6.98% -> 68.255939 | T18: =O18*3% -> 29.336364 | U18: =SUM(P18:S18) -> 561.80624 | V18: =O18-U18 -> 416.07255 | W18: =O18*1.77% -> 17.308455 | X18: =VLOOKUP(D18,Darbuotojai!B14:F28,5,FALSE) -> 150 | Y18: =V18+X18 -> 566.07255
A19: darbo užmokestis | B19: ="03" -> 03 | C19: =EOMONTH(DATE(2022,3,1),0) -> 44651 | D19: =Darbuotojai!B15 -> Darbuotojas10 | E19: =VLOOKUP(D19,Darbuotojai!$B$6:$D$20,3,FALSE) -> 980 | F19: =VLOOKUP(D19,Darbuotojai!$B$6:$E$20,4,FALSE) -> 5.5681818 | G19: =NETWORKDAYS(DATE(2026,3,1),DATE(2026,3,31),DATE(2026,3,11)) -> 21 | H19: =RANDBETWEEN(15,G19) -> 20 | I19: 8 | J19: =E19*'Darbo užmokestis'!H19/'Darbo užmokestis'!G19 -> 933.33333 | K19: =IF(G19=H19,50,0) -> 0 | L19: =IF(G19-H19>4,F19*I19*(G19-H19),0) -> 0 | M19: 0 | N19: =IF(G19-H19<=4,F19*I19*(G19-H19),0) -> 44.545455 | O19: =SUM(J19:N19) -> 977.87879 | P19: =IF(IF(O19<=730,460,IF(O19<1678,460-0.26*O19,IF(O19>1678,460-0.18*O19)))>0,IF(O19<=730,460,IF(O19<1678,460-0.26*O19,IF(O19>1678,460-0.18*O19))),0) -> 205.75152 | Q19: =(O19-P19)*20% -> 154.42545 | R19: =(O19-N19)*14.29% -> 133.37333 | S19: =O19*6.98% -> 68.255939 | T19: =O19*3% -> 29.336364 | U19: =SUM(P19:S19) -> 561.80624 | V19: =O19-U19 -> 416.07255 | W19: =O19*1.77% -> 17.308455 | X19: =VLOOKUP(D19,Darbuotojai!B15:F29,5,FALSE) -> 200 | Y19: =V19+X19 -> 616.07255
A20: darbo užmokestis | B20: ="03" -> 03 | C20: =EOMONTH(DATE(2022,3,1),0) -> 44651 | D20: =Darbuotojai!B16 -> Darbuotojas11 | E20: =VLOOKUP(D20,Darbuotojai!$B$6:$D$20,3,FALSE) -> 980 | F20: =VLOOKUP(D20,Darbuotojai!$B$6:$E$20,4,FALSE) -> 5.5681818 | G20: =NETWORKDAYS(DATE(2026,3,1),DATE(2026,3,31),DATE(2026,3,11)) -> 21 | H20: =RANDBETWEEN(15,G20) -> 19 | I20: 8 | J20: =E20*'Darbo užmokestis'!H20/'Darbo užmokestis'!G20 -> 886.66667 | K20: =IF(G20=H20,50,0) -> 0 | L20: =IF(G20-H20>4,F20*I20*(G20-H20),0) -> 0 | M20: 0 | N20: =IF(G20-H20<=4,F20*I20*(G20-H20),0) -> 89.090909 | O20: =SUM(J20:N20) -> 975.75758 | P20: =IF(IF(O20<=730,460,IF(O20<1678,460-0.26*O20,IF(O20>1678,460-0.18*O20)))>0,IF(O20<=730,460,IF(O20<1678,460-0.26*O20,IF(O20>1678,460-0.18*O20))),0) -> 206.30303 | Q20: =(O20-P20)*20% -> 153.89091 | R20: =(O20-N20)*14.29% -> 126.70467 | S20: =O20*6.98% -> 68.107879 | T20: =O20*3% -> 29.272727 | U20: =SUM(P20:S20) -> 555.00648 | V20: =O20-U20 -> 420.75109 | W20: =O20*1.77% -> 17.270909 | X20: =VLOOKUP(D20,Darbuotojai!B16:F30,5,FALSE) -> 200 | Y20: =V20+X20 -> 620.75109
A21: darbo užmokestis | B21: ="03" -> 03 | C21: =EOMONTH(DATE(2022,3,1),0) -> 44651 | D21: =Darbuotojai!B17 -> Darbuotojas12 | E21: =VLOOKUP(D21,Darbuotojai!$B$6:$D$20,3,FALSE) -> 980 | F21: =VLOOKUP(D21,Darbuotojai!$B$6:$E$20,4,FALSE) -> 5.5681818 | G21: =NETWORKDAYS(DATE(2026,3,1),DATE(2026,3,31),DATE(2026,3,11)) -> 21 | H21: =RANDBETWEEN(15,G21) -> 20 | I21: 8 | J21: =E21*'Darbo užmokestis'!H21/'Darbo užmokestis'!G21 -> 933.33333 | K21: =IF(G21=H21,50,0) -> 0 | L21: =IF(G21-H21>4,F21*I21*(G21-H21),0) -> 0 | M21: 0 | N21: =IF(G21-H21<=4,F21*I21*(G21-H21),0) -> 44.545455 | O21: =SUM(J21:N21) -> 977.87879 | P21: =IF(IF(O21<=730,460,IF(O21<1678,460-0.26*O21,IF(O21>1678,460-0.18*O21)))>0,IF(O21<=730,460,IF(O21<1678,460-0.26*O21,IF(O21>1678,460-0.18*O21))),0) -> 205.75152 | Q21: =(O21-P21)*20% -> 154.42545 | R21: =(O21-N21)*14.29% -> 133.37333 | S21: =O21*6.98% -> 68.255939 | T21: =O21*3% -> 29.336364 | U21: =SUM(P21:S21) -> 561.80624 | V21: =O21-U21 -> 416.07255 | W21: =O21*1.77% -> 17.308455 | X21: =VLOOKUP(D21,Darbuotojai!B17:F31,5,FALSE) -> 200 | Y21: =V21+X21 -> 616.07255
... A24: darbo užmokestis | B24: ="03" -> 03 | C24: =EOMONTH(DATE(2022,3,1),0) -> 44651 | D24: =Darbuotojai!B20 -> Darbuotojas15 | E24: =VLOOKUP(D24,Darbuotojai!$B$6:$D$20,3,FALSE) -> 980 | F24: =VLOOKUP(D24,Darbuotojai!$B$6:$E$20,4,FALSE) -> 5.5681818 | G24: =NETWORKDAYS(DATE(2026,3,1),DATE(2026,3,31),DATE(2026,3,11)) -> 21 | H24: =RANDBETWEEN(15,G24) -> 21 | I24: 8 | J24: =E24*'Darbo užmokestis'!H24/'Darbo užmokestis'!G24 -> 980 | K24: =IF(G24=H24,50,0) -> 50 | L24: =IF(G24-H24>4,F24*I24*(G24-H24),0) -> 0 | M24: 0 | N24: =IF(G24-H24<=4,F24*I24*(G24-H24),0) -> 0 | O24: =SUM(J24:N24) -> 1030 | P24: =IF(IF(O24<=730,460,IF(O24<1678,460-0.26*O24,IF(O24>1678,460-0.18*O24)))>0,IF(O24<=730,460,IF(O24<1678,460-0.26*O24,IF(O24>1678,460-0.18*O24))),0) -> 192.2 | Q24: =(O24-P24)*20% -> 167.56 | R24: =(O24-N24)*14.29% -> 147.187 | S24: =O24*6.98% -> 71.894 | T24: =O24*3% -> 30.9 | U24: =SUM(P24:S24) -> 578.841 | V24: =O24-U24 -> 451.159 | W24: =O24*1.77% -> 18.231 | X24: =VLOOKUP(D24,Darbuotojai!B20:F34,5,FALSE) -> 150 | Y24: =V24+X24 -> 601.159

Sheet suvestinė
A3: 1 | B3: Keli darbuotojai dirbo 18 ir daugiau dienų | C3: =COUNTIF('Darbo užmokestis'!H:H,">=18") -> 9
A4: 2 | B4: Darbuotojų, kurie dirbo mažiau nei 18 dienų, išmokamų atlyginimų suma | C4: =SUMIF('Darbo užmokestis'!H:H,"<18",'Darbo užmokestis'!V:V) -> 3361.4458
A5: 3 | B5: Vidutinė avanso suma | C5: =AVERAGE('Darbo užmokestis'!X:X) -> 325
A6: 4 | B6: Darbuotojų, kurių valandinis įkainis mažiau nei 8 eurai, sumokamų VSD vidurkis | C6: =AVERAGEIF('Darbo užmokestis'!F:F,"<8",'Darbo užmokestis'!R:R) -> 143.20172
A7: 5 | B7: Pritaikyto NPD mediana | C7: =MEDIAN('Darbo užmokestis'!P:P) -> 186.24026
A8: 6 | B8: 2 didžiausia GPM reikšmė | C8: =LARGE('Darbo užmokestis'!Q:Q,2) -> 558.78788
