Workbook

Sheet Pareigybės
A3: Eil. Nr. | B3: Pareigybė | C3: Pareiginis atlyginimas, € | D3: Darbuotojų skaičius
A4: 1 | B4: Vadovas | C4: 2800 | D4: 1
A5: 2 | B5: Buhalterė | C5: 1600 | D5: 2
A6: 3 | B6: Administratorė | C6: 1505 | D6: 1
A7: 4 | B7: Vadybininkas | C7: 1199 | D7: 2
A8: 5 | B8: Sandėlininkas | C8: 1090 | D8: 2
A9: 6 | B9: Gamybos darbuotojas | C9: 980 | D9: 7

Sheet Darbuotojai
A1: Darbuotojai
A5: Eil. Nr. | B5: Pavardė, vardas | C5: Pareigos | D5: Pareiginis atlyginimas, € | E5: Valandinis tarifinis atlygis, € | F5: Avansas, € | G5: Asmens kodas | H5: Tel. Nr. | I5: Adresas
A6: 1 | B6: Darbuotojas1 | C6: =Pareigybės!B4 -> Vadovas | D6: =VLOOKUP(C6,Pareigybės!$B$4:$C$9,2,FALSE) -> 2800 | E6: =D6/ (22*8) -> 15.909091 | F6: =CHOOSE(RANDBETWEEN(1,2),150,200) -> 150 | G6: x | H6: ="+3706"&RANDBETWEEN(1000000,9999999) -> +37068981836 | I6: Jaunystės 1
A7: 2 | B7: Darbuotojas2 | C7: =Pareigybės!B5 -> Buhalterė | D7: =VLOOKUP(C7,Pareigybės!$B$4:$C$9,2,FALSE) -> 1600 | E7: =D7/ (22*8) -> 9.0909091 | F7: =CHOOSE(RANDBETWEEN(1,2),150,200) -> 150 | G7: x | H7: ="+3706"&RANDBETWEEN(1000000,9999999) -> +37065051465 | I7: Jaunystės 2
A8: 3 | B8: Darbuotojas3 | C8: =Pareigybės!B5 -> Buhalterė | D8: =VLOOKUP(C8,Pareigybės!$B$4:$C$9,2,FALSE) -> 1600 | E8: =D8/ (22*8) -> 9.0909091 | F8: =CHOOSE(RANDBETWEEN(1,2),150,200) -> 150 | G8: x | H8: ="+3706"&RANDBETWEEN(1000000,9999999) -> +37069852091 | I8: Jaunystės 3
A9: 4 | B9: Darbuotojas4 | C9: =Pareigybės!B6 -> Administratorė | D9: =VLOOKUP(C9,Pareigybės!$B$4:$C$9,2,FALSE) -> 1505 | E9: =D9/ (22*8) -> 8.5511364 | F9: =CHOOSE(RANDBETWEEN(1,2),150,200) -> 200 | G9: x | H9: ="+3706"&RANDBETWEEN(1000000,9999999) -> +37068573262 | I9: Jaunystės 4
A10: 5 | B10: Darbuotojas5 | C10: =Pareigybės!B7 -> Vadybininkas | D10: =VLOOKUP(C10,Pareigybės!$B$4:$C$9,2,FALSE) -> 1199 | E10: =D10/ (22*8) -> 6.8125 | F10: =CHOOSE(RANDBETWEEN(1,2),150,200) -> 200 | G10: x | H10: ="+3706"&RANDBETWEEN(1000000,9999999) -> +37064278594 | I10: Jaunystės 5
A11: 6 | B11: Darbuotojas6 | C11: =Pareigybės!B7 -> Vadybininkas | D11: =VLOOKUP(C11,Pareigybės!$B$4:$C$9,2,FALSE) -> 1199 | E11: =D11/ (22*8) -> 6.8125 | F11: =CHOOSE(RANDBETWEEN(1,2),150,200) -> 150 | G11: x | H11: ="+3706"&RANDBETWEEN(1000000,9999999) -> +37068854295 | I11: Jaunystės 6
A12: 7 | B12: Darbuotojas7 | C12: =Pareigybės!B8 -> Sandėlininkas | D12: =VLOOKUP(C12,Pareigybės!$B$4:$C$9,2,FALSE) -> 1090 | E12: =D12/ (22*8) -> 6.1931818 | F12: =CHOOSE(RANDBETWEEN(1,2),150,200) -> 200 | G12: x | H12: ="+3706"&RANDBETWEEN(1000000,9999999) -> +37062314360 | I12: Jaunystės 7
A13: 8 | B13: Darbuotojas8 | C13: =Pareigybės!B8 -> Sandėlininkas | D13: =VLOOKUP(C13,Pareigybės!$B$4:$C$9,2,FALSE) -> 1090 | E13: =D13/ (22*8) -> 6.1931818 | F13: =CHOOSE(RANDBETWEEN(1,2),150,200) -> 150 | G13: x | H13: ="+3706"&RANDBETWEEN(1000000,9999999) -> +37069441782 | I13: Jaunystės 8
A14: 9 | B14: Darbuotojas9 | C14: =Pareigybės!B9 -> Gamybos darbuotojas | D14: =VLOOKUP(C14,Pareigybės!$B$4:$C$9,2,FALSE) -> 980 | E14: =D14/ (22*8) -> 5.5681818 | F14: =CHOOSE(RANDBETWEEN(1,2),150,200) -> 150 | G14: x | H14: ="+3706"&RANDBETWEEN(1000000,9999999) -> +37066918467 | I14: Jaunystės 9
A15: 10 | B15: Darbuotojas10 | C15: =Pareigybės!B9 -> Gamybos darbuotojas | D15: =VLOOKUP(C15,Pareigybės!$B$4:$C$9,2,FALSE) -> 980 | E15: =D15/ (22*8) -> 5.5681818 | F15: =CHOOSE(RANDBETWEEN(1,2),150,200) -> 150 | G15: x | H15: ="+3706"&RANDBETWEEN(1000000,9999999) -> +37066538368 | I15: Jaunystės 10
A16: 11 | B16: Darbuotojas11 | C16: =Pareigybės!B9 -> Gamybos darbuotojas | D16: =VLOOKUP(C16,Pareigybės!$B$4:$C$9,2,FALSE) -> 980 | E16: =D16/ (22*8) -> 5.5681818 | F16: =CHOOSE(RANDBETWEEN(1,2),150,200) -> 200 | G16: x | H16: ="+3706"&RANDBETWEEN(1000000,9999999) -> +37062311615 | I16: Jaunystės 11
A17: 12 | B17: Darbuotojas12 | C17: =Pareigybės!B9 -> Gamybos darbuotojas | D17: =VLOOKUP(C17,Pareigybės!$B$4:$C$9,2,FALSE) -> 980 | E17: =D17/ (22*8) -> 5.5681818 | F17: =CHOOSE(RANDBETWEEN(1,2),150,200) -> 150 | G17: x | H17: ="+3706"&RANDBETWEEN(1000000,9999999) -> +37064404427 | I17: Jaunystės 12
A18: 13 | B18: Darbuotojas13 | C18: =Pareigybės!B9 -> Gamybos darbuotojas | D18: =VLOOKUP(C18,Pareigybės!$B$4:$C$9,2,FALSE) -> 980 | E18: =D18/ (22*8) -> 5.5681818 | F18: =CHOOSE(RANDBETWEEN(1,2),150,200) -> 150 | G18: x | H18: ="+3706"&RANDBETWEEN(1000000,9999999) -> +37061092066 | I18: Jaunystės 13
A19: 14 | B19: Darbuotojas14 | C19: =Pareigybės!B9 -> Gamybos darbuotojas | D19: =VLOOKUP(C19,Pareigybės!$B$4:$C$9,2,FALSE) -> 980 | E19: =D19/ (22*8) -> 5.5681818 | F19: =CHOOSE(RANDBETWEEN(1,2),150,200) -> 150 | G19: x | H19: ="+3706"&RANDBETWEEN(1000000,9999999) -> +37065358029 | I19: Jaunystės 14
A20: 15 | B20: Darbuotojas15 | C20: =Pareigybės!B9 -> Gamybos darbuotojas | D20: =VLOOKUP(C20,Pareigybės!$B$4:$C$9,2,FALSE) -> 980 | E20: =D20/ (22*8) -> 5.5681818 | F20: =CHOOSE(RANDBETWEEN(1,2),150,200) -> 150 | G20: x | H20: ="+3706"&RANDBETWEEN(1000000,9999999) -> +37066841214 | I20: Jaunystės 15

Sheet Užduotis
A1: Savarankiško darbo užduotis:
A3: Darbalapis "Darbuotojai"
B4: Stulpelio pavadinimas | C4: Užduotis | D4: Pastabos
A5: 1 | B5: Eil. Nr. | C5: Sukurkite seką
A6: 2 | B6: Pavardė, vardas | C6: Sukurkite seką "Darbuotojas1" ir t.t.
A7: 3 | B7: Pareigos | C7: Sudarykite sąrašą ir parinkite vieną iš pateiktų pareigybių kiekvienam darbuotojui. Pareigybių skaičius duotas "Pareigybės" lape | D7: sąrašas
A8: 4 | B8: Pareiginis atlyginimas, € | C8: Parinkite kiekvienam darbuotojui pareiginį atlyginimą pagal pareigas | D8: vlookup()
A9: 5 | B9: Valandinis tarifinis atlygis, € | C9: Apskaičiuokite iš pareiginio atlyginimo imdami vidutinį mėnesio darbo dienų skaičių 22
A10: 6 | B10: Avansas, € | C10: Avansą parinkite atsitiktiniu būdu 150 arba 200 eurų | D10: choose()
A11: 7 | B11: Asmens kodas | C11: nepildyti
A12: 8 | B12: Tel. Nr. | C12: sujunkite "+370 6" ir 7 atsitiktiniai skaičiai | D12: concatenate()
A13: 9 | B13: Adresas | C13: sugalvokite patys
A16: Darbalapis "Darbo užmokestis"
B17: Stulpelio pavadinimas | C17: Užduotis
A18: 1 | B18: A5 | C18: Įrašykite kovo mėnesį
A19: 2 | B19: Registras | C19: Darbo užmokestis
A20: 3 | B20: Op. Nr. | C20: tarkime, kad darote registrą kovo mėnesiui, tada rašykite visur 03
A21: 4 | B21: Skaičiavimo data | C21: Pasirinkite šių metų kovo datą formatas: 2022/kov/31 | D21: eomonth()
A22: 5 | B22: Pavardė, vardas | C22: nukopijuokite darbuotojus iš darbuotojų lapo
A23: 6 | B23: Pareiginis atlyginimas, € | C23: Parinkite kiekvienam darbuotojui pareiginį atlyginimą iš darbuotojų lapo | D23: vlookup()
A24: 7 | B24: Valandinis tarifinis atlygis, € | C24: Parinkite kiekvienam darbuotojui pareiginį valandinį atlyginimą iš darbuotojų lapo | D24: vlookup()
A25: 8 | B25: Nustatytas darbo dienų skaičius | C25: apskaičiuokite darbo dienų skaičių su funkcija Networkdays(). Nepamirškite švenčių dienų.
A26: 9 | B26: Faktiškai dirbta, d. | C26: parinkite atsitiktiniu būdu nuo 15 iki mėnesio darbo dienų skaičiaus | D26: randbetween()
A27: 10 | B27: Faktiškai dirbta, val. | C27: dienos * 8 val.
A28: 11 | B28: Atlyginimas, € | C28: atlyginimas priskaičiuotas už dirbtas dienas | D28: atlyginimas*fakt.dirbtų d./d.d.skaičius
A29: 12 | B29: Mėnesinė priemoka, € | C29: Skirkite mėnesinę priemoką 50 eurų, jei dirbo visas darbo dienas | D29: IF
A30: 13 | B30: Eilinės atostogos, € | C30: Jei darbuotojas nedirbo daugiau nei 4 dienas, tada jis tas dienas buvo atostogose. Paskaičiuokite už tas dienas atostoginius | D30: IF
A31: 14 | B31: Kompensacija už nepanaudotas atostogas, € | C31: 0
A32: 15 | B32: Nedarbingumo pašalpa darbdavio lėšomis, € | C32: Jei darbuotojas nedirbo 4 ar mažiau dienų, tada jis sirgo. Paskaičiuokite už tas 1-2 dienas darbdavio mokamą atlyginimą | D32: IF
A33: 16 | B33: Priskaičiuota iš viso, € | C33: Visos priskaičiuotos sumos
A34: 17 | B34: pritaikytas NPD, € | C34: paskaičiuokite pagal dešinėje duotas formules | H34: Neapmokestinamo minimumo skaičiavimas:
A35: 18 | B35: GPM, € | C35: GMP=(Priskaičiuota - NPD)*20% | D35: koeficientams suteikite vardus | G35: 1) | H35: NPD max - 460 Eur. Taikomas pajamoms iki 730 Eur.
A36: 19 | B36: VSD ir PSD įmokos, € | C36: 14,29% nuo priskaičiuoto atlygio atėmus nedarbingumo pašalpos sumą, PSD - 6,98% | G36: 2) | H36: NPD = 460 – 0,26* (gyventojo mėnesio su darbo santykiais arba jų esmę atitinkančiais santykiais susijusios pajamos – 730) | R36: jei Du<1678
A37: 20 | B37: Papildomas pensijinis kaupimas | C37: 3% nuo priskaičiuoto atlygio | G37: 3) | H37: NPD = 400 – 0,18* (gyventojo mėnesio su darbo santykiais arba jų esmę atitinkančiais santykiais susijusios pajamos – 642) | R37: jei Du>1678
A38: 21 | B38: Išskaičiuota iš viso, € | C38: visa išskaičiuota suma mokesčiams | G38: 4) | H38: Jei neigiamas tai rašome 0
A39: 22 | B39: Išmokėtina suma, € | C39: Išmokama = priskaičiuota - išskaičiuota
A40: 23 | B40: Darbdavio VSD įmokos, € | C40: VSD (1,77%) * priskaičiuota
A41: 24 | B41: Avansas, € | C41: Parinkite iš darbuotojų lapo | D41: vlookup()
A42: 25 | B42: Išmokėtina suma po avanso, € | C42: Išmokama suma atėmus avansą
A43: 26 | B43: Garantinis fondas | C43: 0,2% nuo visiems darbuotojams priskaičiuotų atlyginimų
...

Sheet Darbo užmokestis
A1: UAB "Jaunystė" | F1: GPM1 | G1: 0.2 | J1: Garantinis fondas | L1: 0.002 | N1: Ilgalaikio darbo išmokų fondo įmoka | R1: 0.0016 | S1: =SUM(O10:O24)*0.16% -> 28.082859
A2: Įmonės kodas 1222555888 | F2: GPM2 | G2: 0.27 | J2: Įmoka | L2: =SUM(O10:O24)*L1 -> 35.103574 | N2: Soc. draudimo įmokos nelaimingų atsitikimų draudimui | R2: 0.0014 | S2: =SUM(O10:O24)*0.14% -> 24.572502
A3: Darbo užmokesčio registras | F3: VSD darbuotojo | G3: 0.1429
F4: PSD | G4: 0.0698
A5: Kovas | F5: VSD darbdavio | G5: 0.0177
F6: Papildomas pensijinis kaupimas | G6: 0.03
A7: mėnuo | F7: Nedarbingumo pašalpa | G7: 0.65 | I7: Iš viso: | J7: =SUM(J10:J24) -> 16142.333 | K7: =SUM(K10:K24) -> 50 | L7: =SUM(L10:L24) -> 278.52381 | M7: =SUM(M10:M24) -> 0 | N7: =SUM(N10:N24) -> 1080.9297 | O7: =SUM(O10:O24) -> 17551.787 | P7: =SUM(P10:P24) -> 5263.7989 | Q7: =SUM(Q10:Q24) -> 2457.5976 | ... Y7: =SUM(Y10:Y24) -> 10014.668
A9: Registras | B9: Op. Nr. | C9: Skaičiavimo data | D9: Pavardė, vardas | E9: Pareiginis atlyginimas, € | F9: Valandinis tarifinis atlygis, € | G9: Nustatytas darbo dienų skaičius | H9: Faktiškai dirbta, d. | I9: Faktiškai dirbta, val. | J9: Atlyginimas, € | K9: Mėnesinė priemoka, € | L9: Eilinės atostogos, € | M9: Kompensacija už nepanaudotas atostogas, € | N9: Nedarbingumo pašalpa darbdavio lėšomis, € | O9: Priskaičiuota iš viso, € | P9: pritaikytas NPD, € | Q9: GPM, € | R9: VSD įmoka, € | S9: PSD įmoka, € | T9: Papildomas pensijinis kaupimas | U9: Išskaičiuota iš viso, € | V9: Išmokėtina suma, € | W9: Darbdavio VSD įmokos, € | X9: Avansas, € | Y9: Išmokėtina suma po avanso, €
A10: darbo užmokestis | B10: ="03" -> 03 | C10: =EOMONTH(DATE(2026,3,1),0) -> 46112 | D10: =Darbuotojai!B6 -> Darbuotojas1 | E10: =VLOOKUP(D10,Darbuotojai!$B$6:$D$20,3,FALSE) -> 2800 | F10: =VLOOKUP(D10,Darbuotojai!$B$6:$E$20,4,FALSE) -> 15.909091 | G10: =NETWORKDAYS(DATE(2026,3,1),DATE(2026,3,31),DATE(2026,3,11)) -> 21 | H10: =RANDBETWEEN(15,G10) -> 19 | I10: =H10*8 -> 152 | J10: =E10*H10/G10 -> 2533.3333 | K10: =IF(H10=G10,50,0) -> 0 | L10: =IF((G10-H10)>4,J10/H10,0) -> 0 | M10: =IF((G10-H10)<4,0,0) -> 0 | N10: =IF((G10-H10) <= 4, J10-(J10/G10*H10), 0) -> 241.26984 | O10: =SUM(J10:N10) -> 2774.6032 | P10: {=_xlfn.IFS(O10<750,$L$33,O10<1678,$L$33-0.26*(O10-730),O10>=1678,MAX(0,400-0.18*(O10-342)))} -> 0 | Q10: =(O10-P10)*$G$1 -> 554.92063 | R10: =(O10-O10*$G$7)*$G$3 -> 138.77178 | S10: =O10*$G$4 -> 193.6673 | T10: =O10*$G$6 -> 83.238095 | U10: =SUM(Q10:T10) -> 970.59781 | V10: =O10-U10 -> 1804.0054 | W10: =O10*$G$5 -> 49.110476 | X10: =VLOOKUP(D10,Darbuotojai!$B$6:$F$20, 5,FALSE) -> 150 | Y10: =V10-X10 -> 1654.0054
A11: darbo užmokestis | B11: ="03" -> 03 | C11: =EOMONTH(DATE(2026,3,1),0) -> 46112 | D11: =Darbuotojai!B7 -> Darbuotojas2 | E11: =VLOOKUP(D11,Darbuotojai!$B$6:$D$20,3,FALSE) -> 1600 | F11: =VLOOKUP(D11,Darbuotojai!$B$6:$E$20,4,FALSE) -> 9.0909091 | G11: =NETWORKDAYS(DATE(2026,3,1),DATE(2026,3,31),DATE(2026,3,11)) -> 21 | H11: =RANDBETWEEN(15,G11) -> 15 | I11: =H11*8 -> 120 | J11: =E11*H11/G11 -> 1142.8571 | K11: =IF(H11=G11,50,0) -> 0 | L11: =IF((G11-H11)>4,J11/H11,0) -> 76.190476 | M11: =IF((G11-H11)<4,0,0) -> 0 | N11: =IF((G11-H11) <= 4, J11-(J11/G11*H11), 0) -> 0 | O11: =SUM(J11:N11) -> 1219.0476 | P11: {=_xlfn.IFS(O11<750,$L$33,O11<1678,$L$33-0.26*(O11-730),O11>=1678,MAX(0,400-0.18*(O11-342)))} -> 332.84762 | Q11: =(O11-P11)*$G$1 -> 177.24 | R11: =(O11-O11*$G$7)*$G$3 -> 60.970667 | S11: =O11*$G$4 -> 85.089524 | T11: =O11*$G$6 -> 36.571429 | U11: =SUM(Q11:T11) -> 359.87162 | V11: =O11-U11 -> 859.176 | W11: =O11*$G$5 -> 21.577143 | X11: =VLOOKUP(D11,Darbuotojai!$B$6:$F$20, 5,FALSE) -> 150 | Y11: =V11-X11 -> 709.176
A12: darbo užmokestis | B12: ="03" -> 03 | C12: =EOMONTH(DATE(2026,3,1),0) -> 46112 | D12: =Darbuotojai!B8 -> Darbuotojas3 | E12: =VLOOKUP(D12,Darbuotojai!$B$6:$D$20,3,FALSE) -> 1600 | F12: =VLOOKUP(D12,Darbuotojai!$B$6:$E$20,4,FALSE) -> 9.0909091 | G12: =NETWORKDAYS(DATE(2026,3,1),DATE(2026,3,31),DATE(2026,3,11)) -> 21 | H12: =RANDBETWEEN(15,G12) -> 17 | I12: =H12*8 -> 136 | J12: =E12*H12/G12 -> 1295.2381 | K12: =IF(H12=G12,50,0) -> 0 | L12: =IF((G12-H12)>4,J12/H12,0) -> 0 | M12: =IF((G12-H12)<4,0,0) -> 0 | N12: =IF((G12-H12) <= 4, J12-(J12/G12*H12), 0) -> 246.71202 | O12: =SUM(J12:N12) -> 1541.9501 | P12: {=_xlfn.IFS(O12<750,$L$33,O12<1678,$L$33-0.26*(O12-730),O12>=1678,MAX(0,400-0.18*(O12-342)))} -> 248.89297 | Q12: =(O12-P12)*$G$1 -> 258.61143 | R12: =(O12-O12*$G$7)*$G$3 -> 77.120635 | S12: =O12*$G$4 -> 107.62812 | T12: =O12*$G$6 -> 46.258503 | U12: =SUM(Q12:T12) -> 489.61868 | V12: =O12-U12 -> 1052.3314 | W12: =O12*$G$5 -> 27.292517 | X12: =VLOOKUP(D12,Darbuotojai!$B$6:$F$20, 5,FALSE) -> 150 | Y12: =V12-X12 -> 902.33143
A13: darbo užmokestis | B13: ="03" -> 03 | C13: =EOMONTH(DATE(2026,3,1),0) -> 46112 | D13: =Darbuotojai!B9 -> Darbuotojas4 | E13: =VLOOKUP(D13,Darbuotojai!$B$6:$D$20,3,FALSE) -> 1505 | F13: =VLOOKUP(D13,Darbuotojai!$B$6:$E$20,4,FALSE) -> 8.5511364 | G13: =NETWORKDAYS(DATE(2026,3,1),DATE(2026,3,31),DATE(2026,3,11)) -> 21 | H13: =RANDBETWEEN(15,G13) -> 19 | I13: =H13*8 -> 152 | J13: =E13*H13/G13 -> 1361.6667 | K13: =IF(H13=G13,50,0) -> 0 | L13: =IF((G13-H13)>4,J13/H13,0) -> 0 | M13: =IF((G13-H13)<4,0,0) -> 0 | N13: =IF((G13-H13) <= 4, J13-(J13/G13*H13), 0) -> 129.68254 | O13: =SUM(J13:N13) -> 1491.3492 | P13: {=_xlfn.IFS(O13<750,$L$33,O13<1678,$L$33-0.26*(O13-730),O13>=1678,MAX(0,400-0.18*(O13-342)))} -> 262.04921 | Q13: =(O13-P13)*$G$1 -> 245.86 | R13: =(O13-O13*$G$7)*$G$3 -> 74.589831 | S13: =O13*$G$4 -> 104.09617 | T13: =O13*$G$6 -> 44.740476 | U13: =SUM(Q13:T13) -> 469.28648 | V13: =O13-U13 -> 1022.0627 | W13: =O13*$G$5 -> 26.396881 | X13: =VLOOKUP(D13,Darbuotojai!$B$6:$F$20, 5,FALSE) -> 200 | Y13: =V13-X13 -> 822.06272
A14: darbo užmokestis | B14: ="03" -> 03 | C14: =EOMONTH(DATE(2026,3,1),0) -> 46112 | D14: =Darbuotojai!B10 -> Darbuotojas5 | E14: =VLOOKUP(D14,Darbuotojai!$B$6:$D$20,3,FALSE) -> 1199 | F14: =VLOOKUP(D14,Darbuotojai!$B$6:$E$20,4,FALSE) -> 6.8125 | G14: =NETWORKDAYS(DATE(2026,3,1),DATE(2026,3,31),DATE(2026,3,11)) -> 21 | H14: =RANDBETWEEN(15,G14) -> 20 | I14: =H14*8 -> 160 | J14: =E14*H14/G14 -> 1141.9048 | K14: =IF(H14=G14,50,0) -> 0 | L14: =IF((G14-H14)>4,J14/H14,0) -> 0 | M14: =IF((G14-H14)<4,0,0) -> 0 | N14: =IF((G14-H14) <= 4, J14-(J14/G14*H14), 0) -> 54.376417 | O14: =SUM(J14:N14) -> 1196.2812 | P14: {=_xlfn.IFS(O14<750,$L$33,O14<1678,$L$33-0.26*(O14-730),O14>=1678,MAX(0,400-0.18*(O14-342)))} -> 338.76689 | Q14: =(O14-P14)*$G$1 -> 171.50286 | R14: =(O14-O14*$G$7)*$G$3 -> 59.832003 | S14: =O14*$G$4 -> 83.500426 | T14: =O14*$G$6 -> 35.888435 | U14: =SUM(Q14:T14) -> 350.72372 | V14: =O14-U14 -> 845.55746 | W14: =O14*$G$5 -> 21.174177 | X14: =VLOOKUP(D14,Darbuotojai!$B$6:$F$20, 5,FALSE) -> 200 | Y14: =V14-X14 -> 645.55746
A15: darbo užmokestis | B15: ="03" -> 03 | C15: =EOMONTH(DATE(2026,3,1),0) -> 46112 | D15: =Darbuotojai!B11 -> Darbuotojas6 | E15: =VLOOKUP(D15,Darbuotojai!$B$6:$D$20,3,FALSE) -> 1199 | F15: =VLOOKUP(D15,Darbuotojai!$B$6:$E$20,4,FALSE) -> 6.8125 | G15: =NETWORKDAYS(DATE(2026,3,1),DATE(2026,3,31),DATE(2026,3,11)) -> 21 | H15: =RANDBETWEEN(15,G15) -> 16 | I15: =H15*8 -> 128 | J15: =E15*H15/G15 -> 913.52381 | K15: =IF(H15=G15,50,0) -> 0 | L15: =IF((G15-H15)>4,J15/H15,0) -> 57.095238 | M15: =IF((G15-H15)<4,0,0) -> 0 | N15: =IF((G15-H15) <= 4, J15-(J15/G15*H15), 0) -> 0 | O15: =SUM(J15:N15) -> 970.61905 | P15: {=_xlfn.IFS(O15<750,$L$33,O15<1678,$L$33-0.26*(O15-730),O15>=1678,MAX(0,400-0.18*(O15-342)))} -> 397.43905 | Q15: =(O15-P15)*$G$1 -> 114.636 | R15: =(O15-O15*$G$7)*$G$3 -> 48.545512 | S15: =O15*$G$4 -> 67.74921 | T15: =O15*$G$6 -> 29.118571 | U15: =SUM(Q15:T15) -> 260.04929 | V15: =O15-U15 -> 710.56975 | W15: =O15*$G$5 -> 17.179957 | X15: =VLOOKUP(D15,Darbuotojai!$B$6:$F$20, 5,FALSE) -> 150 | Y15: =V15-X15 -> 560.56975
A16: darbo užmokestis | B16: ="03" -> 03 | C16: =EOMONTH(DATE(2026,3,1),0) -> 46112 | D16: =Darbuotojai!B12 -> Darbuotojas7 | E16: =VLOOKUP(D16,Darbuotojai!$B$6:$D$20,3,FALSE) -> 1090 | F16: =VLOOKUP(D16,Darbuotojai!$B$6:$E$20,4,FALSE) -> 6.1931818 | G16: =NETWORKDAYS(DATE(2026,3,1),DATE(2026,3,31),DATE(2026,3,11)) -> 21 | H16: =RANDBETWEEN(15,G16) -> 21 | I16: =H16*8 -> 168 | J16: =E16*H16/G16 -> 1090 | K16: =IF(H16=G16,50,0) -> 50 | L16: =IF((G16-H16)>4,J16/H16,0) -> 0 | M16: =IF((G16-H16)<4,0,0) -> 0 | N16: =IF((G16-H16) <= 4, J16-(J16/G16*H16), 0) -> 0 | O16: =SUM(J16:N16) -> 1140 | P16: {=_xlfn.IFS(O16<750,$L$33,O16<1678,$L$33-0.26*(O16-730),O16>=1678,MAX(0,400-0.18*(O16-342)))} -> 353.4 | Q16: =(O16-P16)*$G$1 -> 157.32 | R16: =(O16-O16*$G$7)*$G$3 -> 57.0171 | S16: =O16*$G$4 -> 79.572 | T16: =O16*$G$6 -> 34.2 | U16: =SUM(Q16:T16) -> 328.1091 | V16: =O16-U16 -> 811.8909 | W16: =O16*$G$5 -> 20.178 | X16: =VLOOKUP(D16,Darbuotojai!$B$6:$F$20, 5,FALSE) -> 200 | Y16: =V16-X16 -> 611.8909
A17: darbo užmokestis | B17: ="03" -> 03 | C17: =EOMONTH(DATE(2026,3,1),0) -> 46112 | D17: =Darbuotojai!B13 -> Darbuotojas8 | E17: =VLOOKUP(D17,Darbuotojai!$B$6:$D$20,3,FALSE) -> 1090 | F17: =VLOOKUP(D17,Darbuotojai!$B$6:$E$20,4,FALSE) -> 6.1931818 | G17: =NETWORKDAYS(DATE(2026,3,1),DATE(2026,3,31),DATE(2026,3,11)) -> 21 | H17: =RANDBETWEEN(15,G17) -> 16 | I17: =H17*8 -> 128 | J17: =E17*H17/G17 -> 830.47619 | K17: =IF(H17=G17,50,0) -> 0 | L17: =IF((G17-H17)>4,J17/H17,0) -> 51.904762 | M17: =IF((G17-H17)<4,0,0) -> 0 | N17: =IF((G17-H17) <= 4, J17-(J17/G17*H17), 0) -> 0 | O17: =SUM(J17:N17) -> 882.38095 | P17: {=_xlfn.IFS(O17<750,$L$33,O17<1678,$L$33-0.26*(O17-730),O17>=1678,MAX(0,400-0.18*(O17-342)))} -> 420.38095 | Q17: =(O17-P17)*$G$1 -> 92.4 | R17: =(O17-O17*$G$7)*$G$3 -> 44.132283 | S17: =O17*$G$4 -> 61.59019 | T17: =O17*$G$6 -> 26.471429 | U17: =SUM(Q17:T17) -> 224.5939 | V17: =O17-U17 -> 657.78705 | W17: =O17*$G$5 -> 15.618143 | X17: =VLOOKUP(D17,Darbuotojai!$B$6:$F$20, 5,FALSE) -> 150 | Y17: =V17-X17 -> 507.78705
A18: darbo užmokestis | B18: ="03" -> 03 | C18: =EOMONTH(DATE(2026,3,1),0) -> 46112 | D18: =Darbuotojai!B14 -> Darbuotojas9 | E18: =VLOOKUP(D18,Darbuotojai!$B$6:$D$20,3,FALSE) -> 980 | F18: =VLOOKUP(D18,Darbuotojai!$B$6:$E$20,4,FALSE) -> 5.5681818 | G18: =NETWORKDAYS(DATE(2026,3,1),DATE(2026,3,31),DATE(2026,3,11)) -> 21 | H18: =RANDBETWEEN(15,G18) -> 19 | I18: =H18*8 -> 152 | J18: =E18*H18/G18 -> 886.66667 | K18: =IF(H18=G18,50,0) -> 0 | L18: =IF((G18-H18)>4,J18/H18,0) -> 0 | M18: =IF((G18-H18)<4,0,0) -> 0 | N18: =IF((G18-H18) <= 4, J18-(J18/G18*H18), 0) -> 84.444444 | O18: =SUM(J18:N18) -> 971.11111 | P18: {=_xlfn.IFS(O18<750,$L$33,O18<1678,$L$33-0.26*(O18-730),O18>=1678,MAX(0,400-0.18*(O18-342)))} -> 397.31111 | Q18: =(O18-P18)*$G$1 -> 114.76 | R18: =(O18-O18*$G$7)*$G$3 -> 48.570122 | S18: =O18*$G$4 -> 67.783556 | T18: =O18*$G$6 -> 29.133333 | U18: =SUM(Q18:T18) -> 260.24701 | V18: =O18-U18 -> 710.8641 | W18: =O18*$G$5 -> 17.188667 | X18: =VLOOKUP(D18,Darbuotojai!$B$6:$F$20, 5,FALSE) -> 150 | Y18: =V18-X18 -> 560.8641
A19: darbo užmokestis | B19: ="03" -> 03 | C19: =EOMONTH(DATE(2026,3,1),0) -> 46112 | D19: =Darbuotojai!B15 -> Darbuotojas10 | E19: =VLOOKUP(D19,Darbuotojai!$B$6:$D$20,3,FALSE) -> 980 | F19: =VLOOKUP(D19,Darbuotojai!$B$6:$E$20,4,FALSE) -> 5.5681818 | G19: =NETWORKDAYS(DATE(2026,3,1),DATE(2026,3,31),DATE(2026,3,11)) -> 21 | H19: =RANDBETWEEN(15,G19) -> 20 | I19: =H19*8 -> 160 | J19: =E19*H19/G19 -> 933.33333 | K19: =IF(H19=G19,50,0) -> 0 | L19: =IF((G19-H19)>4,J19/H19,0) -> 0 | M19: =IF((G19-H19)<4,0,0) -> 0 | N19: =IF((G19-H19) <= 4, J19-(J19/G19*H19), 0) -> 44.444444 | O19: =SUM(J19:N19) -> 977.77778 | P19: {=_xlfn.IFS(O19<750,$L$33,O19<1678,$L$33-0.26*(O19-730),O19>=1678,MAX(0,400-0.18*(O19-342)))} -> 395.57778 | Q19: =(O19-P19)*$G$1 -> 116.44 | R19: =(O19-O19*$G$7)*$G$3 -> 48.903556 | S19: =O19*$G$4 -> 68.248889 | T19: =O19*$G$6 -> 29.333333 | U19: =SUM(Q19:T19) -> 262.92578 | V19: =O19-U19 -> 714.852 | W19: =O19*$G$5 -> 17.306667 | X19: =VLOOKUP(D19,Darbuotojai!$B$6:$F$20, 5,FALSE) -> 150 | Y19: =V19-X19 -> 564.852
A20: darbo užmokestis | B20: ="03" -> 03 | C20: =EOMONTH(DATE(2026,3,1),0) -> 46112 | D20: =Darbuotojai!B16 -> Darbuotojas11 | E20: =VLOOKUP(D20,Darbuotojai!$B$6:$D$20,3,FALSE) -> 980 | F20: =VLOOKUP(D20,Darbuotojai!$B$6:$E$20,4,FALSE) -> 5.5681818 | G20: =NETWORKDAYS(DATE(2026,3,1),DATE(2026,3,31),DATE(2026,3,11)) -> 21 | H20: =RANDBETWEEN(15,G20) -> 17 | I20: =H20*8 -> 136 | J20: =E20*H20/G20 -> 793.33333 | K20: =IF(H20=G20,50,0) -> 0 | L20: =IF((G20-H20)>4,J20/H20,0) -> 0 | M20: =IF((G20-H20)<4,0,0) -> 0 | N20: =IF((G20-H20) <= 4, J20-(J20/G20*H20), 0) -> 151.11111 | O20: =SUM(J20:N20) -> 944.44444 | P20: {=_xlfn.IFS(O20<750,$L$33,O20<1678,$L$33-0.26*(O20-730),O20>=1678,MAX(0,400-0.18*(O20-342)))} -> 404.24444 | Q20: =(O20-P20)*$G$1 -> 108.04 | R20: =(O20-O20*$G$7)*$G$3 -> 47.236389 | S20: =O20*$G$4 -> 65.922222 | T20: =O20*$G$6 -> 28.333333 | U20: =SUM(Q20:T20) -> 249.53194 | V20: =O20-U20 -> 694.9125 | W20: =O20*$G$5 -> 16.716667 | X20: =VLOOKUP(D20,Darbuotojai!$B$6:$F$20, 5,FALSE) -> 200 | Y20: =V20-X20 -> 494.9125
A21: darbo užmokestis | B21: ="03" -> 03 | C21: =EOMONTH(DATE(2026,3,1),0) -> 46112 | D21: =Darbuotojai!B17 -> Darbuotojas12 | E21: =VLOOKUP(D21,Darbuotojai!$B$6:$D$20,3,FALSE) -> 980 | F21: =VLOOKUP(D21,Darbuotojai!$B$6:$E$20,4,FALSE) -> 5.5681818 | G21: =NETWORKDAYS(DATE(2026,3,1),DATE(2026,3,31),DATE(2026,3,11)) -> 21 | H21: =RANDBETWEEN(15,G21) -> 15 | I21: =H21*8 -> 120 | J21: =E21*H21/G21 -> 700 | K21: =IF(H21=G21,50,0) -> 0 | L21: =IF((G21-H21)>4,J21/H21,0) -> 46.666667 | M21: =IF((G21-H21)<4,0,0) -> 0 | N21: =IF((G21-H21) <= 4, J21-(J21/G21*H21), 0) -> 0 | O21: =SUM(J21:N21) -> 746.66667 | P21: {=_xlfn.IFS(O21<750,$L$33,O21<1678,$L$33-0.26*(O21-730),O21>=1678,MAX(0,400-0.18*(O21-342)))} -> 460 | Q21: =(O21-P21)*$G$1 -> 57.333333 | R21: =(O21-O21*$G$7)*$G$3 -> 37.344533 | S21: =O21*$G$4 -> 52.117333 | T21: =O21*$G$6 -> 22.4 | U21: =SUM(Q21:T21) -> 169.1952 | V21: =O21-U21 -> 577.47147 | W21: =O21*$G$5 -> 13.216 | X21: =VLOOKUP(D21,Darbuotojai!$B$6:$F$20, 5,FALSE) -> 150 | Y21: =V21-X21 -> 427.47147
... A24: darbo užmokestis | B24: ="03" -> 03 | C24: =EOMONTH(DATE(2026,3,1),0) -> 46112 | D24: =Darbuotojai!B20 -> Darbuotojas15 | E24: =VLOOKUP(D24,Darbuotojai!$B$6:$D$20,3,FALSE) -> 980 | F24: =VLOOKUP(D24,Darbuotojai!$B$6:$E$20,4,FALSE) -> 5.5681818 | G24: =NETWORKDAYS(DATE(2026,3,1),DATE(2026,3,31),DATE(2026,3,11)) -> 21 | H24: =RANDBETWEEN(15,G24) -> 20 | I24: =H24*8 -> 160 | J24: =E24*H24/G24 -> 933.33333 | K24: =IF(H24=G24,50,0) -> 0 | L24: =IF((G24-H24)>4,J24/H24,0) -> 0 | M24: =IF((G24-H24)<4,0,0) -> 0 | N24: =IF((G24-H24) <= 4, J24-(J24/G24*H24), 0) -> 44.444444 | O24: =SUM(J24:N24) -> 977.77778 | P24: {=_xlfn.IFS(O24<750,$L$33,O24<1678,$L$33-0.26*(O24-730),O24>=1678,MAX(0,400-0.18*(O24-342)))} -> 395.57778 | Q24: =(O24-P24)*$G$1 -> 116.44 | R24: =(O24-O24*$G$7)*$G$3 -> 48.903556 | S24: =O24*$G$4 -> 68.248889 | T24: =O24*$G$6 -> 29.333333 | U24: =SUM(Q24:T24) -> 262.92578 | V24: =O24-U24 -> 714.852 | W24: =O24*$G$5 -> 17.306667 | X24: =VLOOKUP(D24,Darbuotojai!$B$6:$F$20, 5,FALSE) -> 150 | Y24: =V24-X24 -> 564.852
K33: NPD | L33: 460
K35: Neapmokestinamo minimumo skaičiavimas:
J36: 1) | K36: NPD max - 460 Eur. Taikomas pajamoms iki 730 Eur.
J37: 2) | K37: NPD = 460 – 0,26* (gyventojo mėnesio su darbo santykiais arba jų esmę atitinkančiais santykiais susijusios pajamos – 730) | U37: jei Du<1678
J38: 3) | K38: NPD = 400 – 0,18* (gyventojo mėnesio su darbo santykiais arba jų esmę atitinkančiais santykiais susijusios pajamos – 642) | U38: jei Du>1678
J39: 4) | K39: Jei neigiamas tai rašome 0

Sheet suvestinė
A3: 1 | B3: Keli darbuotojai dirbo 18 ir daugiau dienų | C3: =COUNTIF('Darbo užmokestis'!H10:H24, ">=18") -> 8
A4: 2 | B4: Darbuotojų, kurie dirbo mažiau nei 18 dienų, išmokamų atlyginimų suma | C4: =SUMIF('Darbo užmokestis'!H10:H24, "<18",'Darbo užmokestis'!V10:V24) -> 5129.7197
A5: 3 | B5: Vidutinė avanso suma | C5: =AVERAGE('Darbo užmokestis'!X10:X24) -> 163.33333
A6: 4 | B6: Darbuotojų, kurių valandinis įkainis mažiau nei 8 eurai, sumokamų VSD vidurkis | C6: =AVERAGEIF(Darbuotojai!E6:E20, "<8",'Darbo užmokestis'!R10:R24) -> 47.854519
A7: 5 | B7: Pritaikyto NPD mediana | C7: =MEDIAN('Darbo užmokestis'!P10:P24) -> 395.57778
A8: 6 | B8: 2 didžiausia GPM reikšmė | C8: =LARGE('Darbo užmokestis'!Q10:Q24,2) -> 258.61143
