Workbook

Sheet Užduotis
A1: Savarankiško darbo užduotis:
A3: Darbalapis "Darbuotojai"
B4: Stulpelio pavadinimas | C4: Užduotis | D4: Pastabos
A5: 1 | B5: Eil. Nr. | C5: Sukurkite seką
A6: 2 | B6: Pavardė, vardas | C6: Sukurkite seką "Darbuotojas1" ir t.t.
A7: 3 | B7: Pareigos | C7: Sudarykite sąrašą ir parinkite vieną iš pateiktų pareigybių kiekvienam darbuotojui. Pareigybių skaičius duotas "Pareigybės" lape | D7: sąrašas
A8: 4 | B8: Pareiginis atlyginimas, € | C8: Parinkite kiekvienam darbuotojui pareiginį atlyginimą pagal pareigas | D8: vlookup()
A9: 5 | B9: Valandinis tarifinis atlygis, € | C9: Apskaičiuokite iš pareiginio atlyginimo imdami vidutinį mėnesio darbo dienų skaičių 22
A10: 6 | B10: Avansas, € | C10: Avansą parinkite atsitiktiniu būdu 150 arba 200 eurų | D10: choose()
A11: 7 | B11: Asmens kodas | C11: nepildyti
A12: 8 | B12: Tel. Nr. | C12: sujunkite "+370 6" ir 7 atsitiktiniai skaičiai | D12: concatenate()
A13: 9 | B13: Adresas | C13: sugalvokite patys
A16: Darbalapis "Darbo užmokestis"
B17: Stulpelio pavadinimas | C17: Užduotis
A18: 1 | B18: A5 | C18: Įrašykite kovo mėnesį
A19: 2 | B19: Registras | C19: Darbo užmokestis
A20: 3 | B20: Op. Nr. | C20: tarkime, kad darote registrą kovo mėnesiui, tada rašykite visur 03
A21: 4 | B21: Skaičiavimo data | C21: Pasirinkite šių metų kovo datą formatas: 2022/kov/31 | D21: eomonth()
A22: 5 | B22: Pavardė, vardas | C22: nukopijuokite darbuotojus iš darbuotojų lapo
A23: 6 | B23: Pareiginis atlyginimas, € | C23: Parinkite kiekvienam darbuotojui pareiginį atlyginimą iš darbuotojų lapo | D23: vlookup()
A24: 7 | B24: Valandinis tarifinis atlygis, € | C24: Parinkite kiekvienam darbuotojui pareiginį valandinį atlyginimą iš darbuotojų lapo | D24: vlookup()
A25: 8 | B25: Nustatytas darbo dienų skaičius | C25: apskaičiuokite darbo dienų skaičių su funkcija Networkdays(). Nepamirškite švenčių dienų.
A26: 9 | B26: Faktiškai dirbta, d. | C26: parinkite atsitiktiniu būdu nuo 15 iki mėnesio darbo dienų skaičiaus | D26: randbetween()
A27: 10 | B27: Faktiškai dirbta, val. | C27: dienos * 8 val.
A28: 11 | B28: Atlyginimas, € | C28: atlyginimas priskaičiuotas už dirbtas dienas | D28: atlyginimas*fakt.dirbtų d./d.d.skaičius
A29: 12 | B29: Mėnesinė priemoka, € | C29: Skirkite mėnesinę priemoką 50 eurų, jei dirbo visas darbo dienas | D29: IF
A30: 13 | B30: Eilinės atostogos, € | C30: Jei darbuotojas nedirbo daugiau nei 4 dienas, tada jis tas dienas buvo atostogose. Paskaičiuokite už tas dienas atostoginius | D30: IF
A31: 14 | B31: Kompensacija už nepanaudotas atostogas, € | C31: 0
A32: 15 | B32: Nedarbingumo pašalpa darbdavio lėšomis, € | C32: Jei darbuotojas nedirbo 4 ar mažiau dienų, tada jis sirgo. Paskaičiuokite už tas 1-2 dienas darbdavio mokamą atlyginimą | D32: IF
A33: 16 | B33: Priskaičiuota iš viso, € | C33: Visos priskaičiuotos sumos
A34: 17 | B34: pritaikytas NPD, € | C34: paskaičiuokite pagal dešinėje duotas formules | H34: Neapmokestinamo minimumo skaičiavimas:
A35: 18 | B35: GPM, € | D35: koeficientams suteikite vardus | G35: 1) | H35: NPD max - 460 Eur. Taikomas pajamoms iki 730 Eur.
A36: 19 | B36: VSD ir PSD įmokos, € | C36: 14,29% nuo priskaičiuoto atlygio atėmus nedarbingumo pašalpos sumą, PSD - 6,98% | G36: 2) | H36: NPD = 460 – 0,26* (gyventojo mėnesio su darbo santykiais arba jų esmę atitinkančiais santykiais susijusios pajamos – 730) | R36: jei Du<1678
A37: 20 | B37: Papildomas pensijinis kaupimas | C37: 3% nuo priskaičiuoto atlygio | G37: 3) | H37: NPD = 400 – 0,18* (gyventojo mėnesio su darbo santykiais arba jų esmę atitinkančiais santykiais susijusios pajamos – 642) | R37: jei Du>1678
A38: 21 | B38: Išskaičiuota iš viso, € | C38: visa išskaičiuota suma mokesčiams | G38: 4) | H38: Jei neigiamas tai rašome 0
A39: 22 | B39: Išmokėtina suma, € | C39: Išmokama = priskaičiuota - išskaičiuota
A40: 23 | B40: Darbdavio VSD įmokos, € | C40: VSD (1,77%) * priskaičiuota
A41: 24 | B41: Avansas, € | C41: Parinkite iš darbuotojų lapo | D41: vlookup()
A42: 25 | B42: Išmokėtina suma po avanso, € | C42: Išmokama suma atėmus avansą
A43: 26 | B43: Garantinis fondas | C43: 0,2% nuo visiems darbuotojams priskaičiuotų atlyginimų
...

Sheet Pareigybės
A3: Eil. Nr. | B3: Pareigybė | C3: Pareiginis atlyginimas, € | D3: Darbuotojų skaičius
A4: 1 | B4: Vadovas | C4: 2800 | D4: 1
A5: 2 | B5: Buhalterė | C5: 1600 | D5: 2
A6: 3 | B6: Administratorė | C6: 1505 | D6: 1
A7: 4 | B7: Vadybininkas | C7: 1199 | D7: 2
A8: 5 | B8: Sandėlininkas | C8: 1090 | D8: 2
A9: 6 | B9: Gamybos darbuotojas | C9: 980 | D9: 7

Sheet Darbuotojai
A1: Darbuotojai
A5: Eil. Nr. | B5: Pavardė, vardas | C5: Pareigos | D5: Pareiginis atlyginimas, € | E5: Valandinis tarifinis atlygis, € | F5: Avansas, € | G5: Asmens kodas | H5: Tel. Nr. | I5: Adresas
A6: 1 | B6: Darbuotojas 1 | C6: Vadovas | D6: =VLOOKUP(Darbuotojai!C6,Pareigybės!$B$4:$C$9,2,FALSE) -> 2800 | E6: =(D6/22)/8 -> 15.909091 | F6: =CHOOSE(RANDBETWEEN(1,2),150,200) -> 150 | G6: x | H6: =CONCATENATE("+370 6",RANDBETWEEN(1000000,9999999)) -> +370 63961161 | I6: Jaunystės 1
A7: 2 | B7: Darbuotojas 2 | C7: Administratorė | D7: =VLOOKUP(Darbuotojai!C7,Pareigybės!$B$4:$C$9,2,FALSE) -> 1505 | E7: =(D7/22)/8 -> 8.5511364 | F7: =CHOOSE(RANDBETWEEN(1,2),150,200) -> 150 | G7: x | H7: =CONCATENATE("+370 6",RANDBETWEEN(1000000,9999999)) -> +370 64401661 | I7: Jaunystės 2
A8: 3 | B8: Darbuotojas 3 | C8: Buhalterė | D8: =VLOOKUP(Darbuotojai!C8,Pareigybės!$B$4:$C$9,2,FALSE) -> 1600 | E8: =(D8/22)/8 -> 9.0909091 | F8: =CHOOSE(RANDBETWEEN(1,2),150,200) -> 200 | G8: x | H8: =CONCATENATE("+370 6",RANDBETWEEN(1000000,9999999)) -> +370 65226000 | I8: Jaunystės 3
A9: 4 | B9: Darbuotojas 4 | C9: Vadybininkas | D9: =VLOOKUP(Darbuotojai!C9,Pareigybės!$B$4:$C$9,2,FALSE) -> 1199 | E9: =(D9/22)/8 -> 6.8125 | F9: =CHOOSE(RANDBETWEEN(1,2),150,200) -> 150 | G9: x | H9: =CONCATENATE("+370 6",RANDBETWEEN(1000000,9999999)) -> +370 66974733 | I9: Jaunystės 4
A10: 5 | B10: Darbuotojas 5 | C10: Buhalterė | D10: =VLOOKUP(Darbuotojai!C10,Pareigybės!$B$4:$C$9,2,FALSE) -> 1600 | E10: =(D10/22)/8 -> 9.0909091 | F10: =CHOOSE(RANDBETWEEN(1,2),150,200) -> 200 | G10: x | H10: =CONCATENATE("+370 6",RANDBETWEEN(1000000,9999999)) -> +370 67361425 | I10: Jaunystės 5
A11: 6 | B11: Darbuotojas 6 | C11: Gamybos Darbuotojas | D11: =VLOOKUP(Darbuotojai!C11,Pareigybės!$B$4:$C$9,2,FALSE) -> 980 | E11: =(D11/22)/8 -> 5.5681818 | F11: =CHOOSE(RANDBETWEEN(1,2),150,200) -> 150 | G11: x | H11: =CONCATENATE("+370 6",RANDBETWEEN(1000000,9999999)) -> +370 69974987 | I11: Jaunystės 6
A12: 7 | B12: Darbuotojas 7 | C12: Sandėlininkas | D12: =VLOOKUP(Darbuotojai!C12,Pareigybės!$B$4:$C$9,2,FALSE) -> 1090 | E12: =(D12/22)/8 -> 6.1931818 | F12: =CHOOSE(RANDBETWEEN(1,2),150,200) -> 200 | G12: x | H12: =CONCATENATE("+370 6",RANDBETWEEN(1000000,9999999)) -> +370 67281059 | I12: Jaunystės 7
A13: 8 | B13: Darbuotojas 8 | C13: Vadybininkas | D13: =VLOOKUP(Darbuotojai!C13,Pareigybės!$B$4:$C$9,2,FALSE) -> 1199 | E13: =(D13/22)/8 -> 6.8125 | F13: =CHOOSE(RANDBETWEEN(1,2),150,200) -> 200 | G13: x | H13: =CONCATENATE("+370 6",RANDBETWEEN(1000000,9999999)) -> +370 66904016 | I13: Jaunystės 8
A14: 9 | B14: Darbuotojas 9 | C14: Gamybos Darbuotojas | D14: =VLOOKUP(Darbuotojai!C14,Pareigybės!$B$4:$C$9,2,FALSE) -> 980 | E14: =(D14/22)/8 -> 5.5681818 | F14: =CHOOSE(RANDBETWEEN(1,2),150,200) -> 200 | G14: x | H14: =CONCATENATE("+370 6",RANDBETWEEN(1000000,9999999)) -> +370 67525764 | I14: Jaunystės 9
A15: 10 | B15: Darbuotojas 10 | C15: Gamybos Darbuotojas | D15: =VLOOKUP(Darbuotojai!C15,Pareigybės!$B$4:$C$9,2,FALSE) -> 980 | E15: =(D15/22)/8 -> 5.5681818 | F15: =CHOOSE(RANDBETWEEN(1,2),150,200) -> 200 | G15: x | H15: =CONCATENATE("+370 6",RANDBETWEEN(1000000,9999999)) -> +370 62987090 | I15: Jaunystės 10
A16: 11 | B16: Darbuotojas 11 | C16: Gamybos Darbuotojas | D16: =VLOOKUP(Darbuotojai!C16,Pareigybės!$B$4:$C$9,2,FALSE) -> 980 | E16: =(D16/22)/8 -> 5.5681818 | F16: =CHOOSE(RANDBETWEEN(1,2),150,200) -> 150 | G16: x | H16: =CONCATENATE("+370 6",RANDBETWEEN(1000000,9999999)) -> +370 66158300 | I16: Jaunystės 11
A17: 12 | B17: Darbuotojas 12 | C17: Sandėlininkas | D17: =VLOOKUP(Darbuotojai!C17,Pareigybės!$B$4:$C$9,2,FALSE) -> 1090 | E17: =(D17/22)/8 -> 6.1931818 | F17: =CHOOSE(RANDBETWEEN(1,2),150,200) -> 200 | G17: x | H17: =CONCATENATE("+370 6",RANDBETWEEN(1000000,9999999)) -> +370 62713528 | I17: Jaunystės 12
... A20: 15 | B20: Darbuotojas 15 | C20: Gamybos Darbuotojas | D20: =VLOOKUP(Darbuotojai!C20,Pareigybės!$B$4:$C$9,2,FALSE) -> 980 | E20: =(D20/22)/8 -> 5.5681818 | F20: =CHOOSE(RANDBETWEEN(1,2),150,200) -> 200 | G20: x | H20: =CONCATENATE("+370 6",RANDBETWEEN(1000000,9999999)) -> +370 62767462 | I20: Jaunystės 15

Sheet Darbo užmokestis
A1: UAB "Jaunystė" | F1: GPM1 | G1: 0.2 | J1: Garantinis fondas | L1: 0.002 | N1: Ilgalaikio darbo išmokų fondo įmoka | R1: 0.0016 | S1: =SUM(J10:J24)*R1 -> 25.76099
A2: Įmonės kodas 1222555888 | F2: GPM2 | G2: 0.27 | J2: Įmoka | L2: =SUM(J10:J24)*0.2% -> 32.201238 | N2: Soc. draudimo įmokos nelaimingų atsitikimų draudimui | R2: 0.0014 | S2: =SUM(J10:J24)*R2 -> 22.540867
A3: Darbo užmokesčio registras | F3: VSD darbuotojo | G3: 0.1429
F4: PSD | G4: 0.0698
A5: Kovas | F5: VSD darbdavio | G5: 0.0177
F6: Papildomas pensijinis kaupimas | G6: 0.03
A7: mėnuo | F7: Nedarbingumo pašalpa | G7: 0.65 | I7: Iš viso: | J7: =SUM(J10:J24) -> 16100.619 | K7: =SUM(K10:K24) -> 150 | L7: =SUM(L10:L24) -> 1667 | M7: =SUM(M10:M24) -> 0 | N7: =SUM(N10:N24) -> 752.68182 | O7: =SUM(O10:O24) -> 18670.301 | P7: =SUM(P10:P24) -> 2449.4794 | Q7: =SUM(Q10:Q24) -> 3244.1643 | ... Y7: =SUM(Y10:Y24) -> 4151.8231
A9: Registras | B9: Op. Nr. | C9: Skaičiavimo data | D9: Pavardė, vardas | E9: Pareiginis atlyginimas, € | F9: Valandinis tarifinis atlygis, € | G9: Nustatytas darbo dienų skaičius | H9: Faktiškai dirbta, d. | I9: Faktiškai dirbta, val. | J9: Atlyginimas, € | K9: Mėnesinė priemoka, € | L9: Eilinės atostogos, € | M9: Kompensacija už nepanaudotas atostogas, € | N9: Nedarbingumo pašalpa darbdavio lėšomis, € | O9: Priskaičiuota iš viso, € | P9: pritaikytas NPD, € | Q9: GPM, € | R9: VSD įmoka, € | S9: PSD įmoka, € | T9: Papildomas pensijinis kaupimas | U9: Išskaičiuota iš viso, € | V9: Išmokėtina suma, € | W9: Darbdavio VSD įmokos, € | X9: Avansas, € | Y9: Išmokėtina suma po avanso, €
A10: darbo užmokestis | B10: ="03" -> 03 | C10: =EOMONTH(DATE(2026,3,1),0) -> 46112 | D10: =Darbuotojai!B6 -> Darbuotojas 1 | E10: =VLOOKUP(D10,Darbuotojai!$B$6:$D$20,3,FALSE) -> 2800 | F10: =VLOOKUP(D10,Darbuotojai!$B$6:$E$20,4,FALSE) -> 15.909091 | G10: =NETWORKDAYS(DATE(2026,3,1),DATE(2026,3,31),DATE(2026,3,11)) -> 21 | H10: =RANDBETWEEN(15,G10) -> 16 | I10: =H10*8 -> 128 | J10: =E10*H10/G10 -> 2133.3333 | K10: =IF(H10=G10,50,0) -> 0 | L10: =IF(G10-H10>4,F10*8*(G10-H10),0) -> 636.36364 | M10: 0 | N10: =IF(G10-H10<=4,F10*8*RANDBETWEEN(1,2),0) -> 0 | O10: =N10+M10+L10+K10+J10 -> 2769.697 | P10: =IF(IF(O10<=730,460,IF(O10<1678,460-0.26*O10,IF(O10>1678,460-0.18*O10)))>0,IF(O10<=730,460,IF(O10<1678,460-0.26*O10,IF(O10>1678,460-0.18*O10))),0) -> 0 | Q10: =(O10-P10)*20% -> 553.93939 | R10: =O10*14.29% -> 395.7897 | S10: =O10*6.98% -> 193.32485 | T10: ='Darbo užmokestis'!O10*0.03 -> 83.090909 | U10: =T10+S10+R10+Q10+P10 -> 1226.1448 | W10: =1.77%*'Darbo užmokestis'!O10 -> 49.023636 | X10: =VLOOKUP(D10,Darbuotojai!B6:F20,5,FALSE) -> 150 | Y10: =V10-X10 -> -150
A11: darbo užmokestis | B11: ="03" -> 03 | C11: =EOMONTH(DATE(2026,3,1),0) -> 46112 | D11: =Darbuotojai!B8 -> Darbuotojas 3 | E11: =VLOOKUP(D11,Darbuotojai!$B$6:$D$20,3,FALSE) -> 1600 | F11: =VLOOKUP(D11,Darbuotojai!$B$6:$E$20,4,FALSE) -> 9.0909091 | G11: =NETWORKDAYS(DATE(2026,3,1),DATE(2026,3,31),DATE(2026,3,11)) -> 21 | H11: =RANDBETWEEN(15,G11) -> 21 | I11: =H11*8 -> 168 | J11: =E11*H11/G11 -> 1600 | K11: =IF(H11=G11,50,0) -> 50 | L11: =IF(G11-H11>4,F11*8*(G11-H11),0) -> 0 | M11: 0 | N11: =IF(G11-H11<=4,F11*8*RANDBETWEEN(1,2),0) -> 145.45455 | O11: =N11+M11+L11+K11+J11 -> 1795.4545 | P11: =IF(IF(O11<=730,460,IF(O11<1678,460-0.26*O11,IF(O11>1678,460-0.18*O11)))>0,IF(O11<=730,460,IF(O11<1678,460-0.26*O11,IF(O11>1678,460-0.18*O11))),0) -> 136.81818 | Q11: =(O11-P11)*20% -> 331.72727 | R11: =O11*14.29% -> 256.57045 | S11: =O11*6.98% -> 125.32273 | T11: ='Darbo užmokestis'!O12*0.03 -> 47.376623 | U11: =T11+S11+R11+Q11+P11 -> 897.81526 | V11: =O11-U11 -> 897.63929 | W11: =1.77%*'Darbo užmokestis'!O12 -> 27.952208 | X11: =VLOOKUP(D11,Darbuotojai!B8:F22,5,FALSE) -> 200 | Y11: =V11-X11 -> 697.63929
A12: darbo užmokestis | B12: ="03" -> 03 | C12: =EOMONTH(DATE(2026,3,1),0) -> 46112 | D12: =Darbuotojai!B10 -> Darbuotojas 5 | E12: =VLOOKUP(D12,Darbuotojai!$B$6:$D$20,3,FALSE) -> 1600 | F12: =VLOOKUP(D12,Darbuotojai!$B$6:$E$20,4,FALSE) -> 9.0909091 | G12: =NETWORKDAYS(DATE(2026,3,1),DATE(2026,3,31),DATE(2026,3,11)) -> 21 | H12: =RANDBETWEEN(15,G12) -> 15 | I12: =H12*8 -> 120 | J12: =E12*H12/G12 -> 1142.8571 | K12: =IF(H12=G12,50,0) -> 0 | L12: =IF(G12-H12>4,F12*8*(G12-H12),0) -> 436.36364 | M12: 0 | N12: =IF(G12-H12<=4,F12*8*RANDBETWEEN(1,2),0) -> 0 | O12: =N12+M12+L12+K12+J12 -> 1579.2208 | P12: =IF(IF(O12<=730,460,IF(O12<1678,460-0.26*O12,IF(O12>1678,460-0.18*O12)))>0,IF(O12<=730,460,IF(O12<1678,460-0.26*O12,IF(O12>1678,460-0.18*O12))),0) -> 49.402597 | Q12: =(O12-P12)*20% -> 305.96364 | R12: =O12*14.29% -> 225.67065 | S12: =O12*6.98% -> 110.22961 | T12: ='Darbo užmokestis'!O14*0.03 -> 30.753571 | U12: =T12+S12+R12+Q12+P12 -> 722.02006 | V12: =O12-U12 -> 857.20071 | W12: =1.77%*'Darbo užmokestis'!O14 -> 18.144607 | X12: =VLOOKUP(D12,Darbuotojai!B10:F24,5,FALSE) -> 200 | Y12: =V12-X12 -> 657.20071
A13: darbo užmokestis | B13: ="03" -> 03 | C13: =EOMONTH(DATE(2026,3,1),0) -> 46112 | D13: =Darbuotojai!B7 -> Darbuotojas 2 | E13: =VLOOKUP(D13,Darbuotojai!$B$6:$D$20,3,FALSE) -> 1505 | F13: =VLOOKUP(D13,Darbuotojai!$B$6:$E$20,4,FALSE) -> 8.5511364 | G13: =NETWORKDAYS(DATE(2026,3,1),DATE(2026,3,31),DATE(2026,3,11)) -> 21 | H13: =RANDBETWEEN(15,G13) -> 17 | I13: =H13*8 -> 136 | J13: =E13*H13/G13 -> 1218.3333 | K13: =IF(H13=G13,50,0) -> 0 | L13: =IF(G13-H13>4,F13*8*(G13-H13),0) -> 0 | M13: 0 | N13: =IF(G13-H13<=4,F13*8*RANDBETWEEN(1,2),0) -> 136.81818 | O13: =N13+M13+L13+K13+J13 -> 1355.1515 | P13: =IF(IF(O13<=730,460,IF(O13<1678,460-0.26*O13,IF(O13>1678,460-0.18*O13)))>0,IF(O13<=730,460,IF(O13<1678,460-0.26*O13,IF(O13>1678,460-0.18*O13))),0) -> 107.66061 | Q13: =(O13-P13)*20% -> 249.49818 | R13: =O13*14.29% -> 193.65115 | S13: =O13*6.98% -> 94.589576 | T13: ='Darbo užmokestis'!O11*0.03 -> 53.863636 | U13: =T13+S13+R13+Q13+P13 -> 699.26315 | V13: =O13-U13 -> 655.88836 | W13: =1.77%*'Darbo užmokestis'!O11 -> 31.779545 | X13: =VLOOKUP(D13,Darbuotojai!B7:F21,5,FALSE) -> 150 | Y13: =V13-X13 -> 505.88836
A14: darbo užmokestis | B14: ="03" -> 03 | C14: =EOMONTH(DATE(2026,3,1),0) -> 46112 | D14: =Darbuotojai!B9 -> Darbuotojas 4 | E14: =VLOOKUP(D14,Darbuotojai!$B$6:$D$20,3,FALSE) -> 1199 | F14: =VLOOKUP(D14,Darbuotojai!$B$6:$E$20,4,FALSE) -> 6.8125 | G14: =NETWORKDAYS(DATE(2026,3,1),DATE(2026,3,31),DATE(2026,3,11)) -> 21 | H14: =RANDBETWEEN(15,G14) -> 17 | I14: =H14*8 -> 136 | J14: =E14*H14/G14 -> 970.61905 | K14: =IF(H14=G14,50,0) -> 0 | L14: =IF(G14-H14>4,F14*8*(G14-H14),0) -> 0 | M14: 0 | N14: =IF(G14-H14<=4,F14*8*RANDBETWEEN(1,2),0) -> 54.5 | O14: =N14+M14+L14+K14+J14 -> 1025.119 | P14: =IF(IF(O14<=730,460,IF(O14<1678,460-0.26*O14,IF(O14>1678,460-0.18*O14)))>0,IF(O14<=730,460,IF(O14<1678,460-0.26*O14,IF(O14>1678,460-0.18*O14))),0) -> 193.46905 | Q14: =(O14-P14)*20% -> 166.33 | R14: =O14*14.29% -> 146.48951 | S14: =O14*6.98% -> 71.55331 | T14: ='Darbo užmokestis'!O13*0.03 -> 40.654545 | U14: =T14+S14+R14+Q14+P14 -> 618.49641 | V14: =O14-U14 -> 406.62263 | W14: =1.77%*'Darbo užmokestis'!O13 -> 23.986182 | X14: =VLOOKUP(D14,Darbuotojai!B9:F23,5,FALSE) -> 150 | Y14: =V14-X14 -> 256.62263
A15: darbo užmokestis | B15: ="03" -> 03 | C15: =EOMONTH(DATE(2026,3,1),0) -> 46112 | D15: =Darbuotojai!B13 -> Darbuotojas 8 | E15: =VLOOKUP(D15,Darbuotojai!$B$6:$D$20,3,FALSE) -> 1199 | F15: =VLOOKUP(D15,Darbuotojai!$B$6:$E$20,4,FALSE) -> 6.8125 | G15: =NETWORKDAYS(DATE(2026,3,1),DATE(2026,3,31),DATE(2026,3,11)) -> 21 | H15: =RANDBETWEEN(15,G15) -> 15 | I15: =H15*8 -> 120 | J15: =E15*H15/G15 -> 856.42857 | K15: =IF(H15=G15,50,0) -> 0 | L15: =IF(G15-H15>4,F15*8*(G15-H15),0) -> 327 | M15: 0 | N15: =IF(G15-H15<=4,F15*8*RANDBETWEEN(1,2),0) -> 0 | O15: =N15+M15+L15+K15+J15 -> 1183.4286 | P15: =IF(IF(O15<=730,460,IF(O15<1678,460-0.26*O15,IF(O15>1678,460-0.18*O15)))>0,IF(O15<=730,460,IF(O15<1678,460-0.26*O15,IF(O15>1678,460-0.18*O15))),0) -> 152.30857 | Q15: =(O15-P15)*20% -> 206.224 | R15: =O15*14.29% -> 169.11194 | S15: =O15*6.98% -> 82.603314 | T15: ='Darbo užmokestis'!O17*0.03 -> 29.514935 | U15: =T15+S15+R15+Q15+P15 -> 639.76276 | V15: =O15-U15 -> 543.66581 | W15: =1.77%*'Darbo užmokestis'!O17 -> 17.413812 | X15: =VLOOKUP(D15,Darbuotojai!B13:F27,5,FALSE) -> 200 | Y15: =V15-X15 -> 343.66581
A16: darbo užmokestis | B16: ="03" -> 03 | C16: =EOMONTH(DATE(2026,3,1),0) -> 46112 | D16: =Darbuotojai!B12 -> Darbuotojas 7 | E16: =VLOOKUP(D16,Darbuotojai!$B$6:$D$20,3,FALSE) -> 1090 | F16: =VLOOKUP(D16,Darbuotojai!$B$6:$E$20,4,FALSE) -> 6.1931818 | G16: =NETWORKDAYS(DATE(2026,3,1),DATE(2026,3,31),DATE(2026,3,11)) -> 21 | H16: =RANDBETWEEN(15,G16) -> 20 | I16: =H16*8 -> 160 | J16: =E16*H16/G16 -> 1038.0952 | K16: =IF(H16=G16,50,0) -> 0 | L16: =IF(G16-H16>4,F16*8*(G16-H16),0) -> 0 | M16: 0 | N16: =IF(G16-H16<=4,F16*8*RANDBETWEEN(1,2),0) -> 99.090909 | O16: =N16+M16+L16+K16+J16 -> 1137.1861 | P16: =IF(IF(O16<=730,460,IF(O16<1678,460-0.26*O16,IF(O16>1678,460-0.18*O16)))>0,IF(O16<=730,460,IF(O16<1678,460-0.26*O16,IF(O16>1678,460-0.18*O16))),0) -> 164.3316 | Q16: =(O16-P16)*20% -> 194.57091 | R16: =O16*14.29% -> 162.5039 | S16: =O16*6.98% -> 79.375593 | T16: ='Darbo užmokestis'!O16*0.03 -> 34.115584 | U16: =T16+S16+R16+Q16+P16 -> 634.89759 | V16: =O16-U16 -> 502.28856 | W16: =1.77%*'Darbo užmokestis'!O16 -> 20.128195 | X16: =VLOOKUP(D16,Darbuotojai!B12:F26,5,FALSE) -> 200 | Y16: =V16-X16 -> 302.28856
A17: darbo užmokestis | B17: ="03" -> 03 | C17: =EOMONTH(DATE(2026,3,1),0) -> 46112 | D17: =Darbuotojai!B17 -> Darbuotojas 12 | E17: =VLOOKUP(D17,Darbuotojai!$B$6:$D$20,3,FALSE) -> 1090 | F17: =VLOOKUP(D17,Darbuotojai!$B$6:$E$20,4,FALSE) -> 6.1931818 | G17: =NETWORKDAYS(DATE(2026,3,1),DATE(2026,3,31),DATE(2026,3,11)) -> 21 | H17: =RANDBETWEEN(15,G17) -> 18 | I17: =H17*8 -> 144 | J17: =E17*H17/G17 -> 934.28571 | K17: =IF(H17=G17,50,0) -> 0 | L17: =IF(G17-H17>4,F17*8*(G17-H17),0) -> 0 | M17: 0 | N17: =IF(G17-H17<=4,F17*8*RANDBETWEEN(1,2),0) -> 49.545455 | O17: =N17+M17+L17+K17+J17 -> 983.83117 | P17: =IF(IF(O17<=730,460,IF(O17<1678,460-0.26*O17,IF(O17>1678,460-0.18*O17)))>0,IF(O17<=730,460,IF(O17<1678,460-0.26*O17,IF(O17>1678,460-0.18*O17))),0) -> 204.2039 | Q17: =(O17-P17)*20% -> 155.92545 | R17: =O17*14.29% -> 140.58947 | S17: =O17*6.98% -> 68.671416 | T17: ='Darbo užmokestis'!O21*0.03 -> 32.236364 | U17: =T17+S17+R17+Q17+P17 -> 601.6266 | V17: =O17-U17 -> 382.20456 | W17: =1.77%*'Darbo užmokestis'!O21 -> 19.019455 | X17: =VLOOKUP(D17,Darbuotojai!B17:F31,5,FALSE) -> 200 | Y17: =V17-X17 -> 182.20456
A18: darbo užmokestis | B18: ="03" -> 03 | C18: =EOMONTH(DATE(2026,3,1),0) -> 46112 | D18: =Darbuotojai!B11 -> Darbuotojas 6 | E18: =VLOOKUP(D18,Darbuotojai!$B$6:$D$20,3,FALSE) -> 980 | F18: =VLOOKUP(D18,Darbuotojai!$B$6:$E$20,4,FALSE) -> 5.5681818 | G18: =NETWORKDAYS(DATE(2026,3,1),DATE(2026,3,31),DATE(2026,3,11)) -> 21 | H18: =RANDBETWEEN(15,G18) -> 20 | I18: =H18*8 -> 160 | J18: =E18*H18/G18 -> 933.33333 | K18: =IF(H18=G18,50,0) -> 0 | L18: =IF(G18-H18>4,F18*8*(G18-H18),0) -> 0 | M18: 0 | N18: =IF(G18-H18<=4,F18*8*RANDBETWEEN(1,2),0) -> 44.545455 | O18: =N18+M18+L18+K18+J18 -> 977.87879 | P18: =IF(IF(O18<=730,460,IF(O18<1678,460-0.26*O18,IF(O18>1678,460-0.18*O18)))>0,IF(O18<=730,460,IF(O18<1678,460-0.26*O18,IF(O18>1678,460-0.18*O18))),0) -> 205.75152 | Q18: =(O18-P18)*20% -> 154.42545 | R18: =O18*14.29% -> 139.73888 | S18: =O18*6.98% -> 68.255939 | T18: ='Darbo užmokestis'!O15*0.03 -> 35.502857 | U18: =T18+S18+R18+Q18+P18 -> 603.67465 | V18: =O18-U18 -> 374.20414 | W18: =1.77%*'Darbo užmokestis'!O15 -> 20.946686 | X18: =VLOOKUP(D18,Darbuotojai!B11:F25,5,FALSE) -> 150 | Y18: =V18-X18 -> 224.20414
A19: darbo užmokestis | B19: ="03" -> 03 | C19: =EOMONTH(DATE(2026,3,1),0) -> 46112 | D19: =Darbuotojai!B14 -> Darbuotojas 9 | E19: =VLOOKUP(D19,Darbuotojai!$B$6:$D$20,3,FALSE) -> 980 | F19: =VLOOKUP(D19,Darbuotojai!$B$6:$E$20,4,FALSE) -> 5.5681818 | G19: =NETWORKDAYS(DATE(2026,3,1),DATE(2026,3,31),DATE(2026,3,11)) -> 21 | H19: =RANDBETWEEN(15,G19) -> 18 | I19: =H19*8 -> 144 | J19: =E19*H19/G19 -> 840 | K19: =IF(H19=G19,50,0) -> 0 | L19: =IF(G19-H19>4,F19*8*(G19-H19),0) -> 0 | M19: 0 | N19: =IF(G19-H19<=4,F19*8*RANDBETWEEN(1,2),0) -> 44.545455 | O19: =N19+M19+L19+K19+J19 -> 884.54545 | P19: =IF(IF(O19<=730,460,IF(O19<1678,460-0.26*O19,IF(O19>1678,460-0.18*O19)))>0,IF(O19<=730,460,IF(O19<1678,460-0.26*O19,IF(O19>1678,460-0.18*O19))),0) -> 230.01818 | Q19: =(O19-P19)*20% -> 130.90545 | R19: =O19*14.29% -> 126.40155 | S19: =O19*6.98% -> 61.741273 | T19: ='Darbo užmokestis'!O18*0.03 -> 29.336364 | U19: =T19+S19+R19+Q19+P19 -> 578.40282 | V19: =O19-U19 -> 306.14264 | W19: =1.77%*'Darbo užmokestis'!O18 -> 17.308455 | X19: =VLOOKUP(D19,Darbuotojai!B14:F28,5,FALSE) -> 200 | Y19: =V19-X19 -> 106.14264
A20: darbo užmokestis | B20: ="03" -> 03 | C20: =EOMONTH(DATE(2026,3,1),0) -> 46112 | D20: =Darbuotojai!B15 -> Darbuotojas 10 | E20: =VLOOKUP(D20,Darbuotojai!$B$6:$D$20,3,FALSE) -> 980 | F20: =VLOOKUP(D20,Darbuotojai!$B$6:$E$20,4,FALSE) -> 5.5681818 | G20: =NETWORKDAYS(DATE(2026,3,1),DATE(2026,3,31),DATE(2026,3,11)) -> 21 | H20: =RANDBETWEEN(15,G20) -> 21 | I20: =H20*8 -> 168 | J20: =E20*H20/G20 -> 980 | K20: =IF(H20=G20,50,0) -> 50 | L20: =IF(G20-H20>4,F20*8*(G20-H20),0) -> 0 | M20: 0 | N20: =IF(G20-H20<=4,F20*8*RANDBETWEEN(1,2),0) -> 44.545455 | O20: =N20+M20+L20+K20+J20 -> 1074.5455 | P20: =IF(IF(O20<=730,460,IF(O20<1678,460-0.26*O20,IF(O20>1678,460-0.18*O20)))>0,IF(O20<=730,460,IF(O20<1678,460-0.26*O20,IF(O20>1678,460-0.18*O20))),0) -> 180.61818 | Q20: =(O20-P20)*20% -> 178.78545 | R20: =O20*14.29% -> 153.55255 | S20: =O20*6.98% -> 75.003273 | T20: ='Darbo užmokestis'!O19*0.03 -> 26.536364 | U20: =T20+S20+R20+Q20+P20 -> 614.49582 | V20: =O20-U20 -> 460.04964 | W20: =1.77%*'Darbo užmokestis'!O19 -> 15.656455 | X20: =VLOOKUP(D20,Darbuotojai!B15:F29,5,FALSE) -> 200 | Y20: =V20-X20 -> 260.04964
A21: darbo užmokestis | B21: ="03" -> 03 | C21: =EOMONTH(DATE(2026,3,1),0) -> 46112 | D21: =Darbuotojai!B16 -> Darbuotojas 11 | E21: =VLOOKUP(D21,Darbuotojai!$B$6:$D$20,3,FALSE) -> 980 | F21: =VLOOKUP(D21,Darbuotojai!$B$6:$E$20,4,FALSE) -> 5.5681818 | G21: =NETWORKDAYS(DATE(2026,3,1),DATE(2026,3,31),DATE(2026,3,11)) -> 21 | H21: =RANDBETWEEN(15,G21) -> 21 | I21: =H21*8 -> 168 | J21: =E21*H21/G21 -> 980 | K21: =IF(H21=G21,50,0) -> 50 | L21: =IF(G21-H21>4,F21*8*(G21-H21),0) -> 0 | M21: 0 | N21: =IF(G21-H21<=4,F21*8*RANDBETWEEN(1,2),0) -> 44.545455 | O21: =N21+M21+L21+K21+J21 -> 1074.5455 | P21: =IF(IF(O21<=730,460,IF(O21<1678,460-0.26*O21,IF(O21>1678,460-0.18*O21)))>0,IF(O21<=730,460,IF(O21<1678,460-0.26*O21,IF(O21>1678,460-0.18*O21))),0) -> 180.61818 | Q21: =(O21-P21)*20% -> 178.78545 | R21: =O21*14.29% -> 153.55255 | S21: =O21*6.98% -> 75.003273 | T21: ='Darbo užmokestis'!O20*0.03 -> 32.236364 | U21: =T21+S21+R21+Q21+P21 -> 620.19582 | V21: =O21-U21 -> 454.34964 | W21: =1.77%*'Darbo užmokestis'!O20 -> 19.019455 | X21: =VLOOKUP(D21,Darbuotojai!B16:F30,5,FALSE) -> 150 | Y21: =V21-X21 -> 304.34964
A22: darbo užmokestis | B22: ="03" -> 03 | C22: =EOMONTH(DATE(2026,3,1),0) -> 46112 | D22: =Darbuotojai!B18 -> Darbuotojas 13 | E22: =VLOOKUP(D22,Darbuotojai!$B$6:$D$20,3,FALSE) -> 980 | F22: =VLOOKUP(D22,Darbuotojai!$B$6:$E$20,4,FALSE) -> 5.5681818 | G22: =NETWORKDAYS(DATE(2026,3,1),DATE(2026,3,31),DATE(2026,3,11)) -> 21 | H22: =RANDBETWEEN(15,G22) -> 18 | I22: =H22*8 -> 144 | J22: =E22*H22/G22 -> 840 | K22: =IF(H22=G22,50,0) -> 0 | L22: =IF(G22-H22>4,F22*8*(G22-H22),0) -> 0 | M22: 0 | N22: =IF(G22-H22<=4,F22*8*RANDBETWEEN(1,2),0) -> 44.545455 | O22: =N22+M22+L22+K22+J22 -> 884.54545 | P22: =IF(IF(O22<=730,460,IF(O22<1678,460-0.26*O22,IF(O22>1678,460-0.18*O22)))>0,IF(O22<=730,460,IF(O22<1678,460-0.26*O22,IF(O22>1678,460-0.18*O22))),0) -> 230.01818 | Q22: =(O22-P22)*20% -> 130.90545 | R22: =O22*14.29% -> 126.40155 | S22: =O22*6.98% -> 61.741273 | T22: ='Darbo užmokestis'!O22*0.03 -> 26.536364 | U22: =T22+S22+R22+Q22+P22 -> 575.60282 | V22: =O22-U22 -> 308.94264 | W22: =1.77%*'Darbo užmokestis'!O22 -> 15.656455 | X22: =VLOOKUP(D22,Darbuotojai!B18:F32,5,FALSE) -> 200 | Y22: =V22-X22 -> 108.94264
A23: darbo užmokestis | B23: ="03" -> 03 | C23: =EOMONTH(DATE(2026,3,1),0) -> 46112 | D23: =Darbuotojai!B19 -> Darbuotojas 14 | E23: =VLOOKUP(D23,Darbuotojai!$B$6:$D$20,3,FALSE) -> 980 | F23: =VLOOKUP(D23,Darbuotojai!$B$6:$E$20,4,FALSE) -> 5.5681818 | G23: =NETWORKDAYS(DATE(2026,3,1),DATE(2026,3,31),DATE(2026,3,11)) -> 21 | H23: =RANDBETWEEN(15,G23) -> 15 | I23: =H23*8 -> 120 | J23: =E23*H23/G23 -> 700 | K23: =IF(H23=G23,50,0) -> 0 | L23: =IF(G23-H23>4,F23*8*(G23-H23),0) -> 267.27273 | M23: 0 | N23: =IF(G23-H23<=4,F23*8*RANDBETWEEN(1,2),0) -> 0 | O23: =N23+M23+L23+K23+J23 -> 967.27273 | P23: =IF(IF(O23<=730,460,IF(O23<1678,460-0.26*O23,IF(O23>1678,460-0.18*O23)))>0,IF(O23<=730,460,IF(O23<1678,460-0.26*O23,IF(O23>1678,460-0.18*O23))),0) -> 208.50909 | Q23: =(O23-P23)*20% -> 151.75273 | R23: =O23*14.29% -> 138.22327 | S23: =O23*6.98% -> 67.515636 | T23: ='Darbo užmokestis'!O23*0.03 -> 29.018182 | U23: =T23+S23+R23+Q23+P23 -> 595.01891 | V23: =O23-U23 -> 372.25382 | W23: =1.77%*'Darbo užmokestis'!O23 -> 17.120727 | X23: =VLOOKUP(D23,Darbuotojai!B19:F33,5,FALSE) -> 200 | Y23: =V23-X23 -> 172.25382
A24: darbo užmokestis | B24: ="03" -> 03 | C24: =EOMONTH(DATE(2026,3,1),0) -> 46112 | D24: =Darbuotojai!B20 -> Darbuotojas 15 | E24: =VLOOKUP(D24,Darbuotojai!$B$6:$D$20,3,FALSE) -> 980 | F24: =VLOOKUP(D24,Darbuotojai!$B$6:$E$20,4,FALSE) -> 5.5681818 | G24: =NETWORKDAYS(DATE(2026,3,1),DATE(2026,3,31),DATE(2026,3,11)) -> 21 | H24: =RANDBETWEEN(15,G24) -> 20 | I24: =H24*8 -> 160 | J24: =E24*H24/G24 -> 933.33333 | K24: =IF(H24=G24,50,0) -> 0 | L24: =IF(G24-H24>4,F24*8*(G24-H24),0) -> 0 | M24: 0 | N24: =IF(G24-H24<=4,F24*8*RANDBETWEEN(1,2),0) -> 44.545455 | O24: =N24+M24+L24+K24+J24 -> 977.87879 | P24: =IF(IF(O24<=730,460,IF(O24<1678,460-0.26*O24,IF(O24>1678,460-0.18*O24)))>0,IF(O24<=730,460,IF(O24<1678,460-0.26*O24,IF(O24>1678,460-0.18*O24))),0) -> 205.75152 | Q24: =(O24-P24)*20% -> 154.42545 | R24: =O24*14.29% -> 139.73888 | S24: =O24*6.98% -> 68.255939 | T24: ='Darbo užmokestis'!O24*0.03 -> 29.336364 | U24: =T24+S24+R24+Q24+P24 -> 597.50815 | V24: =O24-U24 -> 380.37064 | W24: =1.77%*'Darbo užmokestis'!O24 -> 17.308455 | X24: =VLOOKUP(D24,Darbuotojai!B20:F34,5,FALSE) -> 200 | Y24: =V24-X24 -> 180.37064

Sheet suvestinė
A3: 1 | B3: Keli darbuotojai dirbo 18 ir daugiau dienų
A4: 2 | B4: Darbuotojų, kurie dirbo mažiau nei 18 dienų, išmokamų atlyginimų suma
A5: 3 | B5: Vidutinė avanso suma
A6: 4 | B6: Darbuotojų, kurių valandinis įkainis mažiau nei 8 eurai, sumokamų VSD vidurkis
A7: 5 | B7: Pritaikyto NPD mediana
A8: 6 | B8: 2 didžiausia GPM reikšmė
