Workbook

Sheet Pareigybės
A3: Eil. Nr. | B3: Pareigybė | C3: Pareiginis atlyginimas, € | D3: Darbuotojų skaičius
A4: 1 | B4: Vadovas | C4: 2800 | D4: 1
A5: 2 | B5: Buhalterė | C5: 1600 | D5: 2
A6: 3 | B6: Administratorė | C6: 1505 | D6: 1
A7: 4 | B7: Vadybininkas | C7: 1199 | D7: 2
A8: 5 | B8: Sandėlininkas | C8: 1090 | D8: 2
A9: 6 | B9: Gamybos darbuotojas | C9: 980 | D9: 7

Sheet Užduotis
A1: Savarankiško darbo užduotis:
A3: Darbalapis "Darbuotojai"
B4: Stulpelio pavadinimas | C4: Užduotis | D4: Pastabos
A5: 1 | B5: Eil. Nr. | C5: Sukurkite seką
A6: 2 | B6: Pavardė, vardas | C6: Sukurkite seką "Darbuotojas1" ir t.t.
A7: 3 | B7: Pareigos | C7: Sudarykite sąrašą ir parinkite vieną iš pateiktų pareigybių kiekvienam darbuotojui. Pareigybių skaičius duotas "Pareigybės" lape | D7: sąrašas
A8: 4 | B8: Pareiginis atlyginimas, € | C8: Parinkite kiekvienam darbuotojui pareiginį atlyginimą pagal pareigas | D8: vlookup()
A9: 5 | B9: Valandinis tarifinis atlygis, € | C9: Apskaičiuokite iš pareiginio atlyginimo imdami vidutinį mėnesio darbo dienų skaičių 22
A10: 6 | B10: Avansas, € | C10: Avansą parinkite atsitiktiniu būdu 150 arba 200 eurų | D10: choose()
A11: 7 | B11: Asmens kodas | C11: nepildyti
A12: 8 | B12: Tel. Nr. | C12: sujunkite "+370 6" ir 7 atsitiktiniai skaičiai | D12: concatenate()
A13: 9 | B13: Adresas | C13: sugalvokite patys
A16: Darbalapis "Darbo užmokestis"
B17: Stulpelio pavadinimas | C17: Užduotis
A18: 1 | B18: A5 | C18: Įrašykite kovo mėnesį
A19: 2 | B19: Registras | C19: Darbo užmokestis
A20: 3 | B20: Op. Nr. | C20: tarkime, kad darote registrą kovo mėnesiui, tada rašykite visur 03
A21: 4 | B21: Skaičiavimo data | C21: Pasirinkite šių metų kovo datą formatas: 2022/kov/31 | D21: eomonth()
A22: 5 | B22: Pavardė, vardas | C22: nukopijuokite darbuotojus iš darbuotojų lapo
A23: 6 | B23: Pareiginis atlyginimas, € | C23: Parinkite kiekvienam darbuotojui pareiginį atlyginimą iš darbuotojų lapo | D23: vlookup()
A24: 7 | B24: Valandinis tarifinis atlygis, € | C24: Parinkite kiekvienam darbuotojui pareiginį valandinį atlyginimą iš darbuotojų lapo | D24: vlookup()
A25: 8 | B25: Nustatytas darbo dienų skaičius | C25: apskaičiuokite darbo dienų skaičių su funkcija Networkdays(). Nepamirškite švenčių dienų.
A26: 9 | B26: Faktiškai dirbta, d. | C26: parinkite atsitiktiniu būdu nuo 15 iki mėnesio darbo dienų skaičiaus | D26: randbetween()
A27: 10 | B27: Faktiškai dirbta, val. | C27: dienos * 8 val.
A28: 11 | B28: Atlyginimas, € | C28: atlyginimas priskaičiuotas už dirbtas dienas | D28: atlyginimas*fakt.dirbtų d./d.d.skaičius
A29: 12 | B29: Mėnesinė priemoka, € | C29: Skirkite mėnesinę priemoką 50 eurų, jei dirbo visas darbo dienas | D29: IF
A30: 13 | B30: Eilinės atostogos, € | C30: Jei darbuotojas nedirbo daugiau nei 4 dienas, tada jis tas dienas buvo atostogose. Paskaičiuokite už tas dienas atostoginius | D30: IF
A31: 14 | B31: Kompensacija už nepanaudotas atostogas, € | C31: 0
A32: 15 | B32: Nedarbingumo pašalpa darbdavio lėšomis, € | C32: Jei darbuotojas nedirbo 4 ar mažiau dienų, tada jis sirgo. Paskaičiuokite už tas 1-2 dienas darbdavio mokamą atlyginimą | D32: IF
A33: 16 | B33: Priskaičiuota iš viso, € | C33: Visos priskaičiuotos sumos
A34: 17 | B34: pritaikytas NPD, € | C34: paskaičiuokite pagal dešinėje duotas formules | H34: Neapmokestinamo minimumo skaičiavimas:
A35: 18 | B35: GPM, € | C35: GMP=(Priskaičiuota - NPD)*20% | D35: koeficientams suteikite vardus | G35: 1) | H35: NPD max - 460 Eur. Taikomas pajamoms iki 730 Eur.
A36: 19 | B36: VSD ir PSD įmokos, € | C36: 14,29% nuo priskaičiuoto atlygio atėmus nedarbingumo pašalpos sumą, PSD - 6,98% | G36: 2) | H36: NPD = 460 – 0,26* (gyventojo mėnesio su darbo santykiais arba jų esmę atitinkančiais santykiais susijusios pajamos – 730) | R36: jei Du<1678
A37: 20 | B37: Papildomas pensijinis kaupimas | C37: 3% nuo priskaičiuoto atlygio | G37: 3) | H37: NPD = 400 – 0,18* (gyventojo mėnesio su darbo santykiais arba jų esmę atitinkančiais santykiais susijusios pajamos – 642) | R37: jei Du>1678
A38: 21 | B38: Išskaičiuota iš viso, € | C38: visa išskaičiuota suma mokesčiams | G38: 4) | H38: Jei neigiamas tai rašome 0
A39: 22 | B39: Išmokėtina suma, € | C39: Išmokama = priskaičiuota - išskaičiuota
A40: 23 | B40: Darbdavio VSD įmokos, € | C40: VSD (1,77%) * priskaičiuota
A41: 24 | B41: Avansas, € | C41: Parinkite iš darbuotojų lapo | D41: vlookup()
A42: 25 | B42: Išmokėtina suma po avanso, € | C42: Išmokama suma atėmus avansą
A43: 26 | B43: Garantinis fondas | C43: 0,2% nuo visiems darbuotojams priskaičiuotų atlyginimų
...

Sheet Darbuotojai
A1: Darbuotojai
A5: Eil. Nr. | B5: Pavardė, vardas | C5: Pareigos | D5: Pareiginis atlyginimas, € | E5: Valandinis tarifinis atlygis, € | F5: Avansas, € | G5: Asmens kodas | H5: Tel. Nr. | I5: Adresas
A6: =1 -> 1 | B6: Darbuotojas1 | C6: Vadovas | D6: {=_xlfn.XLOOKUP(Lentelė3[[#This Row],[Pareigos]],Lentelė2[Pareigybė],Pareigybės!$C$4:$C$9)} -> 2800 | E6: =D6/22/8 -> 15.909091 | F6: =CHOOSE(RANDBETWEEN(1,2), 150, 200) -> 200 | G6: x | H6: =CONCATENATE("+370 6",RANDBETWEEN(10,99)," ",RANDBETWEEN(10000,99999)) -> +370 673 66792 | I6: Jaunystės 1
A7: =A6+1 -> 2 | B7: Darbuotojas2 | C7: Buhalterė | D7: {=_xlfn.XLOOKUP(Lentelė3[[#This Row],[Pareigos]],Lentelė2[Pareigybė],Pareigybės!$C$4:$C$9)} -> 1600 | E7: =D7/22/8 -> 9.0909091 | F7: =CHOOSE(RANDBETWEEN(1,2), 150, 200) -> 150 | G7: x | H7: =CONCATENATE("+370 6",RANDBETWEEN(10,99)," ",RANDBETWEEN(10000,99999)) -> +370 650 32354 | I7: Jaunystės 2
A8: =A7+1 -> 3 | B8: Darbuotojas3 | C8: Buhalterė | D8: {=_xlfn.XLOOKUP(Lentelė3[[#This Row],[Pareigos]],Lentelė2[Pareigybė],Pareigybės!$C$4:$C$9)} -> 1600 | E8: =D8/22/8 -> 9.0909091 | F8: =CHOOSE(RANDBETWEEN(1,2), 150, 200) -> 150 | G8: x | H8: =CONCATENATE("+370 6",RANDBETWEEN(10,99)," ",RANDBETWEEN(10000,99999)) -> +370 653 33309 | I8: Jaunystės 3
A9: =A8+1 -> 4 | B9: Darbuotojas4 | C9: Administratorė | D9: {=_xlfn.XLOOKUP(Lentelė3[[#This Row],[Pareigos]],Lentelė2[Pareigybė],Pareigybės!$C$4:$C$9)} -> 1505 | E9: =D9/22/8 -> 8.5511364 | F9: =CHOOSE(RANDBETWEEN(1,2), 150, 200) -> 150 | G9: x | H9: =CONCATENATE("+370 6",RANDBETWEEN(10,99)," ",RANDBETWEEN(10000,99999)) -> +370 637 30896 | I9: Jaunystės 4
A10: =A9+1 -> 5 | B10: Darbuotojas5 | C10: Vadybininkas | D10: {=_xlfn.XLOOKUP(Lentelė3[[#This Row],[Pareigos]],Lentelė2[Pareigybė],Pareigybės!$C$4:$C$9)} -> 1199 | E10: =D10/22/8 -> 6.8125 | F10: =CHOOSE(RANDBETWEEN(1,2), 150, 200) -> 150 | G10: x | H10: =CONCATENATE("+370 6",RANDBETWEEN(10,99)," ",RANDBETWEEN(10000,99999)) -> +370 688 53684 | I10: Jaunystės 5
A11: =A10+1 -> 6 | B11: Darbuotojas6 | C11: Vadybininkas | D11: {=_xlfn.XLOOKUP(Lentelė3[[#This Row],[Pareigos]],Lentelė2[Pareigybė],Pareigybės!$C$4:$C$9)} -> 1199 | E11: =D11/22/8 -> 6.8125 | F11: =CHOOSE(RANDBETWEEN(1,2), 150, 200) -> 200 | G11: x | H11: =CONCATENATE("+370 6",RANDBETWEEN(10,99)," ",RANDBETWEEN(10000,99999)) -> +370 676 10058 | I11: Jaunystės 6
A12: =A11+1 -> 7 | B12: Darbuotojas7 | C12: Sandėlininkas | D12: {=_xlfn.XLOOKUP(Lentelė3[[#This Row],[Pareigos]],Lentelė2[Pareigybė],Pareigybės!$C$4:$C$9)} -> 1090 | E12: =D12/22/8 -> 6.1931818 | F12: =CHOOSE(RANDBETWEEN(1,2), 150, 200) -> 200 | G12: x | H12: =CONCATENATE("+370 6",RANDBETWEEN(10,99)," ",RANDBETWEEN(10000,99999)) -> +370 654 83040 | I12: Jaunystės 7
A13: =A12+1 -> 8 | B13: Darbuotojas8 | C13: Sandėlininkas | D13: {=_xlfn.XLOOKUP(Lentelė3[[#This Row],[Pareigos]],Lentelė2[Pareigybė],Pareigybės!$C$4:$C$9)} -> 1090 | E13: =D13/22/8 -> 6.1931818 | F13: =CHOOSE(RANDBETWEEN(1,2), 150, 200) -> 200 | G13: x | H13: =CONCATENATE("+370 6",RANDBETWEEN(10,99)," ",RANDBETWEEN(10000,99999)) -> +370 613 90420 | I13: Jaunystės 8
A14: =A13+1 -> 9 | B14: Darbuotojas9 | C14: Gamybos darbuotojas | D14: {=_xlfn.XLOOKUP(Lentelė3[[#This Row],[Pareigos]],Lentelė2[Pareigybė],Pareigybės!$C$4:$C$9)} -> 980 | E14: =D14/22/8 -> 5.5681818 | F14: =CHOOSE(RANDBETWEEN(1,2), 150, 200) -> 200 | G14: x | H14: =CONCATENATE("+370 6",RANDBETWEEN(10,99)," ",RANDBETWEEN(10000,99999)) -> +370 684 45181 | I14: Jaunystės 9
A15: =A14+1 -> 10 | B15: Darbuotojas10 | C15: Gamybos darbuotojas | D15: {=_xlfn.XLOOKUP(Lentelė3[[#This Row],[Pareigos]],Lentelė2[Pareigybė],Pareigybės!$C$4:$C$9)} -> 980 | E15: =D15/22/8 -> 5.5681818 | F15: =CHOOSE(RANDBETWEEN(1,2), 150, 200) -> 200 | G15: x | H15: =CONCATENATE("+370 6",RANDBETWEEN(10,99)," ",RANDBETWEEN(10000,99999)) -> +370 654 10245 | I15: Jaunystės 10
A16: =A15+1 -> 11 | B16: Darbuotojas11 | C16: Gamybos darbuotojas | D16: {=_xlfn.XLOOKUP(Lentelė3[[#This Row],[Pareigos]],Lentelė2[Pareigybė],Pareigybės!$C$4:$C$9)} -> 980 | E16: =D16/22/8 -> 5.5681818 | F16: =CHOOSE(RANDBETWEEN(1,2), 150, 200) -> 150 | G16: x | H16: =CONCATENATE("+370 6",RANDBETWEEN(10,99)," ",RANDBETWEEN(10000,99999)) -> +370 651 93269 | I16: Jaunystės 11
A17: =A16+1 -> 12 | B17: Darbuotojas12 | C17: Gamybos darbuotojas | D17: {=_xlfn.XLOOKUP(Lentelė3[[#This Row],[Pareigos]],Lentelė2[Pareigybė],Pareigybės!$C$4:$C$9)} -> 980 | E17: =D17/22/8 -> 5.5681818 | F17: =CHOOSE(RANDBETWEEN(1,2), 150, 200) -> 200 | G17: x | H17: =CONCATENATE("+370 6",RANDBETWEEN(10,99)," ",RANDBETWEEN(10000,99999)) -> +370 669 58424 | I17: Jaunystės 12
A18: =A17+1 -> 13 | B18: Darbuotojas13 | C18: Gamybos darbuotojas | D18: {=_xlfn.XLOOKUP(Lentelė3[[#This Row],[Pareigos]],Lentelė2[Pareigybė],Pareigybės!$C$4:$C$9)} -> 980 | E18: =D18/22/8 -> 5.5681818 | F18: =CHOOSE(RANDBETWEEN(1,2), 150, 200) -> 150 | G18: x | H18: =CONCATENATE("+370 6",RANDBETWEEN(10,99)," ",RANDBETWEEN(10000,99999)) -> +370 639 69917 | I18: Jaunystės 13
... A20: =A19+1 -> 15 | B20: Darbuotojas15 | C20: Gamybos darbuotojas | D20: {=_xlfn.XLOOKUP(Lentelė3[[#This Row],[Pareigos]],Lentelė2[Pareigybė],Pareigybės!$C$4:$C$9)} -> 980 | E20: =D20/22/8 -> 5.5681818 | F20: =CHOOSE(RANDBETWEEN(1,2), 150, 200) -> 200 | G20: x | H20: =CONCATENATE("+370 6",RANDBETWEEN(10,99)," ",RANDBETWEEN(10000,99999)) -> +370 677 33421 | I20: Jaunystės 15

Sheet Darbo užmokestis
A1: UAB "Jaunystė" | F1: GPM1 | G1: 0.2 | J1: Garantinis fondas | L1: 0.002 | N1: Ilgalaikio darbo išmokų fondo įmoka | R1: 0.0016
A2: Įmonės kodas 1222555888 | F2: GPM2 | G2: 0.27 | J2: Įmoka | N2: Soc. draudimo įmokos nelaimingų atsitikimų draudimui | R2: 0.0014
A3: Darbo užmokesčio registras | F3: VSD darbuotojo | G3: 0.1429
F4: PSD | G4: 0.0698
A5: Kovas | F5: VSD darbdavio | G5: 0.0177
F6: Papildomas pensijinis kaupimas | G6: 0.03
A7: mėnuo | F7: Nedarbingumo pašalpa | G7: 0.65 | I7: Iš viso: | J7: =SUM(J10:J24) -> 16408.318 | K7: =SUM(K10:K24) -> 150 | L7: =SUM(L10:L24) -> 1426.2479 | M7: =SUM(M10:M24) -> 0 | N7: =SUM(N10:N24) -> 660.40909 | O7: =SUM(O10:O24) -> 18644.975 | P7: =SUM(P10:P24) -> 4977.4962 | Q7: =SUM(Q10:Q24) -> 2733.4958 | ... Y7: =SUM(Y10:Y24) -> 3849.3167
A9: Registras | B9: Op. Nr. | C9: Skaičiavimo data | D9: Pavardė, vardas | E9: Pareiginis atlyginimas, € | F9: Valandinis tarifinis atlygis, € | G9: Nustatytas darbo dienų skaičius | H9: Faktiškai dirbta, d. | I9: Faktiškai dirbta, val. | J9: Atlyginimas, € | K9: Mėnesinė priemoka, € | L9: Eilinės atostogos, € | M9: Kompensacija už nepanaudotas atostogas, € | N9: Nedarbingumo pašalpa darbdavio lėšomis, € | O9: Priskaičiuota iš viso, € | P9: pritaikytas NPD, € | Q9: GPM, € | R9: VSD įmoka, € | S9: PSD įmoka, € | T9: Papildomas pensijinis kaupimas | U9: Išskaičiuota iš viso, € | V9: Išmokėtina suma, € | W9: Darbdavio VSD įmokos, € | X9: Avansas, € | Y9: Išmokėtina suma po avanso, €
A10: darbo užmokestis | B10: ="03" -> 03 | C10: =DATE(2026,3,15) -> 46096 | D10: Darbuotojas1 | E10: =_xlfn.XLOOKUP(D10,Darbuotojai!$B$6:$B$20,Darbuotojai!$D$6:$D$20) -> 2800 | F10: =_xlfn.XLOOKUP(D10,Darbuotojai!$B$6:$B$20,Darbuotojai!$E$6:$E$20) -> 15.909091 | G10: =NETWORKDAYS(2026-3-31,2026-3-1,2026-3-11) -> 22 | H10: =RANDBETWEEN(15,G10) -> 17 | I10: =H10*8 -> 136 | J10: =F10*I10 -> 2163.6364 | K10: =IF(G10=H10,50,0) -> 0 | L10: =IF((G10-H10)>4,J10/G10*(G10-H10),0) -> 491.73554 | M10: ="0.00" -> 0.00 | N10: =IF(G10-H10<=4,J10/H10*(G10-H10),0) -> 0 | O10: =SUM(J10:N10) -> 2655.3719 | P10: =MAX(0, IF(O10<=730, 460, IF(O10<=1678, 460-0.26*(O10-730), 400-0.18*(O10-642)))) -> 37.593058 | Q10: =(O10-P10)*0.2 -> 523.55577 | R10: =(O10-N10)*0.1429 -> 379.45264 | S10: =(O10-N10)*0.0698 -> 185.34496 | T10: =O10*0.03 -> 79.661157 | U10: =SUM(P10:T10) -> 1205.6076 | V10: =O10-U10 -> 1449.7643 | W10: =$G$5*O10 -> 47.000083 | X10: =Darbuotojai!F6 -> 200 | Y10: =V10-X10 -> 1249.7643
A11: darbo užmokestis | B11: ="03" -> 03 | C11: =DATE(2026,3,15) -> 46096 | D11: Darbuotojas2 | E11: =_xlfn.XLOOKUP(D11,Darbuotojai!$B$6:$B$20,Darbuotojai!$D$6:$D$20) -> 1600 | F11: =_xlfn.XLOOKUP(D11,Darbuotojai!$B$6:$B$20,Darbuotojai!$E$6:$E$20) -> 9.0909091 | G11: =NETWORKDAYS(2026-3-31,2026-3-1,2026-3-11) -> 22 | H11: =RANDBETWEEN(15,G11) -> 20 | I11: =H11*8 -> 160 | J11: =F11*I11 -> 1454.5455 | K11: =IF(G11=H11,50,0) -> 0 | L11: =IF((G11-H11)>=4,J11/G11*(G11-H11),0) -> 0 | M11: ="0.00" -> 0.00 | N11: =IF(G11-H11<4,J11/H11*(G11-H11),0) -> 145.45455 | O11: =SUM(J11:N11) -> 1600 | P11: =MAX(0, IF(O11<=730, 460, IF(O11<=1678, 460-0.26*(O11-730), 400-0.18*(O11-642)))) -> 233.8 | Q11: =(O11-P11)*0.2 -> 273.24 | R11: =(O11-N11)*0.1429 -> 207.85455 | S11: =(O11-N11)*0.0698 -> 101.52727 | T11: =O11*0.03 -> 48 | U11: =SUM(P11:T11) -> 864.42182 | V11: =O11-U11 -> 735.57818 | W11: =$G$5*O11 -> 28.32 | X11: =Darbuotojai!F7 -> 150 | Y11: =V11-X11 -> 585.57818
A12: darbo užmokestis | B12: ="03" -> 03 | C12: =DATE(2026,3,15) -> 46096 | D12: Darbuotojas3 | E12: =_xlfn.XLOOKUP(D12,Darbuotojai!$B$6:$B$20,Darbuotojai!$D$6:$D$20) -> 1600 | F12: =_xlfn.XLOOKUP(D12,Darbuotojai!$B$6:$B$20,Darbuotojai!$E$6:$E$20) -> 9.0909091 | G12: =NETWORKDAYS(2026-3-31,2026-3-1,2026-3-11) -> 22 | H12: =RANDBETWEEN(15,G12) -> 22 | I12: =H12*8 -> 176 | J12: =F12*I12 -> 1600 | K12: =IF(G12=H12,50,0) -> 50 | L12: =IF((G12-H12)>=4,J12/G12*(G12-H12),0) -> 0 | M12: ="0.00" -> 0.00 | N12: =IF(G12-H12<4,J12/H12*(G12-H12),0) -> 0 | O12: =SUM(J12:N12) -> 1650 | P12: =MAX(0, IF(O12<=730, 460, IF(O12<=1678, 460-0.26*(O12-730), 400-0.18*(O12-642)))) -> 220.8 | Q12: =(O12-P12)*0.2 -> 285.84 | R12: =(O12-N12)*0.1429 -> 235.785 | S12: =(O12-N12)*0.0698 -> 115.17 | T12: =O12*0.03 -> 49.5 | U12: =SUM(P12:T12) -> 907.095 | V12: =O12-U12 -> 742.905 | W12: =$G$5*O12 -> 29.205 | X12: =Darbuotojai!F8 -> 150 | Y12: =V12-X12 -> 592.905
A13: darbo užmokestis | B13: ="03" -> 03 | C13: =DATE(2026,3,15) -> 46096 | D13: Darbuotojas4 | E13: =_xlfn.XLOOKUP(D13,Darbuotojai!$B$6:$B$20,Darbuotojai!$D$6:$D$20) -> 1505 | F13: =_xlfn.XLOOKUP(D13,Darbuotojai!$B$6:$B$20,Darbuotojai!$E$6:$E$20) -> 8.5511364 | G13: =NETWORKDAYS(2026-3-31,2026-3-1,2026-3-11) -> 22 | H13: =RANDBETWEEN(15,G13) -> 22 | I13: =H13*8 -> 176 | J13: =F13*I13 -> 1505 | K13: =IF(G13=H13,50,0) -> 50 | L13: =IF((G13-H13)>=4,J13/G13*(G13-H13),0) -> 0 | M13: ="0.00" -> 0.00 | N13: =IF(G13-H13<4,J13/H13*(G13-H13),0) -> 0 | O13: =SUM(J13:N13) -> 1555 | P13: =MAX(0, IF(O13<=730, 460, IF(O13<=1678, 460-0.26*(O13-730), 400-0.18*(O13-642)))) -> 245.5 | Q13: =(O13-P13)*0.2 -> 261.9 | R13: =(O13-N13)*0.1429 -> 222.2095 | S13: =(O13-N13)*0.0698 -> 108.539 | T13: =O13*0.03 -> 46.65 | U13: =SUM(P13:T13) -> 884.7985 | V13: =O13-U13 -> 670.2015 | W13: =$G$5*O13 -> 27.5235 | X13: =Darbuotojai!F9 -> 150 | Y13: =V13-X13 -> 520.2015
A14: darbo užmokestis | B14: ="03" -> 03 | C14: =DATE(2026,3,15) -> 46096 | D14: Darbuotojas5 | E14: =_xlfn.XLOOKUP(D14,Darbuotojai!$B$6:$B$20,Darbuotojai!$D$6:$D$20) -> 1199 | F14: =_xlfn.XLOOKUP(D14,Darbuotojai!$B$6:$B$20,Darbuotojai!$E$6:$E$20) -> 6.8125 | G14: =NETWORKDAYS(2026-3-31,2026-3-1,2026-3-11) -> 22 | H14: =RANDBETWEEN(15,G14) -> 21 | I14: =H14*8 -> 168 | J14: =F14*I14 -> 1144.5 | K14: =IF(G14=H14,50,0) -> 0 | L14: =IF((G14-H14)>=4,J14/G14*(G14-H14),0) -> 0 | M14: ="0.00" -> 0.00 | N14: =IF(G14-H14<4,J14/H14*(G14-H14),0) -> 54.5 | O14: =SUM(J14:N14) -> 1199 | P14: =MAX(0, IF(O14<=730, 460, IF(O14<=1678, 460-0.26*(O14-730), 400-0.18*(O14-642)))) -> 338.06 | Q14: =(O14-P14)*0.2 -> 172.188 | R14: =(O14-N14)*0.1429 -> 163.54905 | S14: =(O14-N14)*0.0698 -> 79.8861 | T14: =O14*0.03 -> 35.97 | U14: =SUM(P14:T14) -> 789.65315 | V14: =O14-U14 -> 409.34685 | W14: =$G$5*O14 -> 21.2223 | X14: =Darbuotojai!F10 -> 150 | Y14: =V14-X14 -> 259.34685
A15: darbo užmokestis | B15: ="03" -> 03 | C15: =DATE(2026,3,15) -> 46096 | D15: Darbuotojas6 | E15: =_xlfn.XLOOKUP(D15,Darbuotojai!$B$6:$B$20,Darbuotojai!$D$6:$D$20) -> 1199 | F15: =_xlfn.XLOOKUP(D15,Darbuotojai!$B$6:$B$20,Darbuotojai!$E$6:$E$20) -> 6.8125 | G15: =NETWORKDAYS(2026-3-31,2026-3-1,2026-3-11) -> 22 | H15: =RANDBETWEEN(15,G15) -> 16 | I15: =H15*8 -> 128 | J15: =F15*I15 -> 872 | K15: =IF(G15=H15,50,0) -> 0 | L15: =IF((G15-H15)>=4,J15/G15*(G15-H15),0) -> 237.81818 | M15: ="0.00" -> 0.00 | N15: =IF(G15-H15<4,J15/H15*(G15-H15),0) -> 0 | O15: =SUM(J15:N15) -> 1109.8182 | P15: =MAX(0, IF(O15<=730, 460, IF(O15<=1678, 460-0.26*(O15-730), 400-0.18*(O15-642)))) -> 361.24727 | Q15: =(O15-P15)*0.2 -> 149.71418 | R15: =(O15-N15)*0.1429 -> 158.59302 | S15: =(O15-N15)*0.0698 -> 77.465309 | T15: =O15*0.03 -> 33.294545 | U15: =SUM(P15:T15) -> 780.31433 | V15: =O15-U15 -> 329.50385 | W15: =$G$5*O15 -> 19.643782 | X15: =Darbuotojai!F11 -> 200 | Y15: =V15-X15 -> 129.50385
A16: darbo užmokestis | B16: ="03" -> 03 | C16: =DATE(2026,3,15) -> 46096 | D16: Darbuotojas7 | E16: =_xlfn.XLOOKUP(D16,Darbuotojai!$B$6:$B$20,Darbuotojai!$D$6:$D$20) -> 1090 | F16: =_xlfn.XLOOKUP(D16,Darbuotojai!$B$6:$B$20,Darbuotojai!$E$6:$E$20) -> 6.1931818 | G16: =NETWORKDAYS(2026-3-31,2026-3-1,2026-3-11) -> 22 | H16: =RANDBETWEEN(15,G16) -> 18 | I16: =H16*8 -> 144 | J16: =F16*I16 -> 891.81818 | K16: =IF(G16=H16,50,0) -> 0 | L16: =IF((G16-H16)>=4,J16/G16*(G16-H16),0) -> 162.14876 | M16: ="0.00" -> 0.00 | N16: =IF(G16-H16<4,J16/H16*(G16-H16),0) -> 0 | O16: =SUM(J16:N16) -> 1053.9669 | P16: =MAX(0, IF(O16<=730, 460, IF(O16<=1678, 460-0.26*(O16-730), 400-0.18*(O16-642)))) -> 375.7686 | Q16: =(O16-P16)*0.2 -> 135.63967 | R16: =(O16-N16)*0.1429 -> 150.61188 | S16: =(O16-N16)*0.0698 -> 73.566893 | T16: =O16*0.03 -> 31.619008 | U16: =SUM(P16:T16) -> 767.20604 | V16: =O16-U16 -> 286.7609 | W16: =$G$5*O16 -> 18.655215 | X16: =Darbuotojai!F12 -> 200 | Y16: =V16-X16 -> 86.760901
A17: darbo užmokestis | B17: ="03" -> 03 | C17: =DATE(2026,3,15) -> 46096 | D17: Darbuotojas8 | E17: =_xlfn.XLOOKUP(D17,Darbuotojai!$B$6:$B$20,Darbuotojai!$D$6:$D$20) -> 1090 | F17: =_xlfn.XLOOKUP(D17,Darbuotojai!$B$6:$B$20,Darbuotojai!$E$6:$E$20) -> 6.1931818 | G17: =NETWORKDAYS(2026-3-31,2026-3-1,2026-3-11) -> 22 | H17: =RANDBETWEEN(15,G17) -> 19 | I17: =H17*8 -> 152 | J17: =F17*I17 -> 941.36364 | K17: =IF(G17=H17,50,0) -> 0 | L17: =IF((G17-H17)>=4,J17/G17*(G17-H17),0) -> 0 | M17: ="0.00" -> 0.00 | N17: =IF(G17-H17<4,J17/H17*(G17-H17),0) -> 148.63636 | O17: =SUM(J17:N17) -> 1090 | P17: =MAX(0, IF(O17<=730, 460, IF(O17<=1678, 460-0.26*(O17-730), 400-0.18*(O17-642)))) -> 366.4 | Q17: =(O17-P17)*0.2 -> 144.72 | R17: =(O17-N17)*0.1429 -> 134.52086 | S17: =(O17-N17)*0.0698 -> 65.707182 | T17: =O17*0.03 -> 32.7 | U17: =SUM(P17:T17) -> 744.04805 | V17: =O17-U17 -> 345.95195 | W17: =$G$5*O17 -> 19.293 | X17: =Darbuotojai!F13 -> 200 | Y17: =V17-X17 -> 145.95195
A18: darbo užmokestis | B18: ="03" -> 03 | C18: =DATE(2026,3,15) -> 46096 | D18: Darbuotojas9 | E18: =_xlfn.XLOOKUP(D18,Darbuotojai!$B$6:$B$20,Darbuotojai!$D$6:$D$20) -> 980 | F18: =_xlfn.XLOOKUP(D18,Darbuotojai!$B$6:$B$20,Darbuotojai!$E$6:$E$20) -> 5.5681818 | G18: =NETWORKDAYS(2026-3-31,2026-3-1,2026-3-11) -> 22 | H18: =RANDBETWEEN(15,G18) -> 19 | I18: =H18*8 -> 152 | J18: =F18*I18 -> 846.36364 | K18: =IF(G18=H18,50,0) -> 0 | L18: =IF((G18-H18)>=4,J18/G18*(G18-H18),0) -> 0 | M18: ="0.00" -> 0.00 | N18: =IF(G18-H18<4,J18/H18*(G18-H18),0) -> 133.63636 | O18: =SUM(J18:N18) -> 980 | P18: =MAX(0, IF(O18<=730, 460, IF(O18<=1678, 460-0.26*(O18-730), 400-0.18*(O18-642)))) -> 395 | Q18: =(O18-P18)*0.2 -> 117 | R18: =(O18-N18)*0.1429 -> 120.94536 | S18: =(O18-N18)*0.0698 -> 59.076182 | T18: =O18*0.03 -> 29.4 | U18: =SUM(P18:T18) -> 721.42155 | V18: =O18-U18 -> 258.57845 | W18: =$G$5*O18 -> 17.346 | X18: =Darbuotojai!F14 -> 200 | Y18: =V18-X18 -> 58.578455
A19: darbo užmokestis | B19: ="03" -> 03 | C19: =DATE(2026,3,15) -> 46096 | D19: Darbuotojas10 | E19: =_xlfn.XLOOKUP(D19,Darbuotojai!$B$6:$B$20,Darbuotojai!$D$6:$D$20) -> 980 | F19: =_xlfn.XLOOKUP(D19,Darbuotojai!$B$6:$B$20,Darbuotojai!$E$6:$E$20) -> 5.5681818 | G19: =NETWORKDAYS(2026-3-31,2026-3-1,2026-3-11) -> 22 | H19: =RANDBETWEEN(15,G19) -> 16 | I19: =H19*8 -> 128 | J19: =F19*I19 -> 712.72727 | K19: =IF(G19=H19,50,0) -> 0 | L19: =IF((G19-H19)>=4,J19/G19*(G19-H19),0) -> 194.38017 | M19: ="0.00" -> 0.00 | N19: =IF(G19-H19<4,J19/H19*(G19-H19),0) -> 0 | O19: =SUM(J19:N19) -> 907.10744 | P19: =MAX(0, IF(O19<=730, 460, IF(O19<=1678, 460-0.26*(O19-730), 400-0.18*(O19-642)))) -> 413.95207 | Q19: =(O19-P19)*0.2 -> 98.631074 | R19: =(O19-N19)*0.1429 -> 129.62565 | S19: =(O19-N19)*0.0698 -> 63.316099 | T19: =O19*0.03 -> 27.213223 | U19: =SUM(P19:T19) -> 732.73812 | V19: =O19-U19 -> 174.36932 | W19: =$G$5*O19 -> 16.055802 | X19: =Darbuotojai!F15 -> 200 | Y19: =V19-X19 -> -25.630678
A20: darbo užmokestis | B20: ="03" -> 03 | C20: =DATE(2026,3,15) -> 46096 | D20: Darbuotojas11 | E20: =_xlfn.XLOOKUP(D20,Darbuotojai!$B$6:$B$20,Darbuotojai!$D$6:$D$20) -> 980 | F20: =_xlfn.XLOOKUP(D20,Darbuotojai!$B$6:$B$20,Darbuotojai!$E$6:$E$20) -> 5.5681818 | G20: =NETWORKDAYS(2026-3-31,2026-3-1,2026-3-11) -> 22 | H20: =RANDBETWEEN(15,G20) -> 18 | I20: =H20*8 -> 144 | J20: =F20*I20 -> 801.81818 | K20: =IF(G20=H20,50,0) -> 0 | L20: =IF((G20-H20)>=4,J20/G20*(G20-H20),0) -> 145.78512 | M20: ="0.00" -> 0.00 | N20: =IF(G20-H20<4,J20/H20*(G20-H20),0) -> 0 | O20: =SUM(J20:N20) -> 947.60331 | P20: =MAX(0, IF(O20<=730, 460, IF(O20<=1678, 460-0.26*(O20-730), 400-0.18*(O20-642)))) -> 403.42314 | Q20: =(O20-P20)*0.2 -> 108.83603 | R20: =(O20-N20)*0.1429 -> 135.41251 | S20: =(O20-N20)*0.0698 -> 66.142711 | T20: =O20*0.03 -> 28.428099 | U20: =SUM(P20:T20) -> 742.2425 | V20: =O20-U20 -> 205.36081 | W20: =$G$5*O20 -> 16.772579 | X20: =Darbuotojai!F16 -> 150 | Y20: =V20-X20 -> 55.36081
A21: darbo užmokestis | B21: ="03" -> 03 | C21: =DATE(2026,3,15) -> 46096 | D21: Darbuotojas12 | E21: =_xlfn.XLOOKUP(D21,Darbuotojai!$B$6:$B$20,Darbuotojai!$D$6:$D$20) -> 980 | F21: =_xlfn.XLOOKUP(D21,Darbuotojai!$B$6:$B$20,Darbuotojai!$E$6:$E$20) -> 5.5681818 | G21: =NETWORKDAYS(2026-3-31,2026-3-1,2026-3-11) -> 22 | H21: =RANDBETWEEN(15,G21) -> 22 | I21: =H21*8 -> 176 | J21: =F21*I21 -> 980 | K21: =IF(G21=H21,50,0) -> 50 | L21: =IF((G21-H21)>=4,J21/G21*(G21-H21),0) -> 0 | M21: ="0.00" -> 0.00 | N21: =IF(G21-H21<4,J21/H21*(G21-H21),0) -> 0 | O21: =SUM(J21:N21) -> 1030 | P21: =MAX(0, IF(O21<=730, 460, IF(O21<=1678, 460-0.26*(O21-730), 400-0.18*(O21-642)))) -> 382 | Q21: =(O21-P21)*0.2 -> 129.6 | R21: =(O21-N21)*0.1429 -> 147.187 | S21: =(O21-N21)*0.0698 -> 71.894 | T21: =O21*0.03 -> 30.9 | U21: =SUM(P21:T21) -> 761.581 | V21: =O21-U21 -> 268.419 | W21: =$G$5*O21 -> 18.231 | X21: =Darbuotojai!F17 -> 200 | Y21: =V21-X21 -> 68.419
A22: darbo užmokestis | B22: ="03" -> 03 | C22: =DATE(2026,3,15) -> 46096 | D22: Darbuotojas13 | E22: =_xlfn.XLOOKUP(D22,Darbuotojai!$B$6:$B$20,Darbuotojai!$D$6:$D$20) -> 980 | F22: =_xlfn.XLOOKUP(D22,Darbuotojai!$B$6:$B$20,Darbuotojai!$E$6:$E$20) -> 5.5681818 | G22: =NETWORKDAYS(2026-3-31,2026-3-1,2026-3-11) -> 22 | H22: =RANDBETWEEN(15,G22) -> 16 | I22: =H22*8 -> 128 | J22: =F22*I22 -> 712.72727 | K22: =IF(G22=H22,50,0) -> 0 | L22: =IF((G22-H22)>=4,J22/G22*(G22-H22),0) -> 194.38017 | M22: ="0.00" -> 0.00 | N22: =IF(G22-H22<4,J22/H22*(G22-H22),0) -> 0 | O22: =SUM(J22:N22) -> 907.10744 | P22: =MAX(0, IF(O22<=730, 460, IF(O22<=1678, 460-0.26*(O22-730), 400-0.18*(O22-642)))) -> 413.95207 | Q22: =(O22-P22)*0.2 -> 98.631074 | R22: =(O22-N22)*0.1429 -> 129.62565 | S22: =(O22-N22)*0.0698 -> 63.316099 | T22: =O22*0.03 -> 27.213223 | U22: =SUM(P22:T22) -> 732.73812 | V22: =O22-U22 -> 174.36932 | W22: =$G$5*O22 -> 16.055802 | X22: =Darbuotojai!F18 -> 150 | Y22: =V22-X22 -> 24.369322
... A24: darbo užmokestis | B24: ="03" -> 03 | C24: =DATE(2026,3,15) -> 46096 | D24: Darbuotojas15 | E24: =_xlfn.XLOOKUP(D24,Darbuotojai!$B$6:$B$20,Darbuotojai!$D$6:$D$20) -> 980 | F24: =_xlfn.XLOOKUP(D24,Darbuotojai!$B$6:$B$20,Darbuotojai!$E$6:$E$20) -> 5.5681818 | G24: =NETWORKDAYS(2026-3-31,2026-3-1,2026-3-11) -> 22 | H24: =RANDBETWEEN(15,G24) -> 20 | I24: =H24*8 -> 160 | J24: =F24*I24 -> 890.90909 | K24: =IF(G24=H24,50,0) -> 0 | L24: =IF((G24-H24)>=4,J24/G24*(G24-H24),0) -> 0 | M24: ="0.00" -> 0.00 | N24: =IF(G24-H24<4,J24/H24*(G24-H24),0) -> 89.090909 | O24: =SUM(J24:N24) -> 980 | P24: =MAX(0, IF(O24<=730, 460, IF(O24<=1678, 460-0.26*(O24-730), 400-0.18*(O24-642)))) -> 395 | Q24: =(O24-P24)*0.2 -> 117 | R24: =(O24-N24)*0.1429 -> 127.31091 | S24: =(O24-N24)*0.0698 -> 62.185455 | T24: =O24*0.03 -> 29.4 | U24: =SUM(P24:T24) -> 730.89636 | V24: =O24-U24 -> 249.10364 | W24: =$G$5*O24 -> 17.346 | X24: =Darbuotojai!F20 -> 200 | Y24: =V24-X24 -> 49.103636

Sheet suvestinė
A3: 1 | B3: Keli darbuotojai dirbo 18 ir daugiau dienų | C3: =COUNTIF('Darbo užmokestis'!H10:H24,">=18") -> 11
A4: 2 | B4: Darbuotojų, kurie dirbo mažiau nei 18 dienų, išmokamų atlyginimų suma | C4: =SUMIF('Darbo užmokestis'!H10:H24,"<18",'Darbo užmokestis'!V10:V24) -> 2128.0068
A5: 3 | B5: Vidutinė avanso suma | C5: =AVERAGE('Darbo užmokestis'!X10:X24) -> 180
A6: 4 | B6: Darbuotojų, kurių valandinis įkainis mažiau nei 8 eurai, sumokamų VSD vidurkis | C6: =AVERAGEIF('Darbo užmokestis'!F10:F24,"<8",'Darbo užmokestis'!R10:R25) -> 138.60844
A7: 5 | B7: Pritaikyto NPD mediana | C7: =MEDIAN('Darbo užmokestis'!P10:P24) -> 375.7686
A8: 6 | B8: 2 didžiausia GPM reikšmė | C8: =LARGE('Darbo užmokestis'!Q10:Q24,2) -> 285.84
